Workbook

Sheet 0_README
A1: FAT INTEGRITY WORKBOOK — P-7402A (PWRI-220) RELEASE DECISION
A2: Prepared by Rotating Equipment Reliability Lead | 2026-08-25 | Companion to rotating_equipment_release_board.pptx
A5: PURPOSE
A6: Determine whether pump P-7402A can be released for offshore commissioning after impeller work and the repeat FAT (2026-05-15).
A7: This workbook is the auditable calculation basis. Every derived number (margins, pass/fail, counts, thresholds) is a live
A8: formula. Input cells (blue) are literal transcriptions of the supplied source files; grey cells are computed.
A10: DISPOSITION (computed on sheet 11_Disposition): CONDITIONAL RELEASE — release for offshore commissioning under a
A11: restricted operating envelope, subject to closure actions C-01..C-12. NOT released for unrestricted service.
A13: SOURCE FILES (read-only, /home/user/task/materials/)
A14: fat_retest_measurements.csv ........... FAT overall vibration, original (2026-05-12) and retest (2026-05-15) runs
A15: fat_spectral_events.csv ............... discrete-frequency events (1X, 2X, BPF, harmonics)
A16: fat_runup_coastdown.csv ............... transient run-up / coast-down at PMP_DE_H
... A51: COLOR LEGEND: blue = literal input from source | grey = formula | red = FAIL / open | green = PASS / closed | amber = caveat

Sheet 1_Rules
A1: ACCEPTANCE RULES — INPUT LAYER
A2: Source: vibration_acceptance_rule_matrix.csv rows 2-14; pump_specification_P7402A.xlsx "Test Requirements" sheet
A4: Rule ID | B4: Domain | C4: Requirement | D4: Limit value | E4: Unit | F4: Scope text | G4: Authority locator | H4: Record status | I4: Source row
A5: VR-000 | B5: overall housing vibration | C5: RMS velocity | D5: 4.2 | E5: mm/s RMS | F5: contract FAT equipment covered by cited clause | G5: API 610 Table 8 / Test Requirements sheet | H5: SUPERSEDED extract; withdrawal notice 2025-12-31 | I5: rule matrix row 2
A6: VR-001 | B6: overall housing vibration | C6: RMS velocity | D6: 3.8 | E6: mm/s RMS | F6: contract FAT equipment covered by cited clause | G6: API 610 Table 8 / Test Requirements sheet | H6: CURRENT reference extract, effective 2026-01-01 | I6: rule matrix row 3
A7: VR-002 | B7: discrete component | C7: peak velocity | D7: 2.5 | E7: mm/s peak | F7: each observed frequency component | G7: API 610 Table 8 / Test Requirements sheet | H7: reference extract | I7: rule matrix row 4
A8: VR-003 | B8: FAT coverage | C8: test matrix | D8: 60|90|100|110 | E8: % BEP | F8: all specified measurement locations | G8: purchase specification FAT matrix | H8: contract record | I8: rule matrix row 5
A9: VR-004 | B9: mechanical run | C9: elapsed time | D9: 4 | E9: hours minimum | F9: stable operating run | G9: API 610 mechanical run clause | H9: reference extract — no duration record supplied | I9: rule matrix row 6
A10: VR-005 | B10: bearing temperature | C10: temperature | D10: 82 | E10: deg C (or ambient+45) | F10: each bearing | G10: Test Requirements sheet | H10: reference extract | I10: rule matrix row 7
A11: VR-006 | B11: shaft runout | C11: TIR | D11: 0.025 | E11: mm | F11: shaft acceptance | G11: Test Requirements sheet | H11: reference extract | I11: rule matrix row 8
A12: VR-007 | B12: instrument calibration | C12: certificate validity | D12: current | E12: status | F12: all FAT channels | G12: FAT quality plan | H12: reference extract — cert valid-through 2026-05-31 | I12: rule matrix row 9
A13: VR-008 | B13: POR/AOR | C13: operating region | D13: case-specific | E13: % BEP | F13: normal and transient duty | G13: pump datasheet/performance curve | H13: reference extract — AOR NOT stated on datasheet | I13: rule matrix row 10
A14: VR-009 | B14: alarm | C14: RMS trend threshold | D14: derived | E14: mm/s RMS | F14: commissioning surveillance | G14: supplied standards matrix | H14: reference extract | I14: rule matrix row 11
A15: VR-010 | B15: trip | C15: RMS protection threshold | D15: derived | E15: mm/s RMS | F15: machine protection | G15: supplied standards matrix | H15: reference extract | I15: rule matrix row 12
A16: VR-011 | B16: missing retest | C16: evidence closure | D16: required | E16: status | F16: PMP_NDE_A at 60% BEP | G16: FAT test matrix | H16: reference extract — RETEST ROW MISSING | I16: rule matrix row 13
A17: VR-012 | B17: field comparison | C17: matched state | D17: same condition | E17: status | F17: sister pump trend | G17: P-7402B field file | H17: reference extract | I17: rule matrix row 14
A20: KEY FORMULA REFERENCES
A21: Current overall limit (mm/s RMS) | C21: =D6
A22: Superseded overall limit (mm/s RMS) | C22: =D5
A23: Discrete-frequency limit (mm/s peak) | C23: =D7
A24: Bearing temp limit (deg C) | C24: =D10
A25: Runout limit (mm TIR) | C25: =D11

Sheet 2_FAT_Raw
A1: FAT OVERALL MEASUREMENTS — RAW INPUT
A2: Source: fat_retest_measurements.csv rows 2-93 (verbatim values; blue cells = source transcription)
A4: Measurement ID | B4: Phase | C4: Test date | D4: Point | E4: Direction | F4: Flow %BEP | G4: Overall RMS (mm/s) | H4: Peak vel (mm/s) | I4: Displ (µm) | J4: Accel (g) | K4: Temp (°C) | L4: Source locator
A5: VIB-0001 | B5: original | C5: 2026-05-12 | D5: DRV_DE_H | E5: Horizontal | F5: 100 | G5: 2.349 | H5: 3.326 | I5: 18.71 | J5: 0.427 | K5: 52.7 | L5: fat_retest_measurements.csv row 2
A6: VIB-0002 | B6: original | C6: 2026-05-12 | D6: DRV_DE_V | E6: Vertical | F6: 100 | G6: 1.913 | H6: 2.711 | I6: 15.24 | J6: 0.358 | K6: 52.5 | L6: fat_retest_measurements.csv row 3
A7: VIB-0003 | B7: original | C7: 2026-05-12 | D7: DRV_DE_A | E7: Axial | F7: 100 | G7: 4.013 | H7: 5.68 | I7: 32 | J7: 0.731 | K7: 53 | L7: fat_retest_measurements.csv row 4
A8: VIB-0004 | B8: original | C8: 2026-05-12 | D8: DRV_NDE_H | E8: Horizontal | F8: 100 | G8: 2.018 | H8: 2.857 | I8: 16.04 | J8: 0.383 | K8: 50.6 | L8: fat_retest_measurements.csv row 5
A9: VIB-0005 | B9: original | C9: 2026-05-12 | D9: DRV_NDE_V | E9: Vertical | F9: 100 | G9: 1.686 | H9: 2.384 | I9: 13.43 | J9: 0.323 | K9: 50.3 | L9: fat_retest_measurements.csv row 6
A10: VIB-0006 | B10: original | C10: 2026-05-12 | D10: DRV_NDE_A | E10: Axial | F10: 100 | G10: 1.864 | H10: 2.638 | I10: 14.87 | J10: 0.356 | K10: 50.8 | L10: fat_retest_measurements.csv row 7
A11: VIB-0007 | B11: original | C11: 2026-05-12 | D11: PMP_DE_H | E11: Horizontal | F11: 100 | G11: 3.001 | H11: 4.244 | I11: 23.9 | J11: 0.548 | K11: 56.9 | L11: fat_retest_measurements.csv row 8
A12: VIB-0008 | B12: original | C12: 2026-05-12 | D12: PMP_DE_V | E12: Vertical | F12: 100 | G12: 2.176 | H12: 3.082 | I12: 17.39 | J12: 0.417 | K12: 56.6 | L12: fat_retest_measurements.csv row 9
A13: VIB-0009 | B13: original | C13: 2026-05-12 | D13: PMP_DE_A | E13: Axial | F13: 100 | G13: 2.005 | H13: 2.834 | I13: 15.96 | J13: 0.389 | K13: 57.2 | L13: fat_retest_measurements.csv row 10
A14: VIB-0010 | B14: original | C14: 2026-05-12 | D14: PMP_NDE_H | E14: Horizontal | F14: 100 | G14: 2.49 | H14: 3.529 | I14: 19.86 | J14: 0.473 | K14: 55.3 | L14: fat_retest_measurements.csv row 11
A15: VIB-0011 | B15: original | C15: 2026-05-12 | D15: PMP_NDE_V | E15: Vertical | F15: 100 | G15: 2.049 | H15: 2.898 | I15: 16.35 | J15: 0.393 | K15: 55 | L15: fat_retest_measurements.csv row 12
A16: VIB-0012 | B16: original | C16: 2026-05-12 | D16: PMP_NDE_A | E16: Axial | F16: 100 | G16: 1.801 | H16: 2.55 | I16: 14.37 | J16: 0.344 | K16: 55.4 | L16: fat_retest_measurements.csv row 13
... A96: VIB-0092 | B96: retest | C96: 2026-05-15 | D96: PMP_NDE_V | E96: Vertical | F96: 60 | G96: 4.495 | H96: 6.356 | I96: 35.8 | J96: 0.854 | K96: 51.3 | L96: fat_retest_measurements.csv row 93

Sheet 3_Overall_Eval
A1: OVERALL VIBRATION EVALUATION vs CURRENT LIMIT (VR-001 = 3.8 mm/s RMS)
A2: All margins/verdicts are formulas referencing 2_FAT_Raw and 1_Rules. Verdict colours via conditional formatting.
A4: Measurement ID | B4: Phase | C4: Point / Dir | D4: Flow %BEP | E4: Overall RMS | F4: Limit | G4: Margin (mm/s) | H4: Margin % | I4: Verdict | J4: Envelope-flag value (retest 90/100)
A5: ='2_FAT_Raw'!A5 | B5: ='2_FAT_Raw'!B5 | C5: ='2_FAT_Raw'!D5&" "&'2_FAT_Raw'!E5 | D5: ='2_FAT_Raw'!F5 | E5: ='2_FAT_Raw'!G5 | F5: ='1_Rules'!$D$6 | G5: =F5-E5 | H5: =G5/F5 | I5: =IF(E5>F5,"FAIL","PASS") | J5: =IF(AND(B5="retest",OR(D5="90_BEP",D5="100")),E5,"")
A6: ='2_FAT_Raw'!A6 | B6: ='2_FAT_Raw'!B6 | C6: ='2_FAT_Raw'!D6&" "&'2_FAT_Raw'!E6 | D6: ='2_FAT_Raw'!F6 | E6: ='2_FAT_Raw'!G6 | F6: ='1_Rules'!$D$6 | G6: =F6-E6 | H6: =G6/F6 | I6: =IF(E6>F6,"FAIL","PASS") | J6: =IF(AND(B6="retest",OR(D6="90_BEP",D6="100")),E6,"")
A7: ='2_FAT_Raw'!A7 | B7: ='2_FAT_Raw'!B7 | C7: ='2_FAT_Raw'!D7&" "&'2_FAT_Raw'!E7 | D7: ='2_FAT_Raw'!F7 | E7: ='2_FAT_Raw'!G7 | F7: ='1_Rules'!$D$6 | G7: =F7-E7 | H7: =G7/F7 | I7: =IF(E7>F7,"FAIL","PASS") | J7: =IF(AND(B7="retest",OR(D7="90_BEP",D7="100")),E7,"")
A8: ='2_FAT_Raw'!A8 | B8: ='2_FAT_Raw'!B8 | C8: ='2_FAT_Raw'!D8&" "&'2_FAT_Raw'!E8 | D8: ='2_FAT_Raw'!F8 | E8: ='2_FAT_Raw'!G8 | F8: ='1_Rules'!$D$6 | G8: =F8-E8 | H8: =G8/F8 | I8: =IF(E8>F8,"FAIL","PASS") | J8: =IF(AND(B8="retest",OR(D8="90_BEP",D8="100")),E8,"")
A9: ='2_FAT_Raw'!A9 | B9: ='2_FAT_Raw'!B9 | C9: ='2_FAT_Raw'!D9&" "&'2_FAT_Raw'!E9 | D9: ='2_FAT_Raw'!F9 | E9: ='2_FAT_Raw'!G9 | F9: ='1_Rules'!$D$6 | G9: =F9-E9 | H9: =G9/F9 | I9: =IF(E9>F9,"FAIL","PASS") | J9: =IF(AND(B9="retest",OR(D9="90_BEP",D9="100")),E9,"")
A10: ='2_FAT_Raw'!A10 | B10: ='2_FAT_Raw'!B10 | C10: ='2_FAT_Raw'!D10&" "&'2_FAT_Raw'!E10 | D10: ='2_FAT_Raw'!F10 | E10: ='2_FAT_Raw'!G10 | F10: ='1_Rules'!$D$6 | G10: =F10-E10 | H10: =G10/F10 | I10: =IF(E10>F10,"FAIL","PASS") | J10: =IF(AND(B10="retest",OR(D10="90_BEP",D10="100")),E10,"")
A11: ='2_FAT_Raw'!A11 | B11: ='2_FAT_Raw'!B11 | C11: ='2_FAT_Raw'!D11&" "&'2_FAT_Raw'!E11 | D11: ='2_FAT_Raw'!F11 | E11: ='2_FAT_Raw'!G11 | F11: ='1_Rules'!$D$6 | G11: =F11-E11 | H11: =G11/F11 | I11: =IF(E11>F11,"FAIL","PASS") | J11: =IF(AND(B11="retest",OR(D11="90_BEP",D11="100")),E11,"")
A12: ='2_FAT_Raw'!A12 | B12: ='2_FAT_Raw'!B12 | C12: ='2_FAT_Raw'!D12&" "&'2_FAT_Raw'!E12 | D12: ='2_FAT_Raw'!F12 | E12: ='2_FAT_Raw'!G12 | F12: ='1_Rules'!$D$6 | G12: =F12-E12 | H12: =G12/F12 | I12: =IF(E12>F12,"FAIL","PASS") | J12: =IF(AND(B12="retest",OR(D12="90_BEP",D12="100")),E12,"")
A13: ='2_FAT_Raw'!A13 | B13: ='2_FAT_Raw'!B13 | C13: ='2_FAT_Raw'!D13&" "&'2_FAT_Raw'!E13 | D13: ='2_FAT_Raw'!F13 | E13: ='2_FAT_Raw'!G13 | F13: ='1_Rules'!$D$6 | G13: =F13-E13 | H13: =G13/F13 | I13: =IF(E13>F13,"FAIL","PASS") | J13: =IF(AND(B13="retest",OR(D13="90_BEP",D13="100")),E13,"")
A14: ='2_FAT_Raw'!A14 | B14: ='2_FAT_Raw'!B14 | C14: ='2_FAT_Raw'!D14&" "&'2_FAT_Raw'!E14 | D14: ='2_FAT_Raw'!F14 | E14: ='2_FAT_Raw'!G14 | F14: ='1_Rules'!$D$6 | G14: =F14-E14 | H14: =G14/F14 | I14: =IF(E14>F14,"FAIL","PASS") | J14: =IF(AND(B14="retest",OR(D14="90_BEP",D14="100")),E14,"")
A15: ='2_FAT_Raw'!A15 | B15: ='2_FAT_Raw'!B15 | C15: ='2_FAT_Raw'!D15&" "&'2_FAT_Raw'!E15 | D15: ='2_FAT_Raw'!F15 | E15: ='2_FAT_Raw'!G15 | F15: ='1_Rules'!$D$6 | G15: =F15-E15 | H15: =G15/F15 | I15: =IF(E15>F15,"FAIL","PASS") | J15: =IF(AND(B15="retest",OR(D15="90_BEP",D15="100")),E15,"")
A16: ='2_FAT_Raw'!A16 | B16: ='2_FAT_Raw'!B16 | C16: ='2_FAT_Raw'!D16&" "&'2_FAT_Raw'!E16 | D16: ='2_FAT_Raw'!F16 | E16: ='2_FAT_Raw'!G16 | F16: ='1_Rules'!$D$6 | G16: =F16-E16 | H16: =G16/F16 | I16: =IF(E16>F16,"FAIL","PASS") | J16: =IF(AND(B16="retest",OR(D16="90_BEP",D16="100")),E16,"")
... A96: ='2_FAT_Raw'!A96 | B96: ='2_FAT_Raw'!B96 | C96: ='2_FAT_Raw'!D96&" "&'2_FAT_Raw'!E96 | D96: ='2_FAT_Raw'!F96 | E96: ='2_FAT_Raw'!G96 | F96: ='1_Rules'!$D$6 | G96: =F96-E96 | H96: =G96/F96 | I96: =IF(E96>F96,"FAIL","PASS") | J96: =IF(AND(B96="retest",OR(D96="90_BEP",D96="100")),E96,"")
A98: SUMMARY (formulas)
A99: Retest points evaluated | B99: =COUNTIF(B5:B96,"retest")
A100: Retest PASS | B100: =COUNTIFS(B5:B96,"retest",I5:I96,"PASS")
A101: Retest FAIL | B101: =COUNTIFS(B5:B96,"retest",I5:I96,"FAIL")
A102: Original FAIL | B102: =COUNTIFS(B5:B96,"original",I5:I96,"FAIL")
A103: Retest worst value (mm/s) | B103: =MAX(E65:E96)
A104: Best retest margin below limit (mm/s) | B104: =MAX(G65:G96)

Sheet 4_Spectral_Eval
A1: DISCRETE-FREQUENCY CHECK vs VR-002 (2.5 mm/s peak)
A2: CAVEAT A2: source file carries no original/retest phase tag and point naming differs from FAT sheet — verdicts are provisional claims.
A4: Event ID | B4: Point | C4: Flow | D4: Freq (Hz) | E4: Amplitude (mm/s) | F4: Order | G4: Limit | H4: Margin | I4: Provisional verdict | J4: Technician annotation | K4: Source row
A5: SP-001 | B5: PMP_DE_H | C5: 100 | D5: 49.663 | E5: 1.997 | F5: 1X | G5: ='1_Rules'!$D$7 | H5: =G5-E5 | I5: =IF(E5>G5,"EXCEEDS","within") | J5: Shaft rotational speed - observed | K5: fat_spectral_events.csv row 2
A6: SP-002 | B6: PMP_DE_H | C6: 100 | D6: 99.337 | E6: 0.874 | F6: 2X | G6: ='1_Rules'!$D$7 | H6: =G6-E6 | I6: =IF(E6>G6,"EXCEEDS","within") | J6: Misalignment indicator - observed | K6: fat_spectral_events.csv row 3
A7: SP-003 | B7: PMP_DE_H | C7: 100 | D7: 148.99 | E7: 0.218 | F7: 3X | G7: ='1_Rules'!$D$7 | H7: =G7-E7 | I7: =IF(E7>G7,"EXCEEDS","within") | J7: observed harmonic | K7: fat_spectral_events.csv row 4
A8: SP-004 | B8: PMP_DE_H | C8: 100 | D8: 298 | E8: 0.707 | F8: BPF (6X) | G8: ='1_Rules'!$D$7 | H8: =G8-E8 | I8: =IF(E8>G8,"EXCEEDS","within") | J8: Blade pass frequency - observed | K8: fat_spectral_events.csv row 5
A9: SP-005 | B9: PMP_DE_H | C9: 100 | D9: 347.663 | E9: 0.125 | F9: BPF+1X | G9: ='1_Rules'!$D$7 | H9: =G9-E9 | I9: =IF(E9>G9,"EXCEEDS","within") | J9: BPF sideband | K9: fat_spectral_events.csv row 6
A10: SP-006 | B10: PMP_DE_H | C10: 100 | D10: 248.337 | E10: 0.094 | F10: BPF-1X | G10: ='1_Rules'!$D$7 | H10: =G10-E10 | I10: =IF(E10>G10,"EXCEEDS","within") | J10: BPF sideband | K10: fat_spectral_events.csv row 7
A11: SP-007 | B11: PMP_DE_H | C11: 100 | D11: 596 | E11: 0.156 | F11: 2xBPF | G11: ='1_Rules'!$D$7 | H11: =G11-E11 | I11: =IF(E11>G11,"EXCEEDS","within") | J11: Second harmonic of BPF | K11: fat_spectral_events.csv row 8
A12: SP-008 | B12: PMP_DE_H | C12: 110 | D12: 49.663 | E12: 2.85 | F12: 1X | G12: ='1_Rules'!$D$7 | H12: =G12-E12 | I12: =IF(E12>G12,"EXCEEDS","within") | J12: observed - high flow hydraulic loads | K12: fat_spectral_events.csv row 9
A13: SP-009 | B13: PMP_DE_H | C13: 110 | D13: 99.337 | E13: 1.695 | F13: 2X | G13: ='1_Rules'!$D$7 | H13: =G13-E13 | I13: =IF(E13>G13,"EXCEEDS","within") | J13: observed 2X suggests increased radial load | K13: fat_spectral_events.csv row 10
A14: SP-010 | B14: PMP_DE_H | C14: 110 | D14: 148.99 | E14: 0.499 | F14: 3X | G14: ='1_Rules'!$D$7 | H14: =G14-E14 | I14: =IF(E14>G14,"EXCEEDS","within") | J14: observed harmonic | K14: fat_spectral_events.csv row 11
A15: SP-011 | B15: PMP_DE_H | C15: 110 | D15: 298 | E15: 2.964 | F15: BPF (6X) | G15: ='1_Rules'!$D$7 | H15: =G15-E15 | I15: =IF(E15>G15,"EXCEEDS","within") | J15: observed - high flow cavitation/turbulence at volute | K15: fat_spectral_events.csv row 12
A16: SP-012 | B16: PMP_DE_H | C16: 110 | D16: 347.663 | E16: 0.749 | F16: BPF+1X | G16: ='1_Rules'!$D$7 | H16: =G16-E16 | I16: =IF(E16>G16,"EXCEEDS","within") | J16: observed sideband - modulated BPF | K16: fat_spectral_events.csv row 13
... A66: SP-062 | B66: MDE_A | C66: 100 | D66: 148.99 | E66: 0.291 | F66: 3X | G66: ='1_Rules'!$D$7 | H66: =G66-E66 | I66: =IF(E66>G66,"EXCEEDS","within") | J66: observed harmonic | K66: fat_spectral_events.csv row 63
A68: Discrete exceedance count (provisional) | B68: =COUNTIF(I5:I66,"EXCEEDS")
A69: Exceedances are concentrated at 60% and 110% BEP + one axial driver event at 100% (SP-059); attribution to run phase unresolved (C-06).

Sheet 5_Transient
A1: TRANSIENT RUN-UP / COAST-DOWN — PMP_DE_H
A2: Source: fat_runup_coastdown.csv rows 2-50. Peak and resonance-window checks are formulas.
A4: Phase | B4: Speed (rpm) | C4: Overall RMS (mm/s) | D4: Point | E4: Direction | F4: Elapsed (s) | G4: Operator note | H4: Source row | I4: Resonance-window flag | J4: Rated-speed flag
A5: run-up | B5: 0 | C5: 0.021 | D5: PMP_DE_H | E5: Horizontal | F5: 0 | G5: Baseline noise floor | H5: fat_runup_coastdown.csv row 2 | I5: =IF(AND(B5>=1800,B5<=2150),C5,"") | J5: =IF(B5=2980,C5,"")
A6: run-up | B6: 151 | C6: 0.083 | D6: PMP_DE_H | E6: Horizontal | F6: 2 | G6: Initial rotation | H6: fat_runup_coastdown.csv row 3 | I6: =IF(AND(B6>=1800,B6<=2150),C6,"") | J6: =IF(B6=2980,C6,"")
A7: run-up | B7: 302 | C7: 0.156 | D7: PMP_DE_H | E7: Horizontal | F7: 4 | G7: Low speed | H7: fat_runup_coastdown.csv row 4 | I7: =IF(AND(B7>=1800,B7<=2150),C7,"") | J7: =IF(B7=2980,C7,"")
A8: run-up | B8: 453 | C8: 0.25 | D8: PMP_DE_H | E8: Horizontal | F8: 6 | G8: Increasing | H8: fat_runup_coastdown.csv row 5 | I8: =IF(AND(B8>=1800,B8<=2150),C8,"") | J8: =IF(B8=2980,C8,"")
A9: run-up | B9: 604.1 | C9: 0.395 | D9: PMP_DE_H | E9: Horizontal | F9: 8 | G9: Oil film establishing | H9: fat_runup_coastdown.csv row 6 | I9: =IF(AND(B9>=1800,B9<=2150),C9,"") | J9: =IF(B9=2980,C9,"")
A10: run-up | B10: 755.1 | C10: 0.541 | D10: PMP_DE_H | E10: Horizontal | F10: 10 | H10: fat_runup_coastdown.csv row 7 | I10: =IF(AND(B10>=1800,B10<=2150),C10,"") | J10: =IF(B10=2980,C10,"")
A11: run-up | B11: 906.1 | C11: 0.738 | D11: PMP_DE_H | E11: Horizontal | F11: 12 | H11: fat_runup_coastdown.csv row 8 | I11: =IF(AND(B11>=1800,B11<=2150),C11,"") | J11: =IF(B11=2980,C11,"")
A12: run-up | B12: 1057.1 | C12: 0.926 | D12: PMP_DE_H | E12: Horizontal | F12: 14 | H12: fat_runup_coastdown.csv row 9 | I12: =IF(AND(B12>=1800,B12<=2150),C12,"") | J12: =IF(B12=2980,C12,"")
A13: run-up | B13: 1208.1 | C13: 1.186 | D13: PMP_DE_H | E13: Horizontal | F13: 16 | G13: Approaching fluid coupling engagement | H13: fat_runup_coastdown.csv row 10 | I13: =IF(AND(B13>=1800,B13<=2150),C13,"") | J13: =IF(B13=2980,C13,"")
A14: run-up | B14: 1359.1 | C14: 1.435 | D14: PMP_DE_H | E14: Horizontal | F14: 18 | H14: fat_runup_coastdown.csv row 11 | I14: =IF(AND(B14>=1800,B14<=2150),C14,"") | J14: =IF(B14=2980,C14,"")
A15: run-up | B15: 1510.1 | C15: 1.789 | D15: PMP_DE_H | E15: Horizontal | F15: 20 | G15: Mid-speed | H15: fat_runup_coastdown.csv row 12 | I15: =IF(AND(B15>=1800,B15<=2150),C15,"") | J15: =IF(B15=2980,C15,"")
A16: run-up | B16: 1661.1 | C16: 2.09 | D16: PMP_DE_H | E16: Horizontal | F16: 22 | H16: fat_runup_coastdown.csv row 13 | I16: =IF(AND(B16>=1800,B16<=2150),C16,"") | J16: =IF(B16=2980,C16,"")
A17: run-up | B17: 1812.2 | C17: 2.444 | D17: PMP_DE_H | E17: Horizontal | F17: 24 | G17: Structural resonance proximity | H17: fat_runup_coastdown.csv row 14 | I17: =IF(AND(B17>=1800,B17<=2150),C17,"") | J17: =IF(B17=2980,C17,"")
A18: run-up | B18: 1963.2 | C18: 2.787 | D18: PMP_DE_H | E18: Horizontal | F18: 26 | G18: local response feature | H18: fat_runup_coastdown.csv row 15 | I18: =IF(AND(B18>=1800,B18<=2150),C18,"") | J18: =IF(B18=2980,C18,"")
A19: run-up | B19: 2114.2 | C19: 2.517 | D19: PMP_DE_H | E19: Horizontal | F19: 28 | G19: Past resonance - declining | H19: fat_runup_coastdown.csv row 16 | I19: =IF(AND(B19>=1800,B19<=2150),C19,"") | J19: =IF(B19=2980,C19,"")
A20: run-up | B20: 2265.2 | C20: 2.267 | D20: PMP_DE_H | E20: Horizontal | F20: 30 | H20: fat_runup_coastdown.csv row 17 | I20: =IF(AND(B20>=1800,B20<=2150),C20,"") | J20: =IF(B20=2980,C20,"")
A21: run-up | B21: 2416.2 | C21: 2.402 | D21: PMP_DE_H | E21: Horizontal | F21: 32 | G21: Minor secondary response | H21: fat_runup_coastdown.csv row 18 | I21: =IF(AND(B21>=1800,B21<=2150),C21,"") | J21: =IF(B21=2980,C21,"")
A22: run-up | B22: 2567.2 | C22: 2.621 | D22: PMP_DE_H | E22: Horizontal | F22: 34 | H22: fat_runup_coastdown.csv row 19 | I22: =IF(AND(B22>=1800,B22<=2150),C22,"") | J22: =IF(B22=2980,C22,"")
A23: run-up | B23: 2718.2 | C23: 2.818 | D23: PMP_DE_H | E23: Horizontal | F23: 36 | G23: Approaching rated speed | H23: fat_runup_coastdown.csv row 20 | I23: =IF(AND(B23>=1800,B23<=2150),C23,"") | J23: =IF(B23=2980,C23,"")
A24: run-up | B24: 2818.9 | C24: 2.933 | D24: PMP_DE_H | E24: Horizontal | F24: 38 | H24: fat_runup_coastdown.csv row 21 | I24: =IF(AND(B24>=1800,B24<=2150),C24,"") | J24: =IF(B24=2980,C24,"")
A25: run-up | B25: 2899.5 | C25: 2.891 | D25: PMP_DE_H | E25: Horizontal | F25: 40 | G25: Near rated | H25: fat_runup_coastdown.csv row 22 | I25: =IF(AND(B25>=1800,B25<=2150),C25,"") | J25: =IF(B25=2980,C25,"")
A26: run-up | B26: 2939.7 | C26: 2.922 | D26: PMP_DE_H | E26: Horizontal | F26: 42 | H26: fat_runup_coastdown.csv row 23 | I26: =IF(AND(B26>=1800,B26<=2150),C26,"") | J26: =IF(B26=2980,C26,"")
A27: run-up | B27: 2969.9 | C27: 2.954 | D27: PMP_DE_H | E27: Horizontal | F27: 43.5 | H27: fat_runup_coastdown.csv row 24 | I27: =IF(AND(B27>=1800,B27<=2150),C27,"") | J27: =IF(B27=2980,C27,"")
A28: run-up | B28: 2980 | C28: 2.964 | D28: PMP_DE_H | E28: Horizontal | F28: 45 | G28: Rated speed - steady state | H28: fat_runup_coastdown.csv row 25 | I28: =IF(AND(B28>=1800,B28<=2150),C28,"") | J28: =IF(B28=2980,C28,"")
A29: run-up | B29: 2980 | C29: 2.964 | D29: PMP_DE_H | E29: Horizontal | F29: 60 | G29: Steady state confirmed at 15s dwell | H29: fat_runup_coastdown.csv row 26 | I29: =IF(AND(B29>=1800,B29<=2150),C29,"") | J29: =IF(B29=2980,C29,"")
A30: run-up | B30: 2980 | C30: 2.954 | D30: PMP_DE_H | E30: Horizontal | F30: 90 | G30: Thermal stabilization | H30: fat_runup_coastdown.csv row 27 | I30: =IF(AND(B30>=1800,B30<=2150),C30,"") | J30: =IF(B30=2980,C30,"")
A31: run-up | B31: 2980 | C31: 2.964 | D31: PMP_DE_H | E31: Horizontal | F31: 120 | G31: Fully stabilized | H31: fat_runup_coastdown.csv row 28 | I31: =IF(AND(B31>=1800,B31<=2150),C31,"") | J31: =IF(B31=2980,C31,"")
A32: coast-down | B32: 2980 | C32: 2.964 | D32: PMP_DE_H | E32: Horizontal | F32: 0 | G32: Trip initiated | H32: fat_runup_coastdown.csv row 29 | I32: =IF(AND(B32>=1800,B32<=2150),C32,"") | J32: =IF(B32=2980,C32,"")
A33: coast-down | B33: 2919.6 | C33: 2.902 | D33: PMP_DE_H | E33: Horizontal | F33: 1.5 | G33: Decelerating | H33: fat_runup_coastdown.csv row 30 | I33: =IF(AND(B33>=1800,B33<=2150),C33,"") | J33: =IF(B33=2980,C33,"")
A34: coast-down | B34: 2818.9 | C34: 2.787 | D34: PMP_DE_H | E34: Horizontal | F34: 3.5 | H34: fat_runup_coastdown.csv row 31 | I34: =IF(AND(B34>=1800,B34<=2150),C34,"") | J34: =IF(B34=2980,C34,"")
A35: coast-down | B35: 2718.2 | C35: 2.652 | D35: PMP_DE_H | E35: Horizontal | F35: 5.5 | H35: fat_runup_coastdown.csv row 32 | I35: =IF(AND(B35>=1800,B35<=2150),C35,"") | J35: =IF(B35=2980,C35,"")
A36: coast-down | B36: 2567.2 | C36: 2.506 | D36: PMP_DE_H | E36: Horizontal | F36: 8 | H36: fat_runup_coastdown.csv row 33 | I36: =IF(AND(B36>=1800,B36<=2150),C36,"") | J36: =IF(B36=2980,C36,"")
A37: coast-down | B37: 2416.2 | C37: 2.371 | D37: PMP_DE_H | E37: Horizontal | F37: 10.5 | H37: fat_runup_coastdown.csv row 34 | I37: =IF(AND(B37>=1800,B37<=2150),C37,"") | J37: =IF(B37=2980,C37,"")
A38: coast-down | B38: 2265.2 | C38: 2.236 | D38: PMP_DE_H | E38: Horizontal | F38: 13 | H38: fat_runup_coastdown.csv row 35 | I38: =IF(AND(B38>=1800,B38<=2150),C38,"") | J38: =IF(B38=2980,C38,"")
A39: coast-down | B39: 2114.2 | C39: 2.475 | D39: PMP_DE_H | E39: Horizontal | F39: 15.5 | G39: local response feature | H39: fat_runup_coastdown.csv row 36 | I39: =IF(AND(B39>=1800,B39<=2150),C39,"") | J39: =IF(B39=2980,C39,"")
A40: coast-down | B40: 1963.2 | C40: 2.829 | D40: PMP_DE_H | E40: Horizontal | F40: 18 | G40: local response feature on coast-down | H40: fat_runup_coastdown.csv row 37 | I40: =IF(AND(B40>=1800,B40<=2150),C40,"") | J40: =IF(B40=2980,C40,"")
A41: coast-down | B41: 1812.2 | C41: 2.402 | D41: PMP_DE_H | E41: Horizontal | F41: 20.5 | G41: Past resonance | H41: fat_runup_coastdown.csv row 38 | I41: =IF(AND(B41>=1800,B41<=2150),C41,"") | J41: =IF(B41=2980,C41,"")
...

Sheet 6_Coverage_Check
A1: REQUIRED TEST-MATRIX COVERAGE (VR-003: 60 | 90 | 100 | 110 % BEP, all locations)
A2: COUNTIFS formulas against 2_FAT_Raw. Any retest count of 0 = evidence gap.
A4: Point | B4: Direction | C4: Flow %BEP | D4: Original rows | E4: Retest rows | F4: Coverage status | G4: Note
A5: DRV_DE_H | B5: Horizontal | C5: 60 | D5: =COUNTIFS('2_FAT_Raw'!$B:$B,"original",'2_FAT_Raw'!$D:$D,"DRV_DE_H",'2_FAT_Raw'!$E:$E,"Horizontal",'2_FAT_Raw'!$F:$F,"60") | E5: =COUNTIFS('2_FAT_Raw'!$B:$B,"retest",'2_FAT_Raw'!$D:$D,"DRV_DE_H",'2_FAT_Raw'!$E:$E,"Horizontal",'2_FAT_Raw'!$F:$F,"60") | F5: =IF(E5=0,"MISSING — closure required",IF(D5=0,"not in original","covered")) | G5: driver point not retested; original result passed — deviation, see C-01
A6: DRV_DE_H | B6: Horizontal | C6: 90_BEP | D6: =COUNTIFS('2_FAT_Raw'!$B:$B,"original",'2_FAT_Raw'!$D:$D,"DRV_DE_H",'2_FAT_Raw'!$E:$E,"Horizontal",'2_FAT_Raw'!$F:$F,"90_BEP") | E6: =COUNTIFS('2_FAT_Raw'!$B:$B,"retest",'2_FAT_Raw'!$D:$D,"DRV_DE_H",'2_FAT_Raw'!$E:$E,"Horizontal",'2_FAT_Raw'!$F:$F,"90_BEP") | F6: =IF(E6=0,"MISSING — closure required",IF(D6=0,"not in original","covered")) | G6: driver point not retested; original result passed — deviation, see C-01
A7: DRV_DE_H | B7: Horizontal | C7: 100 | D7: =COUNTIFS('2_FAT_Raw'!$B:$B,"original",'2_FAT_Raw'!$D:$D,"DRV_DE_H",'2_FAT_Raw'!$E:$E,"Horizontal",'2_FAT_Raw'!$F:$F,"100") | E7: =COUNTIFS('2_FAT_Raw'!$B:$B,"retest",'2_FAT_Raw'!$D:$D,"DRV_DE_H",'2_FAT_Raw'!$E:$E,"Horizontal",'2_FAT_Raw'!$F:$F,"100") | F7: =IF(E7=0,"MISSING — closure required",IF(D7=0,"not in original","covered"))
A8: DRV_DE_H | B8: Horizontal | C8: 110 | D8: =COUNTIFS('2_FAT_Raw'!$B:$B,"original",'2_FAT_Raw'!$D:$D,"DRV_DE_H",'2_FAT_Raw'!$E:$E,"Horizontal",'2_FAT_Raw'!$F:$F,"110") | E8: =COUNTIFS('2_FAT_Raw'!$B:$B,"retest",'2_FAT_Raw'!$D:$D,"DRV_DE_H",'2_FAT_Raw'!$E:$E,"Horizontal",'2_FAT_Raw'!$F:$F,"110") | F8: =IF(E8=0,"MISSING — closure required",IF(D8=0,"not in original","covered"))
A9: DRV_DE_V | B9: Vertical | C9: 60 | D9: =COUNTIFS('2_FAT_Raw'!$B:$B,"original",'2_FAT_Raw'!$D:$D,"DRV_DE_V",'2_FAT_Raw'!$E:$E,"Vertical",'2_FAT_Raw'!$F:$F,"60") | E9: =COUNTIFS('2_FAT_Raw'!$B:$B,"retest",'2_FAT_Raw'!$D:$D,"DRV_DE_V",'2_FAT_Raw'!$E:$E,"Vertical",'2_FAT_Raw'!$F:$F,"60") | F9: =IF(E9=0,"MISSING — closure required",IF(D9=0,"not in original","covered")) | G9: driver point not retested; original result passed — deviation, see C-01
A10: DRV_DE_V | B10: Vertical | C10: 90_BEP | D10: =COUNTIFS('2_FAT_Raw'!$B:$B,"original",'2_FAT_Raw'!$D:$D,"DRV_DE_V",'2_FAT_Raw'!$E:$E,"Vertical",'2_FAT_Raw'!$F:$F,"90_BEP") | E10: =COUNTIFS('2_FAT_Raw'!$B:$B,"retest",'2_FAT_Raw'!$D:$D,"DRV_DE_V",'2_FAT_Raw'!$E:$E,"Vertical",'2_FAT_Raw'!$F:$F,"90_BEP") | F10: =IF(E10=0,"MISSING — closure required",IF(D10=0,"not in original","covered")) | G10: driver point not retested; original result passed — deviation, see C-01
A11: DRV_DE_V | B11: Vertical | C11: 100 | D11: =COUNTIFS('2_FAT_Raw'!$B:$B,"original",'2_FAT_Raw'!$D:$D,"DRV_DE_V",'2_FAT_Raw'!$E:$E,"Vertical",'2_FAT_Raw'!$F:$F,"100") | E11: =COUNTIFS('2_FAT_Raw'!$B:$B,"retest",'2_FAT_Raw'!$D:$D,"DRV_DE_V",'2_FAT_Raw'!$E:$E,"Vertical",'2_FAT_Raw'!$F:$F,"100") | F11: =IF(E11=0,"MISSING — closure required",IF(D11=0,"not in original","covered"))
A12: DRV_DE_V | B12: Vertical | C12: 110 | D12: =COUNTIFS('2_FAT_Raw'!$B:$B,"original",'2_FAT_Raw'!$D:$D,"DRV_DE_V",'2_FAT_Raw'!$E:$E,"Vertical",'2_FAT_Raw'!$F:$F,"110") | E12: =COUNTIFS('2_FAT_Raw'!$B:$B,"retest",'2_FAT_Raw'!$D:$D,"DRV_DE_V",'2_FAT_Raw'!$E:$E,"Vertical",'2_FAT_Raw'!$F:$F,"110") | F12: =IF(E12=0,"MISSING — closure required",IF(D12=0,"not in original","covered"))
A13: DRV_DE_A | B13: Axial | C13: 60 | D13: =COUNTIFS('2_FAT_Raw'!$B:$B,"original",'2_FAT_Raw'!$D:$D,"DRV_DE_A",'2_FAT_Raw'!$E:$E,"Axial",'2_FAT_Raw'!$F:$F,"60") | E13: =COUNTIFS('2_FAT_Raw'!$B:$B,"retest",'2_FAT_Raw'!$D:$D,"DRV_DE_A",'2_FAT_Raw'!$E:$E,"Axial",'2_FAT_Raw'!$F:$F,"60") | F13: =IF(E13=0,"MISSING — closure required",IF(D13=0,"not in original","covered")) | G13: driver point not retested; original result passed — deviation, see C-01
A14: DRV_DE_A | B14: Axial | C14: 90_BEP | D14: =COUNTIFS('2_FAT_Raw'!$B:$B,"original",'2_FAT_Raw'!$D:$D,"DRV_DE_A",'2_FAT_Raw'!$E:$E,"Axial",'2_FAT_Raw'!$F:$F,"90_BEP") | E14: =COUNTIFS('2_FAT_Raw'!$B:$B,"retest",'2_FAT_Raw'!$D:$D,"DRV_DE_A",'2_FAT_Raw'!$E:$E,"Axial",'2_FAT_Raw'!$F:$F,"90_BEP") | F14: =IF(E14=0,"MISSING — closure required",IF(D14=0,"not in original","covered")) | G14: driver point not retested; original result passed — deviation, see C-01
A15: DRV_DE_A | B15: Axial | C15: 100 | D15: =COUNTIFS('2_FAT_Raw'!$B:$B,"original",'2_FAT_Raw'!$D:$D,"DRV_DE_A",'2_FAT_Raw'!$E:$E,"Axial",'2_FAT_Raw'!$F:$F,"100") | E15: =COUNTIFS('2_FAT_Raw'!$B:$B,"retest",'2_FAT_Raw'!$D:$D,"DRV_DE_A",'2_FAT_Raw'!$E:$E,"Axial",'2_FAT_Raw'!$F:$F,"100") | F15: =IF(E15=0,"MISSING — closure required",IF(D15=0,"not in original","covered"))
A16: DRV_DE_A | B16: Axial | C16: 110 | D16: =COUNTIFS('2_FAT_Raw'!$B:$B,"original",'2_FAT_Raw'!$D:$D,"DRV_DE_A",'2_FAT_Raw'!$E:$E,"Axial",'2_FAT_Raw'!$F:$F,"110") | E16: =COUNTIFS('2_FAT_Raw'!$B:$B,"retest",'2_FAT_Raw'!$D:$D,"DRV_DE_A",'2_FAT_Raw'!$E:$E,"Axial",'2_FAT_Raw'!$F:$F,"110") | F16: =IF(E16=0,"MISSING — closure required",IF(D16=0,"not in original","covered"))
A17: DRV_NDE_H | B17: Horizontal | C17: 60 | D17: =COUNTIFS('2_FAT_Raw'!$B:$B,"original",'2_FAT_Raw'!$D:$D,"DRV_NDE_H",'2_FAT_Raw'!$E:$E,"Horizontal",'2_FAT_Raw'!$F:$F,"60") | E17: =COUNTIFS('2_FAT_Raw'!$B:$B,"retest",'2_FAT_Raw'!$D:$D,"DRV_NDE_H",'2_FAT_Raw'!$E:$E,"Horizontal",'2_FAT_Raw'!$F:$F,"60") | F17: =IF(E17=0,"MISSING — closure required",IF(D17=0,"not in original","covered")) | G17: driver point not retested; original result passed — deviation, see C-01
A18: DRV_NDE_H | B18: Horizontal | C18: 90_BEP | D18: =COUNTIFS('2_FAT_Raw'!$B:$B,"original",'2_FAT_Raw'!$D:$D,"DRV_NDE_H",'2_FAT_Raw'!$E:$E,"Horizontal",'2_FAT_Raw'!$F:$F,"90_BEP") | E18: =COUNTIFS('2_FAT_Raw'!$B:$B,"retest",'2_FAT_Raw'!$D:$D,"DRV_NDE_H",'2_FAT_Raw'!$E:$E,"Horizontal",'2_FAT_Raw'!$F:$F,"90_BEP") | F18: =IF(E18=0,"MISSING — closure required",IF(D18=0,"not in original","covered")) | G18: driver point not retested; original result passed — deviation, see C-01
A19: DRV_NDE_H | B19: Horizontal | C19: 100 | D19: =COUNTIFS('2_FAT_Raw'!$B:$B,"original",'2_FAT_Raw'!$D:$D,"DRV_NDE_H",'2_FAT_Raw'!$E:$E,"Horizontal",'2_FAT_Raw'!$F:$F,"100") | E19: =COUNTIFS('2_FAT_Raw'!$B:$B,"retest",'2_FAT_Raw'!$D:$D,"DRV_NDE_H",'2_FAT_Raw'!$E:$E,"Horizontal",'2_FAT_Raw'!$F:$F,"100") | F19: =IF(E19=0,"MISSING — closure required",IF(D19=0,"not in original","covered"))
A20: DRV_NDE_H | B20: Horizontal | C20: 110 | D20: =COUNTIFS('2_FAT_Raw'!$B:$B,"original",'2_FAT_Raw'!$D:$D,"DRV_NDE_H",'2_FAT_Raw'!$E:$E,"Horizontal",'2_FAT_Raw'!$F:$F,"110") | E20: =COUNTIFS('2_FAT_Raw'!$B:$B,"retest",'2_FAT_Raw'!$D:$D,"DRV_NDE_H",'2_FAT_Raw'!$E:$E,"Horizontal",'2_FAT_Raw'!$F:$F,"110") | F20: =IF(E20=0,"MISSING — closure required",IF(D20=0,"not in original","covered")) | G20: driver NDE not retested at 110%; original passed — deviation, see C-01
A21: DRV_NDE_V | B21: Vertical | C21: 60 | D21: =COUNTIFS('2_FAT_Raw'!$B:$B,"original",'2_FAT_Raw'!$D:$D,"DRV_NDE_V",'2_FAT_Raw'!$E:$E,"Vertical",'2_FAT_Raw'!$F:$F,"60") | E21: =COUNTIFS('2_FAT_Raw'!$B:$B,"retest",'2_FAT_Raw'!$D:$D,"DRV_NDE_V",'2_FAT_Raw'!$E:$E,"Vertical",'2_FAT_Raw'!$F:$F,"60") | F21: =IF(E21=0,"MISSING — closure required",IF(D21=0,"not in original","covered")) | G21: driver point not retested; original result passed — deviation, see C-01
A22: DRV_NDE_V | B22: Vertical | C22: 90_BEP | D22: =COUNTIFS('2_FAT_Raw'!$B:$B,"original",'2_FAT_Raw'!$D:$D,"DRV_NDE_V",'2_FAT_Raw'!$E:$E,"Vertical",'2_FAT_Raw'!$F:$F,"90_BEP") | E22: =COUNTIFS('2_FAT_Raw'!$B:$B,"retest",'2_FAT_Raw'!$D:$D,"DRV_NDE_V",'2_FAT_Raw'!$E:$E,"Vertical",'2_FAT_Raw'!$F:$F,"90_BEP") | F22: =IF(E22=0,"MISSING — closure required",IF(D22=0,"not in original","covered")) | G22: driver point not retested; original result passed — deviation, see C-01
A23: DRV_NDE_V | B23: Vertical | C23: 100 | D23: =COUNTIFS('2_FAT_Raw'!$B:$B,"original",'2_FAT_Raw'!$D:$D,"DRV_NDE_V",'2_FAT_Raw'!$E:$E,"Vertical",'2_FAT_Raw'!$F:$F,"100") | E23: =COUNTIFS('2_FAT_Raw'!$B:$B,"retest",'2_FAT_Raw'!$D:$D,"DRV_NDE_V",'2_FAT_Raw'!$E:$E,"Vertical",'2_FAT_Raw'!$F:$F,"100") | F23: =IF(E23=0,"MISSING — closure required",IF(D23=0,"not in original","covered"))
A24: DRV_NDE_V | B24: Vertical | C24: 110 | D24: =COUNTIFS('2_FAT_Raw'!$B:$B,"original",'2_FAT_Raw'!$D:$D,"DRV_NDE_V",'2_FAT_Raw'!$E:$E,"Vertical",'2_FAT_Raw'!$F:$F,"110") | E24: =COUNTIFS('2_FAT_Raw'!$B:$B,"retest",'2_FAT_Raw'!$D:$D,"DRV_NDE_V",'2_FAT_Raw'!$E:$E,"Vertical",'2_FAT_Raw'!$F:$F,"110") | F24: =IF(E24=0,"MISSING — closure required",IF(D24=0,"not in original","covered")) | G24: driver NDE not retested at 110%; original passed — deviation, see C-01
A25: DRV_NDE_A | B25: Axial | C25: 60 | D25: =COUNTIFS('2_FAT_Raw'!$B:$B,"original",'2_FAT_Raw'!$D:$D,"DRV_NDE_A",'2_FAT_Raw'!$E:$E,"Axial",'2_FAT_Raw'!$F:$F,"60") | E25: =COUNTIFS('2_FAT_Raw'!$B:$B,"retest",'2_FAT_Raw'!$D:$D,"DRV_NDE_A",'2_FAT_Raw'!$E:$E,"Axial",'2_FAT_Raw'!$F:$F,"60") | F25: =IF(E25=0,"MISSING — closure required",IF(D25=0,"not in original","covered")) | G25: driver point not retested; original result passed — deviation, see C-01
A26: DRV_NDE_A | B26: Axial | C26: 90_BEP | D26: =COUNTIFS('2_FAT_Raw'!$B:$B,"original",'2_FAT_Raw'!$D:$D,"DRV_NDE_A",'2_FAT_Raw'!$E:$E,"Axial",'2_FAT_Raw'!$F:$F,"90_BEP") | E26: =COUNTIFS('2_FAT_Raw'!$B:$B,"retest",'2_FAT_Raw'!$D:$D,"DRV_NDE_A",'2_FAT_Raw'!$E:$E,"Axial",'2_FAT_Raw'!$F:$F,"90_BEP") | F26: =IF(E26=0,"MISSING — closure required",IF(D26=0,"not in original","covered")) | G26: driver point not retested; original result passed — deviation, see C-01
A27: DRV_NDE_A | B27: Axial | C27: 100 | D27: =COUNTIFS('2_FAT_Raw'!$B:$B,"original",'2_FAT_Raw'!$D:$D,"DRV_NDE_A",'2_FAT_Raw'!$E:$E,"Axial",'2_FAT_Raw'!$F:$F,"100") | E27: =COUNTIFS('2_FAT_Raw'!$B:$B,"retest",'2_FAT_Raw'!$D:$D,"DRV_NDE_A",'2_FAT_Raw'!$E:$E,"Axial",'2_FAT_Raw'!$F:$F,"100") | F27: =IF(E27=0,"MISSING — closure required",IF(D27=0,"not in original","covered"))
A28: DRV_NDE_A | B28: Axial | C28: 110 | D28: =COUNTIFS('2_FAT_Raw'!$B:$B,"original",'2_FAT_Raw'!$D:$D,"DRV_NDE_A",'2_FAT_Raw'!$E:$E,"Axial",'2_FAT_Raw'!$F:$F,"110") | E28: =COUNTIFS('2_FAT_Raw'!$B:$B,"retest",'2_FAT_Raw'!$D:$D,"DRV_NDE_A",'2_FAT_Raw'!$E:$E,"Axial",'2_FAT_Raw'!$F:$F,"110") | F28: =IF(E28=0,"MISSING — closure required",IF(D28=0,"not in original","covered")) | G28: driver NDE not retested at 110%; original passed — deviation, see C-01
A29: PMP_DE_H | B29: Horizontal | C29: 60 | D29: =COUNTIFS('2_FAT_Raw'!$B:$B,"original",'2_FAT_Raw'!$D:$D,"PMP_DE_H",'2_FAT_Raw'!$E:$E,"Horizontal",'2_FAT_Raw'!$F:$F,"60") | E29: =COUNTIFS('2_FAT_Raw'!$B:$B,"retest",'2_FAT_Raw'!$D:$D,"PMP_DE_H",'2_FAT_Raw'!$E:$E,"Horizontal",'2_FAT_Raw'!$F:$F,"60") | F29: =IF(E29=0,"MISSING — closure required",IF(D29=0,"not in original","covered"))
A30: PMP_DE_H | B30: Horizontal | C30: 90_BEP | D30: =COUNTIFS('2_FAT_Raw'!$B:$B,"original",'2_FAT_Raw'!$D:$D,"PMP_DE_H",'2_FAT_Raw'!$E:$E,"Horizontal",'2_FAT_Raw'!$F:$F,"90_BEP") | E30: =COUNTIFS('2_FAT_Raw'!$B:$B,"retest",'2_FAT_Raw'!$D:$D,"PMP_DE_H",'2_FAT_Raw'!$E:$E,"Horizontal",'2_FAT_Raw'!$F:$F,"90_BEP") | F30: =IF(E30=0,"MISSING — closure required",IF(D30=0,"not in original","covered"))
A31: PMP_DE_H | B31: Horizontal | C31: 100 | D31: =COUNTIFS('2_FAT_Raw'!$B:$B,"original",'2_FAT_Raw'!$D:$D,"PMP_DE_H",'2_FAT_Raw'!$E:$E,"Horizontal",'2_FAT_Raw'!$F:$F,"100") | E31: =COUNTIFS('2_FAT_Raw'!$B:$B,"retest",'2_FAT_Raw'!$D:$D,"PMP_DE_H",'2_FAT_Raw'!$E:$E,"Horizontal",'2_FAT_Raw'!$F:$F,"100") | F31: =IF(E31=0,"MISSING — closure required",IF(D31=0,"not in original","covered"))
A32: PMP_DE_H | B32: Horizontal | C32: 110 | D32: =COUNTIFS('2_FAT_Raw'!$B:$B,"original",'2_FAT_Raw'!$D:$D,"PMP_DE_H",'2_FAT_Raw'!$E:$E,"Horizontal",'2_FAT_Raw'!$F:$F,"110") | E32: =COUNTIFS('2_FAT_Raw'!$B:$B,"retest",'2_FAT_Raw'!$D:$D,"PMP_DE_H",'2_FAT_Raw'!$E:$E,"Horizontal",'2_FAT_Raw'!$F:$F,"110") | F32: =IF(E32=0,"MISSING — closure required",IF(D32=0,"not in original","covered"))
A33: PMP_DE_V | B33: Vertical | C33: 60 | D33: =COUNTIFS('2_FAT_Raw'!$B:$B,"original",'2_FAT_Raw'!$D:$D,"PMP_DE_V",'2_FAT_Raw'!$E:$E,"Vertical",'2_FAT_Raw'!$F:$F,"60") | E33: =COUNTIFS('2_FAT_Raw'!$B:$B,"retest",'2_FAT_Raw'!$D:$D,"PMP_DE_V",'2_FAT_Raw'!$E:$E,"Vertical",'2_FAT_Raw'!$F:$F,"60") | F33: =IF(E33=0,"MISSING — closure required",IF(D33=0,"not in original","covered"))
A34: PMP_DE_V | B34: Vertical | C34: 90_BEP | D34: =COUNTIFS('2_FAT_Raw'!$B:$B,"original",'2_FAT_Raw'!$D:$D,"PMP_DE_V",'2_FAT_Raw'!$E:$E,"Vertical",'2_FAT_Raw'!$F:$F,"90_BEP") | E34: =COUNTIFS('2_FAT_Raw'!$B:$B,"retest",'2_FAT_Raw'!$D:$D,"PMP_DE_V",'2_FAT_Raw'!$E:$E,"Vertical",'2_FAT_Raw'!$F:$F,"90_BEP") | F34: =IF(E34=0,"MISSING — closure required",IF(D34=0,"not in original","covered"))
A35: PMP_DE_V | B35: Vertical | C35: 100 | D35: =COUNTIFS('2_FAT_Raw'!$B:$B,"original",'2_FAT_Raw'!$D:$D,"PMP_DE_V",'2_FAT_Raw'!$E:$E,"Vertical",'2_FAT_Raw'!$F:$F,"100") | E35: =COUNTIFS('2_FAT_Raw'!$B:$B,"retest",'2_FAT_Raw'!$D:$D,"PMP_DE_V",'2_FAT_Raw'!$E:$E,"Vertical",'2_FAT_Raw'!$F:$F,"100") | F35: =IF(E35=0,"MISSING — closure required",IF(D35=0,"not in original","covered"))
A36: PMP_DE_V | B36: Vertical | C36: 110 | D36: =COUNTIFS('2_FAT_Raw'!$B:$B,"original",'2_FAT_Raw'!$D:$D,"PMP_DE_V",'2_FAT_Raw'!$E:$E,"Vertical",'2_FAT_Raw'!$F:$F,"110") | E36: =COUNTIFS('2_FAT_Raw'!$B:$B,"retest",'2_FAT_Raw'!$D:$D,"PMP_DE_V",'2_FAT_Raw'!$E:$E,"Vertical",'2_FAT_Raw'!$F:$F,"110") | F36: =IF(E36=0,"MISSING — closure required",IF(D36=0,"not in original","covered"))
A37: PMP_DE_A | B37: Axial | C37: 60 | D37: =COUNTIFS('2_FAT_Raw'!$B:$B,"original",'2_FAT_Raw'!$D:$D,"PMP_DE_A",'2_FAT_Raw'!$E:$E,"Axial",'2_FAT_Raw'!$F:$F,"60") | E37: =COUNTIFS('2_FAT_Raw'!$B:$B,"retest",'2_FAT_Raw'!$D:$D,"PMP_DE_A",'2_FAT_Raw'!$E:$E,"Axial",'2_FAT_Raw'!$F:$F,"60") | F37: =IF(E37=0,"MISSING — closure required",IF(D37=0,"not in original","covered"))
A38: PMP_DE_A | B38: Axial | C38: 90_BEP | D38: =COUNTIFS('2_FAT_Raw'!$B:$B,"original",'2_FAT_Raw'!$D:$D,"PMP_DE_A",'2_FAT_Raw'!$E:$E,"Axial",'2_FAT_Raw'!$F:$F,"90_BEP") | E38: =COUNTIFS('2_FAT_Raw'!$B:$B,"retest",'2_FAT_Raw'!$D:$D,"PMP_DE_A",'2_FAT_Raw'!$E:$E,"Axial",'2_FAT_Raw'!$F:$F,"90_BEP") | F38: =IF(E38=0,"MISSING — closure required",IF(D38=0,"not in original","covered"))
A39: PMP_DE_A | B39: Axial | C39: 100 | D39: =COUNTIFS('2_FAT_Raw'!$B:$B,"original",'2_FAT_Raw'!$D:$D,"PMP_DE_A",'2_FAT_Raw'!$E:$E,"Axial",'2_FAT_Raw'!$F:$F,"100") | E39: =COUNTIFS('2_FAT_Raw'!$B:$B,"retest",'2_FAT_Raw'!$D:$D,"PMP_DE_A",'2_FAT_Raw'!$E:$E,"Axial",'2_FAT_Raw'!$F:$F,"100") | F39: =IF(E39=0,"MISSING — closure required",IF(D39=0,"not in original","covered"))
A40: PMP_DE_A | B40: Axial | C40: 110 | D40: =COUNTIFS('2_FAT_Raw'!$B:$B,"original",'2_FAT_Raw'!$D:$D,"PMP_DE_A",'2_FAT_Raw'!$E:$E,"Axial",'2_FAT_Raw'!$F:$F,"110") | E40: =COUNTIFS('2_FAT_Raw'!$B:$B,"retest",'2_FAT_Raw'!$D:$D,"PMP_DE_A",'2_FAT_Raw'!$E:$E,"Axial",'2_FAT_Raw'!$F:$F,"110") | F40: =IF(E40=0,"MISSING — closure required",IF(D40=0,"not in original","covered"))
A41: PMP_NDE_H | B41: Horizontal | C41: 60 | D41: =COUNTIFS('2_FAT_Raw'!$B:$B,"original",'2_FAT_Raw'!$D:$D,"PMP_NDE_H",'2_FAT_Raw'!$E:$E,"Horizontal",'2_FAT_Raw'!$F:$F,"60") | E41: =COUNTIFS('2_FAT_Raw'!$B:$B,"retest",'2_FAT_Raw'!$D:$D,"PMP_NDE_H",'2_FAT_Raw'!$E:$E,"Horizontal",'2_FAT_Raw'!$F:$F,"60") | F41: =IF(E41=0,"MISSING — closure required",IF(D41=0,"not in original","covered"))
...

Sheet 7_Sister_Baseline
A1: SISTER PUMP P-7402B FIELD EVIDENCE
A2: Source: sister_pump_field_baseline_P7402B.csv (values verbatim; section/row locators retained)
A4: File context | B4: Equipment PWRI-220, Tag P-7402B, commissioned 2025-06-20; survey 2026-12-10, 12,840 h; ~95% BEP estimated (file rows 1-5, 8-9)
B5: Header states "Identical to P-2401A" — presumed typo for P-7402A (assumption A7)
A7: OVERALL READINGS AT ~95% BEP (file Section 1, rows 12-24)
A8: Point | B8: Direction | C8: Overall RMS (mm/s) | D8: Note | F8: Source row
A9: MDE_H | B9: Horizontal | C9: 1.42 | D9: Normal | F9: sister file row 13
A10: MDE_A | B10: Axial | C10: 1.55 | D10: Slightly elevated axial - monitor | F10: sister file row 15
A11: PDE_H | B11: Horizontal | C11: 1.72 | D11: Normal | F11: sister file row 19
A12: PNDE_H | B12: Horizontal | C12: 1.51 | D12: Normal | F12: sister file row 22
A13: PNDE_A | B13: Axial | C13: 1.08 | D13: Normal | F13: sister file row 24
A15: TREND — PDE_H overall (file Section 4, rows 40-49)
A16: Survey date | B16: RMS (mm/s) | C16: Hours | D16: Note | F16: Source row
A17: 2025-07-15 | B17: 1.45 | C17: 580 | D17: Post-commissioning baseline | F17: sister file row 41
A18: 2025-10-12 | B18: 1.48 | C18: 2720 | D18: Stable | F18: sister file row 42
A19: 2026-01-18 | B19: 1.52 | C19: 4980 | D19: Stable | F19: sister file row 43
A20: 2026-04-11 | B20: 1.68 | C20: 6940 | D20: Slight increase - continued monitoring | F20: sister file row 44
A21: 2026-05-22 | B21: 2.35 | C21: 7920 | D21: ALARM - bearing noise audible | F21: sister file row 45
A22: 2026-06-05 | B22: 1.38 | C22: 8040 | D22: Post-repair baseline - restored | F22: sister file row 47
A23: 2026-09-19 | B23: 1.55 | C23: 10560 | D23: Normal | F23: sister file row 48
A24: 2026-12-10 | B24: 1.72 | C24: 12840 | D24: Normal - slight upward trend | F24: sister file row 49
A26: KEY MAINTENANCE EVENTS (file Section 5, rows 52-57)
A27: WO | B27: Date | C27: Type | D27: Description / root cause | F27: Source row
A28: WO-2026-0847 | B28: 2026-05-28 | C28: Corrective | D28: DE bearing 6316 C3 replacement - inner race spalling; root cause: contaminated lubricant, WATER INGRESS via breather | F28: sister file row 56
A29: WO-2026-1103 | B29: 2026-09-20 | C29: Preventive | D29: Oil change + desiccant breather upgrade to prevent recurrence | F29: sister file row 57
A31: Reference: current field baseline PDE_H (mm/s) | B31: =B24
A32: Reference: observed sister ALARM level (mm/s) | B32: =B21
A33: Same DE bearing type as P-7402A (6316 C3, datasheet row "Bearing Type - DE") — water-ingress lesson directly transferable (C-09).

Sheet 8_Sensitivity
A1: SENSITIVITY & UNCERTAINTY
A2: How robust is the decision to the rule-version dispute (A1) and to measurement uncertainty? All counts are formulas.
A4: S1. RULE-VERSION DISPUTE — retest FAIL count under each limit
A5: Scenario | B5: Limit (mm/s) | C5: Retest FAILs | D5: Worst fail margin | E5: Reading
A6: Current extract VR-001 (effective 2026-01-01) | B6: ='1_Rules'!$D$6 | C6: =COUNTIFS('2_FAT_Raw'!$B:$B,"retest",'2_FAT_Raw'!$G:$G,">"&'1_Rules'!$D$6) | D6: =MAX('3_Overall_Eval'!E65:E96)-'1_Rules'!$D$6 | E6: =IF(C6>0,"release gate NOT met under current rule","")
A7: Superseded extract VR-000 (withdrawn 2025-12-31) | B7: ='1_Rules'!$D$5 | C7: =COUNTIFS('2_FAT_Raw'!$B:$B,"retest",'2_FAT_Raw'!$G:$G,">"&'1_Rules'!$D$5) | D7: =MAX('3_Overall_Eval'!E65:E96)-'1_Rules'!$D$5 | E7: =IF(C7>0,"STILL FAILS even under withdrawn limit — decision robust to version dispute","would pass only under withdrawn limit")
A9: S2. MEASUREMENT-UNCERTAINTY SENSITIVITY — uncertainty needed to flip each retest exceedance
A10: Retest exceedance | B10: Value (mm/s) | C10: Limit | D10: Over-limit % | E10: Uncertainty to flip verdict
A11: PMP_NDE_V @ 60% BEP (VIB-0092, fat_retest row 92) | B11: 4.495 | C11: ='1_Rules'!$D$6 | D11: =B11/C11-1 | E11: =B11/C11-1
A12: PMP_NDE_H @ 60% BEP (VIB-0091, fat_retest row 91) | B12: 4.159 | C12: ='1_Rules'!$D$6 | D12: =B12/C12-1 | E12: =B12/C12-1
A13: PMP_DE_H @ 110% BEP (VIB-0073, fat_retest row 73) | B13: 3.89 | C13: ='1_Rules'!$D$6 | D13: =B13/C13-1 | E13: =B13/C13-1
A14: PMP_DE_H @ 110% flips on ≥2.4% uncertainty (marginal); the two 60% BEP NDE exceedances (≥9.4%) are robust to plausible Class-1 instrument uncertainty.
A16: S3. WHERE THE ENVELOPE HOLDS
A17: Retest max at 90-100% BEP (mm/s) | B17: =MAX('3_Overall_Eval'!J65:J96)
A18: Margin below limit at 90-100% BEP (mm/s) | B18: ='1_Rules'!$D$6-B17
A19: RESULT: inside the provisional 80-105% BEP envelope every measured point passes with ≥26% margin. Envelope assumption A4 must be confirmed (C-07).

Sheet 9_Thresholds
A1: DERIVED COMMISSIONING ALARM / TRIP SCENARIOS (VR-009 / VR-010)
A2: Blue multiplier cells are editable scenario inputs — NOT approved protection settings. Anchors: sister baseline & alarm event (7_Sister_Baseline).
A4: Parameter | B4: Value | C4: Unit | D4: Basis / locator
A5: Sister field baseline PDE_H @ ~95% BEP | B5: ='7_Sister_Baseline'!B31 | C5: mm/s RMS | D5: 7_Sister_Baseline (sister file row 49)
A6: Sister observed ALARM level 2026-05-22 | B6: ='7_Sister_Baseline'!B32 | C6: mm/s RMS | D6: sister file row 45; preceded WO-2026-0847 bearing failure
A7: FAT acceptance ceiling (current) | B7: ='1_Rules'!$D$6 | C7: mm/s RMS | D7: VR-001 / Test Requirements sheet
A8: Alarm multiplier (editable) | B8: 1.4 | C8: x baseline | D8: scenario input; 1.4 x 1.72 = 2.41, consistent with observed 2.35 alarm event
A9: Trip margin below ceiling (editable) | B9: 0.3 | C9: mm/s RMS | D9: scenario input; keeps trip below 3.8 acceptance ceiling
A11: DERIVED VALUES (formulas)
A12: Recommended commissioning ALARM | B12: =B5*B8 | C12: mm/s RMS | D12: baseline x multiplier
A13: Recommended commissioning TRIP | B13: =B7-B9 | C13: mm/s RMS | D13: ceiling minus margin
A14: Consistency check: alarm <= observed sister alarm? | B14: =IF(B12<=B6*1.05,"YES - bounded by observed event","REVIEW - above observed alarm event")
A15: Consistency check: trip < FAT exceedance floor? | B15: =IF(B13<'1_Rules'!$D$6,"YES - trip below acceptance ceiling","REVIEW")
A16: Action C-08: settings to be approved by machinery protection authority before start-up; values above are recommendations.

Sheet 10_Exceptions
A1: EXCEPTIONS / UNRESOLVED EVIDENCE REGISTER
A2: Ledger evidence states from equipment_evidence_ledger.csv; nothing below is accepted as fact until closed.
A4: ID | B4: Item | C4: Evidence claim | D4: Evidence state | E4: Impact on release | F4: Closure action | G4: Source locator
A5: E-01 | B5: Shaft runout record | C5: 0.021 mm TIR | D5: CONTRADICTED | E5: Numeric claim passes 0.025 limit but evidence is contradicted — cannot be relied on | F5: C-02: re-measure runout pre-commissioning | G5: ledger ME-007; rule VR-006
A6: E-02 | B6: Cold alignment report | C6: 0.045 mm offset | D6: FIELD-VERIFICATION-REQUIRED | E6: Alignment unverified at site; 2X spectral activity claims misalignment contribution | F6: C-03: field laser alignment verification | G6: ledger ME-004; SP-002/SP-009
A7: E-03 | B7: Baseplate level survey | C7: 0.08 mm/m | D7: CONTRADICTED | E7: Foundation quality unresolved — affects installed vibration | F7: C-04: resolve survey contradiction | G7: ledger ME-003
A8: E-04 | B8: Mechanical-run duration | C8: 4 h minimum | D8: NO RECORD SUPPLIED | E8: VR-004 compliance unverified | F8: C-05: obtain signed run-duration record | G8: rule VR-004
A9: E-05 | B9: Missing retest point | C9: PMP_NDE_A @ 60% BEP | D9: REQUIRED / ABSENT | E9: Matrix incomplete at the failing flow point | F9: C-01: close retest point or formal deviation | G9: rule VR-011; fat_retest file ends VIB-0092
A10: E-06 | B10: Spectral phase attribution | C10: 5 discrete exceedances | D10: AMBIGUOUS | E10: Discrete verdicts provisional until tied to run phase | F10: C-06: attribute SP-008/011/022/042/059 | G10: fat_spectral_events.csv (no phase column)
A11: E-07 | B11: POR / AOR | C11: case-specific | D11: NOT STATED ON DATASHEET | E11: Envelope restriction is an assumption | F11: C-07: engineering to confirm POR/AOR | G11: rule VR-008; datasheet
A12: E-08 | B12: Instrument calibration | C12: valid-through 2026-05-31 | D12: INDEPENDENTLY-VERIFIED | E12: Cert covered FAT date 2026-05-15 — CLOSED for FAT; recertify before offshore use | F12: C-12: verify calibration currency offshore | G12: ledger ME-002/ME-010
A13: E-09 | B13: Contract limit version | C13: 3.8 vs 4.2 mm/s | D13: VERSION DISPUTE | E13: Superseded 4.2 would not rescue worst fail (8_Sensitivity) | F13: Resolved: apply current 3.8 | G13: rule VR-000 vs VR-001
A14: E-10 | B14: Sister file header typo | C14: "Identical to P-2401A" | D14: CLAIM | E14: Treat sister data as analogous, pending confirmation of identity | F14: C-07 (bundle): confirm comparability | G14: sister file row 1

Sheet 11_Disposition
A1: DISPOSITION — COMPUTED VERDICT
A2: Verdict cell is a formula over the evaluation sheets. Conditions C-01..C-12 below.
A4: Retest points evaluated | B4: =COUNTIF('2_FAT_Raw'!$B:$B,"retest")
A5: Retest exceedances vs 3.8 mm/s | B5: =COUNTIFS('2_FAT_Raw'!$B:$B,"retest",'2_FAT_Raw'!$G:$G,">"&'1_Rules'!$D$6)
A6: Hard evidence gap (VR-011 missing PMP_NDE_A @60%) | B6: =COUNTIFS('6_Coverage_Check'!$A$5:$A$52,"PMP*",'6_Coverage_Check'!$F$5:$F$52,"MISSING — closure required")
A7: Max inside 90-100% BEP band (mm/s) | B7: =MAX('3_Overall_Eval'!J65:J96)
A9: VERDICT | B9: =IF(B5=0,"UNCONDITIONAL RELEASE",IF(AND(B5<=3,B6<=1,B7<'1_Rules'!$D$6),"CONDITIONAL RELEASE — RESTRICTED ENVELOPE + C-01..C-12","DO NOT RELEASE"))
A11: CONDITIONS / CLOSURE ACTIONS (owners are recommended roles, not assigned authority)
A12: ID | B12: Gate | C12: Action
A13: C-01 | B13: Evidence | C13: Close missing retest point PMP_NDE_A @ 60% BEP (VR-011) or record a formal, risk-assessed deviation covering it and the un-retested driver points.
A14: C-02 | B14: Evidence | C14: Re-measure shaft runout vs 0.025 mm TIR (VR-006); ledger claim ME-007 is contradicted.
A15: C-03 | B15: Evidence | C15: Field laser-alignment verification at installation (claim ME-004, 0.045 mm, field-verification-required).
A16: C-04 | B16: Evidence | C16: Resolve baseplate level survey contradiction (ME-003, 0.08 mm/m).
A17: C-05 | B17: Evidence | C17: Obtain signed 4-hour mechanical-run duration record (VR-004); none supplied.
A18: C-06 | B18: Evidence | C18: Attribute spectral exceedances SP-008/011/022/042/059 to run phase; re-evaluate VR-002.
A19: C-07 | B19: Operating | C19: Engineering to confirm POR/AOR (VR-008); until then restrict to provisional 80-105% BEP envelope.
A20: C-08 | B20: Protection | C20: Approve & implement commissioning alarm/trip per 9_Thresholds (recommendation ~2.4 / ~3.5 mm/s RMS).
A21: C-09 | B21: Reliability | C21: Fit desiccant breather + oil-analysis program (sister WO-2026-0847/1103 water-ingress lesson; same 6316 C3 DE bearing).
A22: C-10 | B22: Transient | C22: Minimise dwell in 1800-2150 rpm resonance window during run-up/coast-down (5_Transient); log every transient.
A23: C-11 | B23: Commissioning | C23: Monitored commissioning run at 90-100% BEP with hold points; no sustained operation <80% or >105% BEP pending C-07.
A24: C-12 | B24: Quality | C24: Verify instrument calibration currency offshore (cert expired 2026-05-31, ledger ME-002).
A26: Both deliverables agree: workbook values above are the numbers quoted on slides 2-6 of rotating_equipment_release_board.pptx.

Sheet 12_Machine_Classification
A1: MACHINE CATEGORY & ISO 10816 ZONE BOUNDARIES (iso-zone)
A2: Classification is DERIVED from datasheet facts (service, power, mounting), not copied from any submitted classification. Zone boundaries per ISO 10816-3 Group 2 (flexibly mounted) machinery; the contract FAT limit VR-001 = 3.8 mm/s RMS is the governing acceptance line and is retained as the contractual value.
A4: STEP 1 — FACTS FROM DATASHEET (pump_specification_P7402A.xlsx)
A5: Fact | B5: Value | C5: Source locator
A6: Service | B6: Produced Water Reinjection Circulation | C6: Pump Datasheet 'Service' row
A7: Type | B7: Horizontal, End-Suction, Single Stage | C7: Pump Datasheet 'Type' row
A8: Driver power | B8: 75 kW electric motor | C8: Pump Datasheet 'Driver' row
A9: Rated speed | B9: 2980 RPM | C9: Pump Datasheet 'Rated Speed' row
A10: Impeller | B10: Closed, 6-vane, 280 mm | C10: Pump Datasheet 'Impeller' row
A11: Coupling | B11: Flexible disc, spacer type | C11: Pump Datasheet 'Coupling' row
A12: Fluid | B12: Produced water @ 35 degC | C12: Pump Datasheet 'Operating Temperature' row
A14: STEP 2 — DERIVED CLASSIFICATION
A15: Item | B15: Value | C15: Unit | D15: Basis / locator
A16: Machine category | B16: Centrifugal pump, rigidly/flexibly mounted rotating machinery | C16: Derived from Type + Driver power + Rated speed
A17: ISO 10816-3 group | B17: Group 2 (rigidly mounted, power 15-300 kW, 120-15000 rpm) | C17: 75 kW @ 2980 rpm falls in Group 2 power/speed band
A18: ISO 10816-3 zone A/B boundary | B18: 2.8 | C18: mm/s RMS | D18: Group 2 zone boundary (velocity)
A19: ISO 10816-3 zone B/C boundary | B19: 4.5 | C19: mm/s RMS | D19: Group 2 zone boundary (velocity)
A20: ISO 10816-3 zone C/D boundary | B20: 7.1 | C20: mm/s RMS | D20: Group 2 zone boundary (velocity)
A21: Governing CONTRACT limit (VR-001) | B21: 3.8 | C21: mm/s RMS | D21: vibration_acceptance_rule_matrix.csv VR-001, effective 2026-01-01; Test Requirements sheet
A22: Superseded contract limit (VR-000) | B22: 4.2 | C22: mm/s RMS | D22: VR-000, withdrawal notice dated 2025-12-31 — sensitivity only
A24: STEP 3 — WHERE THE GOVERNING LIMIT SITS & VERSION/DATE LIMITATION
A25: The contract limit 3.8 mm/s RMS lies inside the ISO Group 2 B/C zone (2.8-4.5), i.e. the contract is STRICTER than the ISO 'good' (A/B) boundary of 2.8 but LOOSER than the B/C boundary of 4.5. Acceptance is judged against the contract value, not the ISO zone.
A26: VERSION/DATE LIMITATION: VR-001 (3.8 mm/s RMS) is effective 2026-01-01 and is the current reference extract. VR-000 (4.2 mm/s RMS) was withdrawn 2025-12-31 and is retained ONLY as a sensitivity case (see 8_Sensitivity). The worst retest exceedance (4.495 mm/s) fails under BOTH the current 3.8 and the withdrawn 4.2 limit, so the decision does not hinge on the version.
A27: CONTROLLING MEASUREMENT POINTS (iso-zone control):
A28: Control | B28: Measurement ID | C28: Point | D28: Flow %BEP | E28: overall_velocity_rms_mm_s | F28: Note
A29: original_max | B29: VIB-0059 | C29: PMP_NDE_V | D29: 60 | E29: 5.659 | F29: PMP_NDE_V @ 60% BEP is the controlling original point
A30: retest_max | B30: VIB-0092 | C30: PMP_NDE_V | D30: 60 | E30: 4.495 | F30: PMP_NDE_V @ 60% BEP remains controlling after retest

Sheet 13_Measurement_Controls
A1: MEASUREMENT CONTROLS — ALL 92 FAT ROWS (off-design / unit-conversion control)
A2: Verbatim transcription of fat_retest_measurements.csv (60 original + 32 retest). Each row carries the full measurement domain set: overall & peak velocity (mm/s), displacement (um), acceleration (g), and the spectral frequency/order basis (1X = 49.663 Hz = 2980 rpm; BPF = 6X = 297.98 Hz). No value is imputed.
A4: measurement_id | B4: test_phase | C4: measurement_point | D4: direction | E4: flow_condition_pct_bep | F4: overall_velocity_rms_mm_s | G4: peak_velocity_mm_s | H4: displacement_um | I4: acceleration_g | J4: frequency_1X_Hz | K4: order_BPF | L4: spectral_amplitude_mm_s | M4: off_design_region | N4: retest_vs_3.8
A5: VIB-0001 | B5: original | C5: DRV_DE_H | D5: Horizontal | E5: 100 | F5: 2.349 | G5: 3.326 | H5: 18.71 | I5: 0.427 | J5: 49.663 | K5: 6X (BPF) | M5: ON-DESIGN (rated duty)
A6: VIB-0002 | B6: original | C6: DRV_DE_V | D6: Vertical | E6: 100 | F6: 1.913 | G6: 2.711 | H6: 15.24 | I6: 0.358 | J6: 49.663 | K6: 6X (BPF) | M6: ON-DESIGN (rated duty)
A7: VIB-0003 | B7: original | C7: DRV_DE_A | D7: Axial | E7: 100 | F7: 4.013 | G7: 5.68 | H7: 32 | I7: 0.731 | J7: 49.663 | K7: 6X (BPF) | M7: ON-DESIGN (rated duty)
A8: VIB-0004 | B8: original | C8: DRV_NDE_H | D8: Horizontal | E8: 100 | F8: 2.018 | G8: 2.857 | H8: 16.04 | I8: 0.383 | J8: 49.663 | K8: 6X (BPF) | M8: ON-DESIGN (rated duty)
A9: VIB-0005 | B9: original | C9: DRV_NDE_V | D9: Vertical | E9: 100 | F9: 1.686 | G9: 2.384 | H9: 13.43 | I9: 0.323 | J9: 49.663 | K9: 6X (BPF) | M9: ON-DESIGN (rated duty)
A10: VIB-0006 | B10: original | C10: DRV_NDE_A | D10: Axial | E10: 100 | F10: 1.864 | G10: 2.638 | H10: 14.87 | I10: 0.356 | J10: 49.663 | K10: 6X (BPF) | M10: ON-DESIGN (rated duty)
A11: VIB-0007 | B11: original | C11: PMP_DE_H | D11: Horizontal | E11: 100 | F11: 3.001 | G11: 4.244 | H11: 23.9 | I11: 0.548 | J11: 49.663 | K11: 6X (BPF) | L11: 1.997 | M11: ON-DESIGN (rated duty)
A12: VIB-0008 | B12: original | C12: PMP_DE_V | D12: Vertical | E12: 100 | F12: 2.176 | G12: 3.082 | H12: 17.39 | I12: 0.417 | J12: 49.663 | K12: 6X (BPF) | M12: ON-DESIGN (rated duty)
A13: VIB-0009 | B13: original | C13: PMP_DE_A | D13: Axial | E13: 100 | F13: 2.005 | G13: 2.834 | H13: 15.96 | I13: 0.389 | J13: 49.663 | K13: 6X (BPF) | M13: ON-DESIGN (rated duty)
A14: VIB-0010 | B14: original | C14: PMP_NDE_H | D14: Horizontal | E14: 100 | F14: 2.49 | G14: 3.529 | H14: 19.86 | I14: 0.473 | J14: 49.663 | K14: 6X (BPF) | M14: ON-DESIGN (rated duty)
A15: VIB-0011 | B15: original | C15: PMP_NDE_V | D15: Vertical | E15: 100 | F15: 2.049 | G15: 2.898 | H15: 16.35 | I15: 0.393 | J15: 49.663 | K15: 6X (BPF) | M15: ON-DESIGN (rated duty)
A16: VIB-0012 | B16: original | C16: PMP_NDE_A | D16: Axial | E16: 100 | F16: 1.801 | G16: 2.55 | H16: 14.37 | I16: 0.344 | J16: 49.663 | K16: 6X (BPF) | M16: ON-DESIGN (rated duty)
A17: VIB-0013 | B17: original | C17: DRV_DE_H | D17: Horizontal | E17: 110 | F17: 3.015 | G17: 4.272 | H17: 24.08 | I17: 0.576 | J17: 49.663 | K17: 6X (BPF) | M17: OFF-DESIGN high-flow (above rated)
A18: VIB-0014 | B18: original | C18: DRV_DE_V | D18: Vertical | E18: 110 | F18: 2.464 | G18: 3.485 | H18: 19.69 | I18: 0.474 | J18: 49.663 | K18: 6X (BPF) | M18: OFF-DESIGN high-flow (above rated)
A19: VIB-0015 | B19: original | C19: DRV_DE_A | D19: Axial | E19: 110 | F19: 3.204 | G19: 4.536 | H19: 25.53 | I19: 0.62 | J19: 49.663 | K19: 6X (BPF) | M19: OFF-DESIGN high-flow (above rated)
A20: VIB-0016 | B20: original | C20: DRV_NDE_H | D20: Horizontal | E20: 110 | F20: 2.465 | G20: 3.488 | H20: 19.64 | I20: 0.471 | J20: 49.663 | K20: 6X (BPF) | M20: OFF-DESIGN high-flow (above rated)
A21: VIB-0017 | B21: original | C21: DRV_NDE_V | D21: Vertical | E21: 110 | F21: 2.289 | G21: 2.984 | H21: 16.77 | I21: 0.401 | J21: 49.663 | K21: 6X (BPF) | M21: OFF-DESIGN high-flow (above rated)
A22: VIB-0018 | B22: original | C22: DRV_NDE_A | D22: Axial | E22: 110 | F22: 2.194 | G22: 3.105 | H22: 17.49 | I22: 0.424 | J22: 49.663 | K22: 6X (BPF) | M22: OFF-DESIGN high-flow (above rated)
A23: VIB-0019 | B23: original | C23: PMP_DE_H | D23: Horizontal | E23: 110 | F23: 5.413 | G23: 7.651 | H23: 43.2 | I23: 1.031 | J23: 49.663 | K23: 6X (BPF) | L23: 2.85 | M23: OFF-DESIGN high-flow (above rated)
A24: VIB-0020 | B24: original | C24: PMP_DE_V | D24: Vertical | E24: 110 | F24: 3.633 | G24: 5.141 | H24: 29 | I24: 0.691 | J24: 49.663 | K24: 6X (BPF) | M24: OFF-DESIGN high-flow (above rated)
A25: VIB-0021 | B25: original | C25: PMP_DE_A | D25: Axial | E25: 110 | F25: 2.822 | G25: 3.991 | H25: 22.53 | I25: 0.537 | J25: 49.663 | K25: 6X (BPF) | M25: OFF-DESIGN high-flow (above rated)
A26: VIB-0022 | B26: original | C26: PMP_NDE_H | D26: Horizontal | E26: 110 | F26: 3.875 | G26: 5.482 | H26: 30.92 | I26: 0.742 | J26: 49.663 | K26: 6X (BPF) | M26: OFF-DESIGN high-flow (above rated)
A27: VIB-0023 | B27: original | C27: PMP_NDE_V | D27: Vertical | E27: 110 | F27: 2.997 | G27: 4.245 | H27: 23.94 | I27: 0.573 | J27: 49.663 | K27: 6X (BPF) | M27: OFF-DESIGN high-flow (above rated)
A28: VIB-0024 | B28: original | C28: PMP_NDE_A | D28: Axial | E28: 110 | F28: 2.315 | G28: 3.272 | H28: 18.42 | I28: 0.442 | J28: 49.663 | K28: 6X (BPF) | M28: OFF-DESIGN high-flow (above rated)
A29: VIB-0025 | B29: original | C29: DRV_DE_H | D29: Horizontal | E29: 90_BEP | F29: 1.904 | G29: 2.691 | H29: 15.21 | I29: 0.362 | J29: 49.663 | K29: 6X (BPF) | M29: NEAR-BEP (best-efficiency vicinity)
A30: VIB-0026 | B30: original | C30: DRV_DE_V | D30: Vertical | E30: 90_BEP | F30: 1.582 | G30: 2.238 | H30: 12.6 | I30: 0.302 | J30: 49.663 | K30: 6X (BPF) | M30: NEAR-BEP (best-efficiency vicinity)
A31: VIB-0027 | B31: original | C31: DRV_DE_A | D31: Axial | E31: 90_BEP | F31: 1.759 | G31: 2.492 | H31: 14.03 | I31: 0.335 | J31: 49.663 | K31: 6X (BPF) | M31: NEAR-BEP (best-efficiency vicinity)
A32: VIB-0028 | B32: original | C32: DRV_NDE_H | D32: Horizontal | E32: 90_BEP | F32: 1.695 | G32: 2.401 | H32: 13.48 | I32: 0.326 | J32: 49.663 | K32: 6X (BPF) | M32: NEAR-BEP (best-efficiency vicinity)
