Workbook

Sheet AAPL-3-Statements
B2: =Company_Name&" - Financial Statements" -> Apple Inc. - Financial Statements
B3: ($ in Millions, Except Per Share Amounts in Dollars and Share Counts in Thousands)
B5: Assumptions & Valuation Overview
B7: Valuation Date: | E7: 40207 | G7: Last Historical Year: | I7: 2009 | K7: Days in Year: | M7: 360
B8: Company Name: | E8: Apple Inc. | G8: Debt Issue Date: | I8: 2010 | K8: Debt Amount: | M8: 1000
B9: Share Price: | E9: 192.06 | G9: Share Units: | I9: 1000 | K9: Tax Rate: | M9: 0.3
B11: Basic Shares Outstanding: | E11: 900678.47 | G11: Options Calculations (in Thousands Except Exercise Price):
B12: Basic Equity Value: | E12: =E11/Units*Share_Price -> 172984.31
B13: Diluted Shares Outstanding: | E13: =E11+J20 -> 920525.62 | I13: Exercise
B14: Diluted Equity Value: | E14: =E13/Units*Share_Price -> 176796.15 | G14: Name | H14: Number | I14: Price | J14: Dilution
B15: Less: Cash & Investments | E15: =H99+H100+H108 -> 35395 | G15: Tranche A | H15: 34375 | I15: 81.17 | J15: =IF(I15>Share_Price,0,H15-H15*I15/Share_Price) -> 19847.151
B16: Plus: Debt | E16: =H124 -> 0 | G16: Tranche B
B17: Plus: Minority Interest | E17: 0 | G17: Tranche C
B18: Plus: Preferred Stock | E18: 0 | G18: Tranche D
B19: Plus: Other Liabilities | E19: 0 | G19: Tranche E
B20: Enterprise Value: | E20: =Equity_Value-E15+E16+E17+E18+E19 -> 141401.15 | G20: Total | J20: =SUM(J15:J19) -> 19847.151
F22: Historical | I22: Projections
F23: =G23-1 -> 2007 | G23: =H23-1 -> 2008 | H23: =Hist_Year -> 2009 | I23: =H23+1 -> 2010 | J23: =I23+1 -> 2011 | K23: =J23+1 -> 2012 | L23: =K23+1 -> 2013 | M23: =L23+1 -> 2014
F24: ="FY "&Hist_Year-2 -> FY 2007 | G24: ="FY "&Hist_Year-1 -> FY 2008 | H24: ="FY "&Hist_Year -> FY 2009 | I24: ="FY "&Hist_Year+1&"E" -> FY 2010E | J24: ="FY "&Hist_Year+2&"E" -> FY 2011E | K24: ="FY "&Hist_Year+3&"E" -> FY 2012E | L24: ="FY "&Hist_Year+4&"E" -> FY 2013E | M24: ="FY "&Hist_Year+5&"E" -> FY 2014E
B26: EV / Revenue: | F26: =Enterprise_Value/F66 -> 5.7531594 | G26: =Enterprise_Value/G66 -> 3.7716026 | H26: =Enterprise_Value/H66 -> 3.29568 | I26: =Enterprise_Value/I66 -> 2.636544 | J26: =Enterprise_Value/J66 -> 2.2534564 | K26: =Enterprise_Value/K66 -> 2.0301409 | L26: =Enterprise_Value/L66 -> 1.8625146 | M26: =Enterprise_Value/M66 -> 1.7406679
B27: EV / EBIT: | F27: =Enterprise_Value/F90 -> 30.415391 | G27: =Enterprise_Value/G90 -> 15.990179 | H27: =Enterprise_Value/H90 -> 11.357522 | I27: =Enterprise_Value/I90 -> 9.1094316 | J27: =Enterprise_Value/J90 -> 7.7816399 | K27: =Enterprise_Value/K90 -> 7.0059466 | L27: =Enterprise_Value/L90 -> 6.4223593 | M27: =Enterprise_Value/M90 -> 6.0012089
B28: EV / EBITDA: | F28: =Enterprise_Value/F91 -> 28.41663 | G28: =Enterprise_Value/G91 -> 15.140931 | H28: =Enterprise_Value/H91 -> 10.725209 | I28: =Enterprise_Value/I91 -> 8.5801669 | J28: =Enterprise_Value/J91 -> 7.333476 | K28: =Enterprise_Value/K91 -> 6.6067352 | L28: =Enterprise_Value/L91 -> 6.0612249 | M28: =Enterprise_Value/M91 -> 5.6646962
B30: Equity Value / FCF: | F30: =Equity_Value/F92 -> 37.338152 | G30: =Equity_Value/G92 -> 20.787319 | H30: =Equity_Value/H92 -> 17.146363 | I30: =Equity_Value/I92 -> 13.53647 | J30: =Equity_Value/J92 -> 12.094069 | K30: =Equity_Value/K92 -> 10.941841 | L30: =Equity_Value/L92 -> 10.098435 | M30: =Equity_Value/M92 -> 9.1218144
B31: P / E: | F31: =Share_Price/F87 -> 48.869076 | G31: =Share_Price/G87 -> 28.315871 | H31: =Share_Price/H87 -> 21.153537 | I31: =Share_Price/I87 -> 16.574667 | J31: =Share_Price/J87 -> 14.13121 | K31: =Share_Price/K87 -> 12.208721 | L31: =Share_Price/L87 -> 11.084718 | M31: =Share_Price/M87 -> 9.8165282
B32: P / BV: | G32: =Share_Price/G93 -> 7.9461049 | H32: =Share_Price/H93 -> 5.5576627 | I32: =Share_Price/I93 -> 4.0718411 | J32: =Share_Price/J93 -> 3.1005085 | K32: =Share_Price/K93 -> 2.4318258 | L32: =Share_Price/L93 -> 1.9657387 | M32: =Share_Price/M93 -> 1.6171864
B34: Operating Assumptions
F36: =F22 -> Historical | I36: =I22 -> Projections
F37: =F24 -> FY 2007 | G37: =G24 -> FY 2008 | H37: =H24 -> FY 2009 | I37: =I24 -> FY 2010E | J37: =J24 -> FY 2011E | K37: =K24 -> FY 2012E | L37: =L24 -> FY 2013E | M37: =M24 -> FY 2014E
B39: Revenue Growth %: | F39: =F66/19315-1 -> 0.27248253 | G39: =G66/F66-1 -> 0.52538856 | H39: =H66/G66-1 -> 0.14440799 | I39: 0.25 | J39: 0.17 | K39: 0.11 | L39: 0.09 | M39: 0.07
B40: COGS % Revenue: | F40: =F67/F66 -> 0.66246236 | G40: =G67/G66 -> 0.64145173 | H40: =H67/H66 -> 0.59024201 | I40: =H40 -> 0.59024201 | J40: =I40 -> 0.59024201 | K40: =J40 -> 0.59024201 | L40: =K40 -> 0.59024201 | M40: =L40 -> 0.59024201
B41: R&D % Revenue: | F41: =F70/F66 -> 0.024249329 | G41: =G70/G66 -> 0.020235968 | H41: =H70/H66 -> 0.019352834 | I41: =H41 -> 0.019352834 | J41: =I41 -> 0.019352834 | K41: =J41 -> 0.019352834 | L41: =K41 -> 0.019352834 | M41: =L41 -> 0.019352834
B42: SG&A % Revenue: | F42: =F71/F66 -> 0.11083082 | G42: =G71/G66 -> 0.089212522 | H42: =H71/H66 -> 0.083121625 | I42: =H42 -> 0.083121625 | J42: =I42 -> 0.083121625 | K42: =J42 -> 0.083121625 | L42: =K42 -> 0.083121625 | M42: =L42 -> 0.083121625
B44: Stock-Based Compensation % Revenue: | F44: =F76/F66 -> 0.0098462039 | G44: =G76/G66 -> 0.013763303 | H44: =H76/H66 -> 0.016548188 | I44: =H44 -> 0.016548188 | J44: =I44 -> 0.016548188 | K44: =J44 -> 0.016548188 | L44: =K44 -> 0.016548188 | M44: =L44 -> 0.016548188
B45: Depreciation & Amortization % Revenue: | F45: =F74/F66 -> 0.013304581 | G45: =G74/G66 -> 0.013229842 | H45: =H74/H66 -> 0.017107563 | I45: =H45 -> 0.017107563 | J45: =I45 -> 0.017107563 | K45: =J45 -> 0.017107563 | L45: =K45 -> 0.017107563 | M45: =L45 -> 0.017107563
B46: Effective Cash Interest Rate: | F46: 0.0527 | G46: 0.0344 | H46: 0.0143 | I46: 0.01 | J46: 0.01 | K46: 0.02 | L46: 0.02 | M46: 0.03
B47: Debt Interest Rate: | F47: 0 | G47: 0 | H47: 0 | I47: 0.09 | J47: =I47 -> 0.09 | K47: =J47 -> 0.09 | L47: =K47 -> 0.09 | M47: =L47 -> 0.09
B48: Effective Tax Rate: | F48: =F83/F82 -> 0.30183779 | G48: =G83/G82 -> 0.3160836 | H48: =H83/H82 -> 0.31750373 | I48: =Tax_Rate -> 0.3 | J48: =Tax_Rate -> 0.3 | K48: =Tax_Rate -> 0.3 | L48: =Tax_Rate -> 0.3 | M48: =Tax_Rate -> 0.3
B50: Accounts Receivable % Revenue: | G50: =G101/G66 -> 0.064602171 | H50: =H101/H66 -> 0.078335858 | I50: =I51/Days_In_Year -> 0.078335858 | J50: =J51/Days_In_Year -> 0.078335858 | K50: =K51/Days_In_Year -> 0.078335858 | L50: =L51/Days_In_Year -> 0.078335858 | M50: =M51/Days_In_Year -> 0.078335858
B51: Accounts Receivable Days: | G51: =G50*Days_In_Year -> 23.256782 | H51: =H50*Days_In_Year -> 28.200909 | I51: =H51 -> 28.200909 | J51: =I51 -> 28.200909 | K51: =J51 -> 28.200909 | L51: =K51 -> 28.200909 | M51: =L51 -> 28.200909
B52: Inventory % COGS: | G52: =G102/G67 -> 0.021165415 | H52: =H102/H67 -> 0.017966909 | I52: =H52 -> 0.017966909 | J52: =I52 -> 0.017966909 | K52: =J52 -> 0.017966909 | L52: =K52 -> 0.017966909 | M52: =L52 -> 0.017966909
...

Sheet ValSum
B2: ="Valuation Summary - "&TEXT(Company_Name,"") -> Valuation Summary - Apple Inc.
B3: ($ in Millions, Except Per Share Amounts in Dollars and Share Counts in Thousands)
B5: ="Valuation Statistics - "&TEXT(Company_Name,"") -> Valuation Statistics - Apple Inc. | C5: =TEXT(Company_Name,"")&" - Range of Valuation Multiples / Premiums" -> Apple Inc. - Range of Valuation Multiples / Premiums | I5: =TEXT(Company_Name,"")&" - Implied Per Share Value Range" -> Apple Inc. - Implied Per Share Value Range
D7: 25th | F7: 75th | H7: Applicable | J7: 25th | L7: 75th
C8: Minimum | D8: Pecentile | E8: Median | F8: Pecentile | G8: Maximum | H8: =TEXT(Company_Name,"") -> Apple Inc. | I8: Minimum | J8: Pecentile | K8: Median | L8: Pecentile | M8: Maximum
B9: Methodology Name | C9: Multiple | D9: Multiple | E9: Multiple | F9: Multiple | G9: Multiple | H9: Figure | I9: Multiple | J9: Multiple | K9: Multiple | L9: Multiple | M9: Multiple
B11: Public Company Comparables:
B12: =Hist_Year&" EV / Revenue:" -> 2009 EV / Revenue: | C12: ='Public Comps'!$L$35 -> 0.29321149 | D12: ='Public Comps'!$L$34 -> 0.45467864 | E12: ='Public Comps'!$L$33 -> 1.086233 | F12: ='Public Comps'!$L$32 -> 2.8302336 | G12: ='Public Comps'!$L$31 -> 3.0646433 | H12: ='AAPL-3-Statements'!H66 -> 42905 | I12: =(C12*$H12+$R$12)*Units/Diluted_Shares -> 52.117223 | J12: =(D12*$H12+$R$12)*Units/Diluted_Shares -> 59.643084 | K12: =(E12*$H12+$R$12)*Units/Diluted_Shares -> 89.079351 | L12: =(F12*$H12+$R$12)*Units/Diluted_Shares -> 170.3659 | M12: =(G12*$H12+$R$12)*Units/Diluted_Shares -> 181.29156 | O12: Balance Sheet Adjustment: | R12: ='AAPL-3-Statements'!E15-'AAPL-3-Statements'!E16-'AAPL-3-Statements'!E17-'AAPL-3-Statements'!E18-'AAPL-3-Statements'!E19 -> 35395
B13: =Hist_Year+1&"E EV / Revenue:" -> 2010E EV / Revenue: | C13: ='Public Comps'!$M$35 -> 0.27229807 | D13: ='Public Comps'!$M$34 -> 0.48355989 | E13: ='Public Comps'!$M$33 -> 1.0020225 | F13: ='Public Comps'!$M$32 -> 2.323086 | G13: ='Public Comps'!$M$31 -> 2.5914302 | H13: ='AAPL-3-Statements'!I66 -> 53631.25 | I13: =(C13*$H13+$R$12)*Units/Diluted_Shares -> 54.315366 | J13: =(D13*$H13+$R$12)*Units/Diluted_Shares -> 66.623807 | K13: =(E13*$H13+$R$12)*Units/Diluted_Shares -> 96.830245 | L13: =(F13*$H13+$R$12)*Units/Diluted_Shares -> 173.79745 | M13: =(G13*$H13+$R$12)*Units/Diluted_Shares -> 189.4316
B14: =Hist_Year&" EV / EBITDA:" -> 2009 EV / EBITDA: | C14: ='Public Comps'!$N$35 -> 4.4015957 | D14: ='Public Comps'!$N$34 -> 7.3014148 | E14: ='Public Comps'!$N$33 -> 7.5719685 | F14: ='Public Comps'!$N$32 -> 10.586646 | G14: ='Public Comps'!$N$31 -> 11.517707 | H14: ='AAPL-3-Statements'!H91 -> 13184 | I14: =(C14*$H14+$R$12)*Units/Diluted_Shares -> 101.49162 | J14: =(D14*$H14+$R$12)*Units/Diluted_Shares -> 143.02356 | K14: =(E14*$H14+$R$12)*Units/Diluted_Shares -> 146.8985 | L14: =(F14*$H14+$R$12)*Units/Diluted_Shares -> 190.07546 | M14: =(G14*$H14+$R$12)*Units/Diluted_Shares -> 203.41036
B15: =Hist_Year+1&"E EV / EBITDA:" -> 2010E EV / EBITDA: | C15: ='Public Comps'!$O$35 -> 3.6521838 | D15: ='Public Comps'!$O$34 -> 5.0613455 | E15: ='Public Comps'!$O$33 -> 5.5347156 | F15: ='Public Comps'!$O$32 -> 6.842085 | G15: ='Public Comps'!$O$31 -> 8.3506373 | H15: ='AAPL-3-Statements'!I91 -> 16480 | I15: =(C15*$H15+$R$12)*Units/Diluted_Shares -> 103.83523 | J15: =(D15*$H15+$R$12)*Units/Diluted_Shares -> 129.06319 | K15: =(E15*$H15+$R$12)*Units/Diluted_Shares -> 137.53785 | L15: =(F15*$H15+$R$12)*Units/Diluted_Shares -> 160.94344 | M15: =(G15*$H15+$R$12)*Units/Diluted_Shares -> 187.95077
B16: =Hist_Year&" P / E:" -> 2009 P / E: | C16: ='Public Comps'!$P$35 -> 14.990446 | D16: ='Public Comps'!$P$34 -> 16.054965 | E16: ='Public Comps'!$P$33 -> 19.736491 | F16: ='Public Comps'!$P$32 -> 29.089089 | G16: ='Public Comps'!$P$31 -> 47.166825 | H16: ='AAPL-3-Statements'!H87 -> 9.0793325 | I16: =C16*$H16 -> 136.10324 | J16: =D16*$H16 -> 145.76837 | K16: =E16*$H16 -> 179.19416 | L16: =F16*$H16 -> 264.10951 | M16: =G16*$H16 -> 428.24329
B17: =Hist_Year+1&"E P / E:" -> 2010E P / E: | C17: ='Public Comps'!$Q$35 -> 10.932203 | D17: ='Public Comps'!$Q$34 -> 12.162791 | E17: ='Public Comps'!$Q$33 -> 16.282609 | F17: ='Public Comps'!$Q$32 -> 16.616702 | G17: ='Public Comps'!$Q$31 -> 44.573394 | H17: ='AAPL-3-Statements'!I87 -> 11.587563 | I17: =C17*$H17 -> 126.6776 | J17: =D17*$H17 -> 140.9371 | K17: =E17*$H17 -> 188.67575 | L17: =F17*$H17 -> 192.54708 | M17: =G17*$H17 -> 516.49702
B19: Precedent Transactions:
B20: Trailing EV / Revenue: | C20: ='M&A-Comps'!$K$20 -> 0.40673666 | D20: ='M&A-Comps'!$K$19 -> 1.9443931 | E20: ='M&A-Comps'!$K$18 -> 2.732626 | F20: ='M&A-Comps'!$K$17 -> 6.0324032 | G20: ='M&A-Comps'!$K$16 -> 8.278749 | H20: ='AAPL-3-Statements'!H66 -> 42905 | I20: =(C20*$H20+$R$12)*Units/Diluted_Shares -> 57.408545 | J20: =(D20*$H20+$R$12)*Units/Diluted_Shares -> 129.07754 | K20: =(E20*$H20+$R$12)*Units/Diluted_Shares -> 165.81648 | L20: =(F20*$H20+$R$12)*Units/Diluted_Shares -> 319.61659 | M20: =(G20*$H20+$R$12)*Units/Diluted_Shares -> 424.31706
B21: Forward EV / Revenue: | C21: ='M&A-Comps'!$L$20 -> 0.43266177 | D21: ='M&A-Comps'!$L$19 -> 2.1430785 | E21: ='M&A-Comps'!$L$18 -> 2.7392064 | F21: ='M&A-Comps'!$L$17 -> 4.9811727 | G21: ='M&A-Comps'!$L$16 -> 7.4560742 | H21: ='AAPL-3-Statements'!I66 -> 53631.25 | I21: =(C21*$H21+$R$12)*Units/Diluted_Shares -> 63.658403 | J21: =(D21*$H21+$R$12)*Units/Diluted_Shares -> 163.30993 | K21: =(E21*$H21+$R$12)*Units/Diluted_Shares -> 198.04127 | L21: =(F21*$H21+$R$12)*Units/Diluted_Shares -> 328.6617 | M21: =(G21*$H21+$R$12)*Units/Diluted_Shares -> 472.8533
B22: Trailing EV / EBITDA: | C22: ='M&A-Comps'!$M$20 -> 8.654416 | D22: ='M&A-Comps'!$M$19 -> 11.48861 | E22: ='M&A-Comps'!$M$18 -> 14.372059 | F22: ='M&A-Comps'!$M$17 -> 17.251684 | G22: ='M&A-Comps'!$M$16 -> 39.654905 | H22: ='AAPL-3-Statements'!H91 -> 13184 | I22: =(C22*$H22+$R$12)*Units/Diluted_Shares -> 162.40159 | J22: =(D22*$H22+$R$12)*Units/Diluted_Shares -> 202.99363 | K22: =(E22*$H22+$R$12)*Units/Diluted_Shares -> 244.29111 | L22: =(F22*$H22+$R$12)*Units/Diluted_Shares -> 285.53383 | M22: =(G22*$H22+$R$12)*Units/Diluted_Shares -> 606.3984
B23: Forward EV / EBITDA: | C23: ='M&A-Comps'!$N$20 -> 9.6487136 | D23: ='M&A-Comps'!$N$19 -> 13.363937 | E23: ='M&A-Comps'!$N$18 -> 19.064474 | F23: ='M&A-Comps'!$N$17 -> 23.868387 | G23: ='M&A-Comps'!$N$16 -> 32.797394 | H23: ='AAPL-3-Statements'!I91 -> 16480 | I23: =(C23*$H23+$R$12)*Units/Diluted_Shares -> 211.18999 | J23: =(D23*$H23+$R$12)*Units/Diluted_Shares -> 277.70296 | K23: =(E23*$H23+$R$12)*Units/Diluted_Shares -> 379.75862 | L23: =(F23*$H23+$R$12)*Units/Diluted_Shares -> 465.76218 | M23: =(G23*$H23+$R$12)*Units/Diluted_Shares -> 625.61654
B25: Discounted Cash Flow Analysis:
B26: 11-15% Discount Rate, 5-9x Terminal Multiple: | I26: =DCF!I43 -> 163.88468 | J26: =DCF!H44 -> 182.19365 | K26: =DCF!G45 -> 201.97959 | L26: =DCF!F46 -> 223.35893 | M26: =DCF!E47 -> 246.45785

Sheet Valuation Graph
G25: Min. | H25: 25th | I25: Median | J25: 75th | K25: Max | L25: Min Point | M25: 25 Point | N25: Med Point | O25: 75 Point | P25: Max Point
B26: =ValSum!B26 -> 11-15% Discount Rate, 5-9x Terminal Multiple: | G26: =ValSum!I26 -> 163.88468 | H26: =ValSum!J26 -> 182.19365 | I26: =ValSum!K26 -> 201.97959 | J26: =ValSum!L26 -> 223.35893 | K26: =ValSum!M26 -> 246.45785 | L26: =G26 -> 163.88468 | M26: =H26-G26 -> 18.30897 | N26: =I26-H26 -> 19.785945 | O26: =J26-I26 -> 21.379336 | P26: =K26-J26 -> 23.098925
B28: =ValSum!B23 -> Forward EV / EBITDA: | G28: =ValSum!I23 -> 211.18999 | H28: =ValSum!J23 -> 277.70296 | I28: =ValSum!K23 -> 379.75862 | J28: =ValSum!L23 -> 465.76218 | K28: =ValSum!M23 -> 625.61654 | L28: =G28 -> 211.18999 | M28: =H28-G28 -> 66.512965 | N28: =I28-H28 -> 102.05566 | O28: =J28-I28 -> 86.003558 | P28: =K28-J28 -> 159.85437
B29: =ValSum!B22 -> Trailing EV / EBITDA: | G29: =ValSum!I22 -> 162.40159 | H29: =ValSum!J22 -> 202.99363 | I29: =ValSum!K22 -> 244.29111 | J29: =ValSum!L22 -> 285.53383 | K29: =ValSum!M22 -> 606.3984 | L29: =G29 -> 162.40159 | M29: =H29-G29 -> 40.592048 | N29: =I29-H29 -> 41.297473 | O29: =J29-I29 -> 41.242722 | P29: =K29-J29 -> 320.86457
B30: =ValSum!B21 -> Forward EV / Revenue: | G30: =ValSum!I21 -> 63.658403 | H30: =ValSum!J21 -> 163.30993 | I30: =ValSum!K21 -> 198.04127 | J30: =ValSum!L21 -> 328.6617 | K30: =ValSum!M21 -> 472.8533 | L30: =G30 -> 63.658403 | M30: =H30-G30 -> 99.651529 | N30: =I30-H30 -> 34.731338 | O30: =J30-I30 -> 130.62043 | P30: =K30-J30 -> 144.1916
B31: =ValSum!B20 -> Trailing EV / Revenue: | G31: =ValSum!I20 -> 57.408545 | H31: =ValSum!J20 -> 129.07754 | I31: =ValSum!K20 -> 165.81648 | J31: =ValSum!L20 -> 319.61659 | K31: =ValSum!M20 -> 424.31706 | L31: =G31 -> 57.408545 | M31: =H31-G31 -> 71.668999 | N31: =I31-H31 -> 36.738934 | O31: =J31-I31 -> 153.80011 | P31: =K31-J31 -> 104.70047
B33: =ValSum!B17 -> 2010E P / E: | G33: =ValSum!I17 -> 126.6776 | H33: =ValSum!J17 -> 140.9371 | I33: =ValSum!K17 -> 188.67575 | J33: =ValSum!L17 -> 192.54708 | K33: =ValSum!M17 -> 516.49702 | L33: =G33 -> 126.6776 | M33: =H33-G33 -> 14.259508 | N33: =I33-H33 -> 47.73865 | O33: =J33-I33 -> 3.8713313 | P33: =K33-J33 -> 323.94993
B34: =ValSum!B16 -> 2009 P / E: | G34: =ValSum!I16 -> 136.10324 | H34: =ValSum!J16 -> 145.76837 | I34: =ValSum!K16 -> 179.19416 | J34: =ValSum!L16 -> 264.10951 | K34: =ValSum!M16 -> 428.24329 | L34: =G34 -> 136.10324 | M34: =H34-G34 -> 9.6651265 | N34: =I34-H34 -> 33.425794 | O34: =J34-I34 -> 84.915345 | P34: =K34-J34 -> 164.13378
B35: =ValSum!B15 -> 2010E EV / EBITDA: | G35: =ValSum!I15 -> 103.83523 | H35: =ValSum!J15 -> 129.06319 | I35: =ValSum!K15 -> 137.53785 | J35: =ValSum!L15 -> 160.94344 | K35: =ValSum!M15 -> 187.95077 | L35: =G35 -> 103.83523 | M35: =H35-G35 -> 25.22796 | N35: =I35-H35 -> 8.474658 | O35: =J35-I35 -> 23.405593 | P35: =K35-J35 -> 27.007332
B36: =ValSum!B14 -> 2009 EV / EBITDA: | G36: =ValSum!I14 -> 101.49162 | H36: =ValSum!J14 -> 143.02356 | I36: =ValSum!K14 -> 146.8985 | J36: =ValSum!L14 -> 190.07546 | K36: =ValSum!M14 -> 203.41036 | L36: =G36 -> 101.49162 | M36: =H36-G36 -> 41.531939 | N36: =I36-H36 -> 3.8749383 | O36: =J36-I36 -> 43.176965 | P36: =K36-J36 -> 13.334901
B37: =ValSum!B13 -> 2010E EV / Revenue: | G37: =ValSum!I13 -> 54.315366 | H37: =ValSum!J13 -> 66.623807 | I37: =ValSum!K13 -> 96.830245 | J37: =ValSum!L13 -> 173.79745 | K37: =ValSum!M13 -> 189.4316 | L37: =G37 -> 54.315366 | M37: =H37-G37 -> 12.308441 | N37: =I37-H37 -> 30.206438 | O37: =J37-I37 -> 76.967206 | P37: =K37-J37 -> 15.634146
B38: =ValSum!B12 -> 2009 EV / Revenue: | G38: =ValSum!I12 -> 52.117223 | H38: =ValSum!J12 -> 59.643084 | I38: =ValSum!K12 -> 89.079351 | J38: =ValSum!L12 -> 170.3659 | K38: =ValSum!M12 -> 181.29156 | L38: =G38 -> 52.117223 | M38: =H38-G38 -> 7.5258613 | N38: =I38-H38 -> 29.436267 | O38: =J38-I38 -> 81.286546 | P38: =K38-J38 -> 10.925659

Sheet Public Comps
B2: ="Comparable Companies - US-Based Hardware & Networking Companies with Over $20 Billion Revenue" -> Comparable Companies - US-Based Hardware & Networking Companies with Over $20 Billion Revenue
B3: ='AAPL-3-Statements'!B3 -> ($ in Millions, Except Per Share Amounts in Dollars and Share Counts in Thousands)
B5: Operating Statistics | E5: Capitalization | R5: Projected
C6: Share | D6: Diluted | E6: Equity | H6: Preferred | I6: Minority | J6: Other | K6: Enterprise | L6: Revenue | N6: EBITDA | P6: EPS | R6: Revenue | S6: EBITDA Margin
B7: Company Name | C7: Price | D7: Shares | E7: Value | F7: Cash | G7: Debt | H7: Stock | I7: Interest | J7: Liabilities | K7: Value | L7: =Hist_Year -> 2009 | M7: =Hist_Year+1&"E" -> 2010E | N7: =Hist_Year -> 2009 | O7: =Hist_Year+1&"E" -> 2010E | P7: =Hist_Year -> 2009 | Q7: =Hist_Year+1&"E" -> 2010E | R7: Growth | S7: =Hist_Year -> 2009 | T7: =Hist_Year+1&"E" -> 2010E
B8: Hewlett-Packard Company | C8: 47.07 | D8: 2438478 | E8: =C8/Units*D8 -> 114779.16 | F8: 13334 | G8: 15830 | H8: 0 | I8: 0 | J8: 7155 | K8: =E8-F8+G8+H8+I8+J8 -> 124430.16 | L8: 114552 | M8: 124179 | N8: 16433 | O8: 18186 | P8: 3.14 | Q8: 3.87 | R8: =M8/L8-1 -> 0.084040436 | S8: =N8/L8 -> 0.1434545 | T8: =O8/M8 -> 0.14644988
B9: Dell Inc. | C9: 12.9 | D9: 1956656.4 | E9: =C9/Units*D9 -> 25240.867 | F9: 13954 | G9: 3793 | H9: 0 | I9: 0 | J9: 0 | K9: =E9-F9+G9+H9+I9+J9 -> 15079.867 | L9: 51430 | M9: 55380 | N9: 3426 | O9: 4129 | P9: 0.78611536 | Q9: 1.18 | R9: =M9/L9-1 -> 0.076803422 | S9: =N9/L9 -> 0.066614816 | T9: =O9/M9 -> 0.074557602
B10: Cisco Systems, Inc. | C10: 22.47 | D10: 5862885.6 | E10: =C10/Units*D10 -> 131739.04 | F10: 35365 | G10: 10273 | H10: 0 | I10: 24 | J10: 0 | K10: =E10-F10+G10+H10+I10+J10 -> 106671.04 | L10: 34807 | M10: 41163 | N10: 10076 | O10: 12774 | P10: 0.97428036 | Q10: 1.38 | R10: =M10/L10-1 -> 0.18260695 | S10: =N10/L10 -> 0.289482 | T10: =O10/M10 -> 0.31032724
B11: Intel Corporation | C11: 19.4 | D11: 5527029.8 | E11: =C11/Units*D11 -> 107224.38 | F11: 17307 | G11: 2224 | H11: 0 | I11: 0 | J11: 645 | K11: =E11-F11+G11+H11+I11+J11 -> 92786.379 | L11: 32784 | M11: 39941 | N11: 12708 | O11: 18332.354 | P11: 0.41130604 | Q11: 1.1675 | R11: =M11/L11-1 -> 0.21830771 | S11: =N11/L11 -> 0.38762811 | T11: =O11/M11 -> 0.45898587
B12: Motorola, Inc. | C12: 6.15 | D12: 2315349.1 | E12: =C12/Units*D12 -> 14239.397 | F12: 7606 | G12: 3925 | H12: 0 | I12: 107 | J12: 0 | K12: =E12-F12+G12+H12+I12+J12 -> 10665.397 | L12: 23457 | M12: 22056 | N12: 926 | O12: 1927 | P12: -1.6985333 | Q12: 0.13797468 | R12: =M12/L12-1 -> -0.059726308 | S12: =N12/L12 -> 0.039476489 | T12: =O12/M12 -> 0.087368517
B14: Maximum | C14: =MAX(C8:C12) -> 47.07 | E14: =MAX(E8:E12) -> 131739.04 | F14: =MAX(F8:F12) -> 35365 | G14: =MAX(G8:G12) -> 15830 | H14: =MAX(H8:H12) -> 0 | I14: =MAX(I8:I12) -> 107 | J14: =MAX(J8:J12) -> 7155 | K14: =MAX(K8:K12) -> 124430.16 | L14: =MAX(L8:L12) -> 114552 | ... T14: =MAX(T8:T12) -> 0.45898587
B15: 75th Percentile | C15: =QUARTILE(C8:C12,3) -> 22.47 | E15: =QUARTILE(E8:E12,3) -> 114779.16 | F15: =QUARTILE(F8:F12,3) -> 17307 | G15: =QUARTILE(G8:G12,3) -> 10273 | H15: =QUARTILE(H8:H12,3) -> 0 | I15: =QUARTILE(I8:I12,3) -> 24 | J15: =QUARTILE(J8:J12,3) -> 645 | K15: =QUARTILE(K8:K12,3) -> 106671.04 | L15: =QUARTILE(L8:L12,3) -> 51430 | ... T15: =QUARTILE(T8:T12,3) -> 0.31032724
B16: Median | C16: =MEDIAN(C8:C12) -> 19.4 | E16: =MEDIAN(E8:E12) -> 107224.38 | F16: =MEDIAN(F8:F12) -> 13954 | G16: =MEDIAN(G8:G12) -> 3925 | H16: =MEDIAN(H8:H12) -> 0 | I16: =MEDIAN(I8:I12) -> 0 | J16: =MEDIAN(J8:J12) -> 0 | K16: =MEDIAN(K8:K12) -> 92786.379 | L16: =MEDIAN(L8:L12) -> 34807 | ... T16: =MEDIAN(T8:T12) -> 0.14644988
B17: 25th Percentile | C17: =QUARTILE(C8:C12,1) -> 12.9 | E17: =QUARTILE(E8:E12,1) -> 25240.867 | F17: =QUARTILE(F8:F12,1) -> 13334 | G17: =QUARTILE(G8:G12,1) -> 3793 | H17: =QUARTILE(H8:H12,1) -> 0 | I17: =QUARTILE(I8:I12,1) -> 0 | J17: =QUARTILE(J8:J12,1) -> 0 | K17: =QUARTILE(K8:K12,1) -> 15079.867 | L17: =QUARTILE(L8:L12,1) -> 32784 | ... T17: =QUARTILE(T8:T12,1) -> 0.087368517
B18: Minimum | C18: =MIN(C8:C12) -> 6.15 | E18: =MIN(E8:E12) -> 14239.397 | F18: =MIN(F8:F12) -> 7606 | G18: =MIN(G8:G12) -> 2224 | H18: =MIN(H8:H12) -> 0 | I18: =MIN(I8:I12) -> 0 | J18: =MIN(J8:J12) -> 0 | K18: =MIN(K8:K12) -> 10665.397 | L18: =MIN(L8:L12) -> 23457 | ... T18: =MIN(T8:T12) -> 0.074557602
B20: =Company_Name -> Apple Inc. | C20: =Share_Price -> 192.06 | D20: =Diluted_Shares -> 920525.62 | E20: =C20/Units*D20 -> 176796.15 | F20: ='AAPL-3-Statements'!E15 -> 35395 | G20: ='AAPL-3-Statements'!E16 -> 0 | H20: ='AAPL-3-Statements'!E18 -> 0 | I20: ='AAPL-3-Statements'!E17 -> 0 | J20: ='AAPL-3-Statements'!E19 -> 0 | K20: =E20-F20+G20+H20+I20+J20 -> 141401.15 | L20: ='AAPL-3-Statements'!H66 -> 42905 | M20: ='AAPL-3-Statements'!I66 -> 53631.25 | N20: ='AAPL-3-Statements'!H91 -> 13184 | O20: ='AAPL-3-Statements'!I91 -> 16480 | P20: ='AAPL-3-Statements'!H87 -> 9.0793325 | Q20: ='AAPL-3-Statements'!I87 -> 11.587563 | R20: =M20/L20-1 -> 0.25 | S20: =N20/L20 -> 0.30728353 | T20: =O20/M20 -> 0.30728353
B22: Valuation Statistics | E22: Capitalization | L22: Enterprise Value / | N22: Enterprise Value /
C23: Share | E23: Equity | K23: Enterprise | L23: Revenue | N23: EBITDA | P23: P / E Multiple
B24: Company Name | C24: Price | E24: Value | K24: Value | L24: =L7 -> 2009 | M24: =M7 -> 2010E | N24: =N7 -> 2009 | O24: =O7 -> 2010E | P24: =P7 -> 2009 | Q24: =Q7 -> 2010E
B25: =B8 -> Hewlett-Packard Company | C25: =C8 -> 47.07 | E25: =E8 -> 114779.16 | K25: =K8 -> 124430.16 | L25: =IF($K25/L8>0,$K25/L8,"NM") -> 1.086233 | M25: =IF($K25/M8>0,$K25/M8,"NM") -> 1.0020225 | N25: =IF($K25/N8>0,$K25/N8,"NM") -> 7.5719685 | O25: =IF($K25/O8>0,$K25/O8,"NM") -> 6.842085 | P25: =IF($C25/P8>0,$C25/P8,"NM") -> 14.990446 | Q25: =IF($C25/Q8>0,$C25/Q8,"NM") -> 12.162791
B26: =B9 -> Dell Inc. | C26: =C9 -> 12.9 | E26: =E9 -> 25240.867 | K26: =K9 -> 15079.867 | L26: =IF($K26/L9>0,$K26/L9,"NM") -> 0.29321149 | M26: =IF($K26/M9>0,$K26/M9,"NM") -> 0.27229807 | N26: =IF($K26/N9>0,$K26/N9,"NM") -> 4.4015957 | O26: =IF($K26/O9>0,$K26/O9,"NM") -> 3.6521838 | P26: =IF($C26/P9>0,$C26/P9,"NM") -> 16.409805 | Q26: =IF($C26/Q9>0,$C26/Q9,"NM") -> 10.932203
B27: =B10 -> Cisco Systems, Inc. | C27: =C10 -> 22.47 | E27: =E10 -> 131739.04 | K27: =K10 -> 106671.04 | L27: =IF($K27/L10>0,$K27/L10,"NM") -> 3.0646433 | M27: =IF($K27/M10>0,$K27/M10,"NM") -> 2.5914302 | N27: =IF($K27/N10>0,$K27/N10,"NM") -> 10.586646 | O27: =IF($K27/O10>0,$K27/O10,"NM") -> 8.3506373 | P27: =IF($C27/P10>0,$C27/P10,"NM") -> 23.063177 | Q27: =IF($C27/Q10>0,$C27/Q10,"NM") -> 16.282609
B28: =B11 -> Intel Corporation | C28: =C11 -> 19.4 | E28: =E11 -> 107224.38 | K28: =K11 -> 92786.379 | L28: =IF($K28/L11>0,$K28/L11,"NM") -> 2.8302336 | M28: =IF($K28/M11>0,$K28/M11,"NM") -> 2.323086 | N28: =IF($K28/N11>0,$K28/N11,"NM") -> 7.3014148 | O28: =IF($K28/O11>0,$K28/O11,"NM") -> 5.0613455 | P28: =IF($C28/P11>0,$C28/P11,"NM") -> 47.166825 | Q28: =IF($C28/Q11>0,$C28/Q11,"NM") -> 16.616702
B29: =B12 -> Motorola, Inc. | C29: =C12 -> 6.15 | E29: =E12 -> 14239.397 | K29: =K12 -> 10665.397 | L29: =IF($K29/L12>0,$K29/L12,"NM") -> 0.45467864 | M29: =IF($K29/M12>0,$K29/M12,"NM") -> 0.48355989 | N29: =IF($K29/N12>0,$K29/N12,"NM") -> 11.517707 | O29: =IF($K29/O12>0,$K29/O12,"NM") -> 5.5347156 | P29: =IF($C29/P12>0,$C29/P12,"NM") -> NM | Q29: =IF($C29/Q12>0,$C29/Q12,"NM") -> 44.573394
B31: Maximum | C31: =MAX(C25:C29) -> 47.07 | E31: =MAX(E25:E29) -> 131739.04 | F31: =MAX(F25:F29) -> 0 | G31: =MAX(G25:G29) -> 0 | H31: =MAX(H25:H29) -> 0 | I31: =MAX(I25:I29) -> 0 | J31: =MAX(J25:J29) -> 0 | K31: =MAX(K25:K29) -> 124430.16 | L31: =MAX(L25:L29) -> 3.0646433 | ... Q31: =MAX(Q25:Q29) -> 44.573394
B32: 75th Percentile | C32: =QUARTILE(C25:C29,3) -> 22.47 | E32: =QUARTILE(E25:E29,3) -> 114779.16 | F32: =QUARTILE(F25:F29,3) -> #VALUE! | G32: =QUARTILE(G25:G29,3) -> #VALUE! | H32: =QUARTILE(H25:H29,3) -> #VALUE! | I32: =QUARTILE(I25:I29,3) -> #VALUE! | J32: =QUARTILE(J25:J29,3) -> #VALUE! | K32: =QUARTILE(K25:K29,3) -> 106671.04 | L32: =QUARTILE(L25:L29,3) -> 2.8302336 | ... Q32: =QUARTILE(Q25:Q29,3) -> 16.616702
B33: Median | C33: =MEDIAN(C25:C29) -> 19.4 | E33: =MEDIAN(E25:E29) -> 107224.38 | F33: =MEDIAN(F25:F29) -> #VALUE! | G33: =MEDIAN(G25:G29) -> #VALUE! | H33: =MEDIAN(H25:H29) -> #VALUE! | I33: =MEDIAN(I25:I29) -> #VALUE! | J33: =MEDIAN(J25:J29) -> #VALUE! | K33: =MEDIAN(K25:K29) -> 92786.379 | L33: =MEDIAN(L25:L29) -> 1.086233 | ... Q33: =MEDIAN(Q25:Q29) -> 16.282609
B34: 25th Percentile | C34: =QUARTILE(C25:C29,1) -> 12.9 | E34: =QUARTILE(E25:E29,1) -> 25240.867 | F34: =QUARTILE(F25:F29,1) -> #VALUE! | G34: =QUARTILE(G25:G29,1) -> #VALUE! | H34: =QUARTILE(H25:H29,1) -> #VALUE! | I34: =QUARTILE(I25:I29,1) -> #VALUE! | J34: =QUARTILE(J25:J29,1) -> #VALUE! | K34: =QUARTILE(K25:K29,1) -> 15079.867 | L34: =QUARTILE(L25:L29,1) -> 0.45467864 | ... Q34: =QUARTILE(Q25:Q29,1) -> 12.162791
B35: Minimum | C35: =MIN(C25:C29) -> 6.15 | E35: =MIN(E25:E29) -> 14239.397 | F35: =MIN(F25:F29) -> 0 | G35: =MIN(G25:G29) -> 0 | H35: =MIN(H25:H29) -> 0 | I35: =MIN(I25:I29) -> 0 | J35: =MIN(J25:J29) -> 0 | K35: =MIN(K25:K29) -> 10665.397 | L35: =MIN(L25:L29) -> 0.29321149 | ... Q35: =MIN(Q25:Q29) -> 10.932203
B37: =B20 -> Apple Inc. | C37: =C20 -> 192.06 | E37: =E20 -> 176796.15 | K37: =K20 -> 141401.15 | L37: =IF($K37/L20>0,$K37/L20,"NM") -> 3.29568 | M37: =IF($K37/M20>0,$K37/M20,"NM") -> 2.636544 | N37: =IF($K37/N20>0,$K37/N20,"NM") -> 10.725209 | O37: =IF($K37/O20>0,$K37/O20,"NM") -> 8.5801669 | P37: =IF($C37/P20>0,$C37/P20,"NM") -> 21.153537 | Q37: =IF($C37/Q20>0,$C37/Q20,"NM") -> 16.574667

Sheet M&A-Comps
B2: Networking & Hardware M&A Transactions Over $1 Billion with US-Based Sellers Since 1/1/2008
B3: ='AAPL-3-Statements'!B3 -> ($ in Millions, Except Per Share Amounts in Dollars and Share Counts in Thousands)
B5: =TEXT(Company_Name,"")&" - Comparable M&A Transactions" -> Apple Inc. - Comparable M&A Transactions | G5: Operating Metrics | K5: Valuation Multiples
K6: EV / | L6: EV / | M6: EV / | N6: EV /
E7: Equity | F7: Enterprise | G7: Trailing | H7: Forward | I7: Trailing | J7: Forward | K7: Trailing | L7: Forward | M7: Trailing | N7: Forward
B8: Acquirer Name | C8: Target Name | D8: Date | E8: Value | F8: Value | G8: Revenue | H8: Revenue | I8: EBITDA | J8: EBITDA | K8: Revenue | L8: Revenue | M8: EBITDA | N8: EBITDA
B9: Hewlett-Packard Company | C9: 3Com | D9: 40128 | E9: 3180.0634 | F9: 2714.2404 | G9: 1264.83 | H9: 1222.855 | I9: 152.24 | J9: 110.2178 | K9: =IF(ISERROR($F9/G9),"NA",IF($F9/G9>0,$F9/G9,"NM")) -> 2.145933 | L9: =IF(ISERROR($F9/H9),"NA",IF($F9/H9>0,$F9/H9,"NM")) -> 2.219593 | M9: =IF(ISERROR($F9/I9),"NA",IF($F9/I9>0,$F9/I9,"NM")) -> 17.828694 | N9: =IF(ISERROR($F9/J9),"NA",IF($F9/J9>0,$F9/J9,"NM")) -> 24.626153
B10: Cisco Systems, Inc. | C10: Starent Networks | D10: 40099 | E10: 2776.6787 | F10: 2385.9437 | G10: 288.201 | H10: 320 | I10: 153.727 | J10: 110.48548 | K10: =IF(ISERROR($F10/G10),"NA",IF($F10/G10>0,$F10/G10,"NM")) -> 8.278749 | L10: =IF(ISERROR($F10/H10),"NA",IF($F10/H10>0,$F10/H10,"NM")) -> 7.4560742 | M10: =IF(ISERROR($F10/I10),"NA",IF($F10/I10>0,$F10/I10,"NM")) -> 15.520655 | N10: =IF(ISERROR($F10/J10),"NA",IF($F10/J10>0,$F10/J10,"NM")) -> 21.59509
B11: Emerson Electric Co. | C11: Avocent | D11: 40092 | E11: 1114.489 | F11: 1147.439 | G11: 611.246 | H11: 541.865 | I11: 105.17 | J11: 93.232417 | K11: =IF(ISERROR($F11/G11),"NA",IF($F11/G11>0,$F11/G11,"NM")) -> 1.8772132 | L11: =IF(ISERROR($F11/H11),"NA",IF($F11/H11>0,$F11/H11,"NM")) -> 2.1175736 | M11: =IF(ISERROR($F11/I11),"NA",IF($F11/I11>0,$F11/I11,"NM")) -> 10.910326 | N11: =IF(ISERROR($F11/J11),"NA",IF($F11/J11>0,$F11/J11,"NM")) -> 12.307297
B12: EMC Corporation | C12: Data Domain | D12: 40002 | E12: 2362.3224 | F12: 2084.5394 | G12: 300.506 | H12: 375.235 | I12: 52.567 | J12: 63.558079 | K12: =IF(ISERROR($F12/G12),"NA",IF($F12/G12>0,$F12/G12,"NM")) -> 6.9367646 | L12: =IF(ISERROR($F12/H12),"NA",IF($F12/H12>0,$F12/H12,"NM")) -> 5.5552904 | M12: =IF(ISERROR($F12/I12),"NA",IF($F12/I12>0,$F12/I12,"NM")) -> 39.654905 | N12: =IF(ISERROR($F12/J12),"NA",IF($F12/J12>0,$F12/J12,"NM")) -> 32.797394
B13: Oracle Corporation | C13: Sun Microsystems | D13: 39923 | E13: 7074.7012 | F13: 5391.7012 | G13: 13256 | H13: 12461.7 | I13: 623 | J13: 558.8 | K13: =IF(ISERROR($F13/G13),"NA",IF($F13/G13>0,$F13/G13,"NM")) -> 0.40673666 | L13: =IF(ISERROR($F13/H13),"NA",IF($F13/H13>0,$F13/H13,"NM")) -> 0.43266177 | M13: =IF(ISERROR($F13/I13),"NA",IF($F13/I13>0,$F13/I13,"NM")) -> 8.654416 | N13: =IF(ISERROR($F13/J13),"NA",IF($F13/J13>0,$F13/J13,"NM")) -> 9.6487136
B14: Brocade Communication Systems, Inc. | C14: Foundry Networks | D14: 39650 | E14: 2899.1908 | F14: 2062.7808 | G14: 621.447 | H14: 632.984 | I14: 155.994 | J14: 124.761 | K14: =IF(ISERROR($F14/G14),"NA",IF($F14/G14>0,$F14/G14,"NM")) -> 3.319319 | L14: =IF(ISERROR($F14/H14),"NA",IF($F14/H14>0,$F14/H14,"NM")) -> 3.2588198 | M14: =IF(ISERROR($F14/I14),"NA",IF($F14/I14>0,$F14/I14,"NM")) -> 13.223462 | N14: =IF(ISERROR($F14/J14),"NA",IF($F14/J14>0,$F14/J14,"NM")) -> 16.533859
C16: Maximum | E16: =MAX(E9:E14) -> 7074.7012 | F16: =MAX(F9:F14) -> 5391.7012 | G16: =MAX(G9:G14) -> 13256 | H16: =MAX(H9:H14) -> 12461.7 | I16: =MAX(I9:I14) -> 623 | J16: =MAX(J9:J14) -> 558.8 | K16: =MAX(K9:K14) -> 8.278749 | L16: =MAX(L9:L14) -> 7.4560742 | ... N16: =MAX(N9:N14) -> 32.797394
C17: 75th Percentile | E17: =QUARTILE(E9:E14,3) -> 3109.8452 | F17: =QUARTILE(F9:F14,3) -> 2632.1662 | G17: =QUARTILE(G9:G14,3) -> 1103.9842 | H17: =QUARTILE(H9:H14,3) -> 1075.3872 | I17: =QUARTILE(I9:I14,3) -> 155.42725 | J17: =QUARTILE(J9:J14,3) -> 121.19212 | K17: =QUARTILE(K9:K14,3) -> 6.0324032 | L17: =QUARTILE(L9:L14,3) -> 4.9811727 | ... N17: =QUARTILE(N9:N14,3) -> 23.868387
C18: Median | E18: =MEDIAN(E9:E14) -> 2837.9348 | F18: =MEDIAN(F9:F14) -> 2235.2416 | G18: =MEDIAN(G9:G14) -> 616.3465 | H18: =MEDIAN(H9:H14) -> 587.4245 | I18: =MEDIAN(I9:I14) -> 152.9835 | J18: =MEDIAN(J9:J14) -> 110.35164 | K18: =MEDIAN(K9:K14) -> 2.732626 | L18: =MEDIAN(L9:L14) -> 2.7392064 | ... N18: =MEDIAN(N9:N14) -> 19.064474
C19: 25th Percentile | E19: =QUARTILE(E9:E14,1) -> 2465.9115 | F19: =QUARTILE(F9:F14,1) -> 2068.2204 | G19: =QUARTILE(G9:G14,1) -> 378.191 | H19: =QUARTILE(H9:H14,1) -> 416.8925 | I19: =QUARTILE(I9:I14,1) -> 116.9375 | J19: =QUARTILE(J9:J14,1) -> 97.478763 | K19: =QUARTILE(K9:K14,1) -> 1.9443931 | L19: =QUARTILE(L9:L14,1) -> 2.1430785 | ... N19: =QUARTILE(N9:N14,1) -> 13.363937
C20: Minimum | E20: =MIN(E9:E14) -> 1114.489 | F20: =MIN(F9:F14) -> 1147.439 | G20: =MIN(G9:G14) -> 288.201 | H20: =MIN(H9:H14) -> 320 | I20: =MIN(I9:I14) -> 52.567 | J20: =MIN(J9:J14) -> 63.558079 | K20: =MIN(K9:K14) -> 0.40673666 | L20: =MIN(L9:L14) -> 0.43266177 | ... N20: =MIN(N9:N14) -> 9.6487136

Sheet DCF
B2: ="Discounted Cash Flow Analysis - "&TEXT(Company_Name,"") -> Discounted Cash Flow Analysis - Apple Inc.
B3: ='AAPL-3-Statements'!B3 -> ($ in Millions, Except Per Share Amounts in Dollars and Share Counts in Thousands)
B5: =TEXT(Company_Name,"")&" - Cash Flow Projections" -> Apple Inc. - Cash Flow Projections | L5: =TEXT(Company_Name,"")&" - DCF Assumptions & Output" -> Apple Inc. - DCF Assumptions & Output
F6: ='AAPL-3-Statements'!I24 -> FY 2010E | G6: ='AAPL-3-Statements'!J24 -> FY 2011E | H6: ='AAPL-3-Statements'!K24 -> FY 2012E | I6: ='AAPL-3-Statements'!L24 -> FY 2013E | J6: ='AAPL-3-Statements'!M24 -> FY 2014E
B8: Revenue: | F8: ='AAPL-3-Statements'!I66 -> 53631.25 | G8: ='AAPL-3-Statements'!J66 -> 62748.562 | H8: ='AAPL-3-Statements'!K66 -> 69650.904 | I8: ='AAPL-3-Statements'!L66 -> 75919.486 | J8: ='AAPL-3-Statements'!M66 -> 81233.85 | L8: Use Multiples Method? | O8: 1
B9: EBITDA: | F9: ='AAPL-3-Statements'!I91 -> 16480 | G9: ='AAPL-3-Statements'!J91 -> 19281.6 | H9: ='AAPL-3-Statements'!K91 -> 21402.576 | I9: ='AAPL-3-Statements'!L91 -> 23328.808 | J9: ='AAPL-3-Statements'!M91 -> 24961.824 | L9: Discount Rate: | O9: =WACC!G34 -> 0.1249633
B10: Operating Income: | F10: ='AAPL-3-Statements'!I78 -> 14635 | G10: ='AAPL-3-Statements'!J78 -> 17132.75 | H10: ='AAPL-3-Statements'!K78 -> 19030.423 | I10: ='AAPL-3-Statements'!L78 -> 20760.681 | J10: ='AAPL-3-Statements'!M78 -> 22217.838
L11: Terminal EBITDA Multiple: | O11: 7
B12: Less: Taxes | F12: =-F10*Tax_Rate -> -4390.5 | G12: =-G10*Tax_Rate -> -5139.825 | H12: =-H10*Tax_Rate -> -5709.1268 | I12: =-I10*Tax_Rate -> -6228.2042 | J12: =-J10*Tax_Rate -> -6665.3514 | L12: Terminal Growth Rate: | O12: 0.03
L13: Terminal Value: | O13: =IF(O8,O11*J9,J21*(1+O12)/(O9-O12)) -> 174732.77
B14: Plus: Depreciation | F14: ='AAPL-3-Statements'!I144 -> 917.5 | G14: ='AAPL-3-Statements'!J144 -> 1073.475 | H14: ='AAPL-3-Statements'!K144 -> 1191.5573 | I14: ='AAPL-3-Statements'!L144 -> 1298.7974 | J14: ='AAPL-3-Statements'!M144 -> 1389.7132
B15: Plus: Amortization | F15: ='AAPL-3-Statements'!I145 -> 40 | G15: ='AAPL-3-Statements'!J145 -> 37 | H15: ='AAPL-3-Statements'!K145 -> 28 | I15: ='AAPL-3-Statements'!L145 -> 13 | J15: ='AAPL-3-Statements'!M145 -> 10 | L15: PV of Terminal Value: | O15: =IF(O8,O13/((1+O9)^J24),O13/((1+O9)^J25)) -> 96980.093
B16: Plus: Stock-Based Compensation | F16: ='AAPL-3-Statements'!I146 -> 887.5 | G16: ='AAPL-3-Statements'!J146 -> 1038.375 | H16: ='AAPL-3-Statements'!K146 -> 1152.5963 | I16: ='AAPL-3-Statements'!L146 -> 1256.3299 | J16: ='AAPL-3-Statements'!M146 -> 1344.273 | L16: Sum of PV of Cash Flows: | O16: =SUM(F22:J22) -> 56296.251
L17: Enterprise Value: | O17: =SUM(O15:O16) -> 153276.34
B18: Less: Increase in Working Capital: | F18: =SUM('AAPL-3-Statements'!I150:I156) -> 2135.75 | G18: =SUM('AAPL-3-Statements'!J150:J156) -> 1815.3875 | H18: =SUM('AAPL-3-Statements'!K150:K156) -> 1374.3551 | I18: =SUM('AAPL-3-Statements'!L150:L156) -> 1248.1643 | J18: =SUM('AAPL-3-Statements'!M150:M156) -> 1058.166
B19: Less: Capital Expenditures | F19: ='AAPL-3-Statements'!I163 -> -1430 | G19: ='AAPL-3-Statements'!J163 -> -1673.1 | H19: ='AAPL-3-Statements'!K163 -> -1857.141 | I19: ='AAPL-3-Statements'!L163 -> -2024.2837 | J19: ='AAPL-3-Statements'!M163 -> -2165.9835 | L19: Terminal Value % EV: | O19: =O15/O17 -> 0.63271403
B21: Unlevered Free Cash Flow | F21: =F10+F12+F14+F15+F16+F18+F19 -> 12795.25 | G21: =G10+G12+G14+G15+G16+G18+G19 -> 14284.062 | H21: =H10+H12+H14+H15+H16+H18+H19 -> 15210.663 | I21: =I10+I12+I14+I15+I16+I18+I19 -> 16324.484 | J21: =J10+J12+J14+J15+J16+J18+J19 -> 17188.655 | L21: Enterprise Value: | O21: =O17 -> 153276.34
B22: Present Value of Free Cash Flow | F22: =F21/((1+$O$9)^F25) -> 12063.674 | G22: =G21/((1+$O$9)^G25) -> 11971.38 | H22: =H21/((1+$O$9)^H25) -> 11331.888 | I22: =I21/((1+$O$9)^I25) -> 10810.735 | J22: =J21/((1+$O$9)^J25) -> 10118.574 | L22: Balance Sheet Adjustment: | O22: ='AAPL-3-Statements'!E15-'AAPL-3-Statements'!E16-'AAPL-3-Statements'!E17-'AAPL-3-Statements'!E18-'AAPL-3-Statements'!E19 -> 35395
L23: Implied Equity Value: | O23: =SUM(O21:O22) -> 188671.34
B24: Normal Discount Period: | F24: 1 | G24: =F24+1 -> 2 | H24: =G24+1 -> 3 | I24: =H24+1 -> 4 | J24: =I24+1 -> 5
B25: Mid-Year Discount: | F25: 0.5 | G25: =F25+1 -> 1.5 | H25: =G25+1 -> 2.5 | I25: =H25+1 -> 3.5 | J25: =I25+1 -> 4.5 | L25: Implied Price Per Share: | O25: =O23*Units/Diluted_Shares -> 204.96045
B27: Free Cash Flow Growth Rate: | G27: =G21/F21-1 -> 0.11635666 | H27: =H21/G21-1 -> 0.064869562 | I27: =I21/H21-1 -> 0.073226323 | J27: =J21/I21-1 -> 0.052937112
B29: =TEXT(Company_Name,"")&" - Net Present Value Sensitivity - Terminal Growth Rates" -> Apple Inc. - Net Present Value Sensitivity - Terminal Growth Rates
D30: Discount Rate
C31: =O25 -> 204.96045 | D31: 0.1 | E31: =D31+1% -> 0.11 | F31: =E31+1% -> 0.12 | G31: =F31+1% -> 0.13 | H31: =G31+1% -> 0.14 | I31: =H31+1% -> 0.15 | J31: =I31+1% -> 0.16
B32: Terminal Growth Rate | C32: 0 | D32: =TABLE($C$31,$O$12,$C32,$O$9,D$31) -> 220.90082 | E32: =TABLE($C$31,$O$12,$C32,$O$9,E$31) -> 214.2727 | F32: =TABLE($C$31,$O$12,$C32,$O$9,F$31) -> 207.97206 | G32: =TABLE($C$31,$O$12,$C32,$O$9,G$31) -> 201.97959 | H32: =TABLE($C$31,$O$12,$C32,$O$9,H$31) -> 196.27733 | I32: =TABLE($C$31,$O$12,$C32,$O$9,I$31) -> 190.84849 | J32: =TABLE($C$31,$O$12,$C32,$O$9,J$31) -> 185.6774
C33: =C32+1% -> 0.01 | D33: =TABLE($C$31,$O$12,$C33,$O$9,D$31) -> 220.90082 | E33: =TABLE($C$31,$O$12,$C33,$O$9,E$31) -> 214.2727 | F33: =TABLE($C$31,$O$12,$C33,$O$9,F$31) -> 207.97206 | G33: =TABLE($C$31,$O$12,$C33,$O$9,G$31) -> 201.97959 | H33: =TABLE($C$31,$O$12,$C33,$O$9,H$31) -> 196.27733 | I33: =TABLE($C$31,$O$12,$C33,$O$9,I$31) -> 190.84849 | J33: =TABLE($C$31,$O$12,$C33,$O$9,J$31) -> 185.6774
C34: =C33+1% -> 0.02 | D34: =TABLE($C$31,$O$12,$C34,$O$9,D$31) -> 220.90082 | E34: =TABLE($C$31,$O$12,$C34,$O$9,E$31) -> 214.2727 | F34: =TABLE($C$31,$O$12,$C34,$O$9,F$31) -> 207.97206 | G34: =TABLE($C$31,$O$12,$C34,$O$9,G$31) -> 201.97959 | H34: =TABLE($C$31,$O$12,$C34,$O$9,H$31) -> 196.27733 | I34: =TABLE($C$31,$O$12,$C34,$O$9,I$31) -> 190.84849 | J34: =TABLE($C$31,$O$12,$C34,$O$9,J$31) -> 185.6774
C35: =C34+1% -> 0.03 | D35: =TABLE($C$31,$O$12,$C35,$O$9,D$31) -> 220.90082 | E35: =TABLE($C$31,$O$12,$C35,$O$9,E$31) -> 214.2727 | F35: =TABLE($C$31,$O$12,$C35,$O$9,F$31) -> 207.97206 | G35: =TABLE($C$31,$O$12,$C35,$O$9,G$31) -> 201.97959 | H35: =TABLE($C$31,$O$12,$C35,$O$9,H$31) -> 196.27733 | I35: =TABLE($C$31,$O$12,$C35,$O$9,I$31) -> 190.84849 | J35: =TABLE($C$31,$O$12,$C35,$O$9,J$31) -> 185.6774
C36: =C35+1% -> 0.04 | D36: =TABLE($C$31,$O$12,$C36,$O$9,D$31) -> 220.90082 | E36: =TABLE($C$31,$O$12,$C36,$O$9,E$31) -> 214.2727 | F36: =TABLE($C$31,$O$12,$C36,$O$9,F$31) -> 207.97206 | G36: =TABLE($C$31,$O$12,$C36,$O$9,G$31) -> 201.97959 | H36: =TABLE($C$31,$O$12,$C36,$O$9,H$31) -> 196.27733 | I36: =TABLE($C$31,$O$12,$C36,$O$9,I$31) -> 190.84849 | J36: =TABLE($C$31,$O$12,$C36,$O$9,J$31) -> 185.6774
C37: =C36+1% -> 0.05 | D37: =TABLE($C$31,$O$12,$C37,$O$9,D$31) -> 220.90082 | E37: =TABLE($C$31,$O$12,$C37,$O$9,E$31) -> 214.2727 | F37: =TABLE($C$31,$O$12,$C37,$O$9,F$31) -> 207.97206 | G37: =TABLE($C$31,$O$12,$C37,$O$9,G$31) -> 201.97959 | H37: =TABLE($C$31,$O$12,$C37,$O$9,H$31) -> 196.27733 | I37: =TABLE($C$31,$O$12,$C37,$O$9,I$31) -> 190.84849 | J37: =TABLE($C$31,$O$12,$C37,$O$9,J$31) -> 185.6774
B39: =TEXT(Company_Name,"")&" - Net Present Value Sensitivity - Terminal EBITDA Multiples" -> Apple Inc. - Net Present Value Sensitivity - Terminal EBITDA Multiples
D40: =D30 -> Discount Rate
C41: =O25 -> 204.96045 | D41: =D31 -> 0.1 | E41: =E31 -> 0.11 | F41: =F31 -> 0.12 | G41: =G31 -> 0.13 | H41: =H31 -> 0.14 | I41: =I31 -> 0.15 | J41: =J31 -> 0.16
B42: Terminal EBITDA Multiple | C42: 4 | D42: =TABLE($C$41,$O$11,$C42,$O$9,D$41) -> 170.38839 | E42: =TABLE($C$41,$O$11,$C42,$O$9,E$41) -> 165.99498 | F42: =TABLE($C$41,$O$11,$C42,$O$9,F$41) -> 161.81144 | G42: =TABLE($C$41,$O$11,$C42,$O$9,G$41) -> 157.82565 | H42: =TABLE($C$41,$O$11,$C42,$O$9,H$41) -> 154.02628 | I42: =TABLE($C$41,$O$11,$C42,$O$9,I$41) -> 150.40277 | J42: =TABLE($C$41,$O$11,$C42,$O$9,J$41) -> 146.94524
C43: =C42+1 -> 5 | D43: =TABLE($C$41,$O$11,$C43,$O$9,D$41) -> 187.22586 | E43: =TABLE($C$41,$O$11,$C43,$O$9,E$41) -> 182.08755 | F43: =TABLE($C$41,$O$11,$C43,$O$9,F$41) -> 177.19831 | G43: =TABLE($C$41,$O$11,$C43,$O$9,G$41) -> 172.54363 | H43: =TABLE($C$41,$O$11,$C43,$O$9,H$41) -> 168.10997 | I43: =TABLE($C$41,$O$11,$C43,$O$9,I$41) -> 163.88468 | J43: =TABLE($C$41,$O$11,$C43,$O$9,J$41) -> 159.85596
C44: =C43+1 -> 6 | D44: =TABLE($C$41,$O$11,$C44,$O$9,D$41) -> 204.06334 | E44: =TABLE($C$41,$O$11,$C44,$O$9,E$41) -> 198.18013 | F44: =TABLE($C$41,$O$11,$C44,$O$9,F$41) -> 192.58518 | G44: =TABLE($C$41,$O$11,$C44,$O$9,G$41) -> 187.26161 | H44: =TABLE($C$41,$O$11,$C44,$O$9,H$41) -> 182.19365 | I44: =TABLE($C$41,$O$11,$C44,$O$9,I$41) -> 177.36658 | J44: =TABLE($C$41,$O$11,$C44,$O$9,J$41) -> 172.76668
C45: =C44+1 -> 7 | D45: =TABLE($C$41,$O$11,$C45,$O$9,D$41) -> 220.90082 | E45: =TABLE($C$41,$O$11,$C45,$O$9,E$41) -> 214.2727 | F45: =TABLE($C$41,$O$11,$C45,$O$9,F$41) -> 207.97206 | G45: =TABLE($C$41,$O$11,$C45,$O$9,G$41) -> 201.97959 | H45: =TABLE($C$41,$O$11,$C45,$O$9,H$41) -> 196.27733 | I45: =TABLE($C$41,$O$11,$C45,$O$9,I$41) -> 190.84849 | J45: =TABLE($C$41,$O$11,$C45,$O$9,J$41) -> 185.6774
C46: =C45+1 -> 8 | D46: =TABLE($C$41,$O$11,$C46,$O$9,D$41) -> 237.73829 | E46: =TABLE($C$41,$O$11,$C46,$O$9,E$41) -> 230.36528 | F46: =TABLE($C$41,$O$11,$C46,$O$9,F$41) -> 223.35893 | G46: =TABLE($C$41,$O$11,$C46,$O$9,G$41) -> 216.69757 | H46: =TABLE($C$41,$O$11,$C46,$O$9,H$41) -> 210.36101 | I46: =TABLE($C$41,$O$11,$C46,$O$9,I$41) -> 204.33039 | J46: =TABLE($C$41,$O$11,$C46,$O$9,J$41) -> 198.58812
C47: =C46+1 -> 9 | D47: =TABLE($C$41,$O$11,$C47,$O$9,D$41) -> 254.57577 | E47: =TABLE($C$41,$O$11,$C47,$O$9,E$41) -> 246.45785 | F47: =TABLE($C$41,$O$11,$C47,$O$9,F$41) -> 238.7458 | G47: =TABLE($C$41,$O$11,$C47,$O$9,G$41) -> 231.41555 | H47: =TABLE($C$41,$O$11,$C47,$O$9,H$41) -> 224.44469 | I47: =TABLE($C$41,$O$11,$C47,$O$9,I$41) -> 217.81229 | J47: =TABLE($C$41,$O$11,$C47,$O$9,J$41) -> 211.49884

Sheet WACC
B2: ="WACC Analysis - "&TEXT(Company_Name,"") -> WACC Analysis - Apple Inc.
B3: ='AAPL-3-Statements'!B3 -> ($ in Millions, Except Per Share Amounts in Dollars and Share Counts in Thousands)
B5: Discount Rate Calculation - Assumptions
B6: Risk-Free Rate: | E6: 0.0438
B7: Equity Risk Premium: | E7: 0.07
B8: Interest Rate on Debt: | E8: ='AAPL-3-Statements'!I47 -> 0.09
B10: Comparable Companies - Unlevered Beta Calculation
C11: Levered | E11: Equity | G11: Unlevered
B12: Name | C12: Beta | D12: Debt | E12: Value | F12: Tax Rate | G12: Beta
B13: ='Public Comps'!B8 -> Hewlett-Packard Company | C13: 1.04 | D13: ='Public Comps'!G8 -> 15830 | E13: ='Public Comps'!E8 -> 114779.16 | F13: 0.2 | G13: =C13/(1+(1-F13)*(D13/E13)) -> 0.93665542
B14: ='Public Comps'!B9 -> Dell Inc. | C14: 1.31 | D14: ='Public Comps'!G9 -> 3793 | E14: ='Public Comps'!E9 -> 25240.867 | F14: 0.27 | G14: =C14/(1+(1-F14)*(D14/E14)) -> 1.1805006
B15: ='Public Comps'!B10 -> Cisco Systems, Inc. | C15: 1.23 | D15: ='Public Comps'!G10 -> 10273 | E15: ='Public Comps'!E10 -> 131739.04 | F15: 0.22 | G15: =C15/(1+(1-F15)*(D15/E15)) -> 1.1594757
B16: ='Public Comps'!B11 -> Intel Corporation | C16: 1.17 | D16: ='Public Comps'!G11 -> 2224 | E16: ='Public Comps'!E11 -> 107224.38 | F16: 0.33 | G16: =C16/(1+(1-F16)*(D16/E16)) -> 1.1539636
B17: ='Public Comps'!B12 -> Motorola, Inc. | C17: 1.87 | D17: ='Public Comps'!G12 -> 3925 | E17: ='Public Comps'!E12 -> 14239.397 | F17: 0.34 | G17: =C17/(1+(1-F17)*(D17/E17)) -> 1.5821649
B19: Median | C19: =MEDIAN(C13:C17) -> 1.23 | G19: =MEDIAN(G13:G17) -> 1.1594757
B21: =Company_Name -> Apple Inc. | C21: 1.57
B23: =TEXT(Company_Name,"")&" - Levered Beta & WACC Calculation" -> Apple Inc. - Levered Beta & WACC Calculation
C24: Unlevered | E24: Equity | G24: Levered
C25: Beta | D25: Debt | E25: Value | F25: Tax Rate | G25: Beta
B27: =Company_Name -> Apple Inc. | C27: =G19 -> 1.1594757 | D27: 0 | E27: =Equity_Value -> 176796.15 | F27: =Tax_Rate -> 0.3 | G27: =C27*(1+(1-F27)*(D27/E27)) -> 1.1594757
B29: Cost of Equity Based on Comparables: | G29: =E6+E7*G27 -> 0.1249633
B30: Cost of Equity Based on Historical Beta: | G30: =E6+E7*C21 -> 0.1537
B32: WACC = Cost of Equity * % Equity + Cost of Debt * % Debt * (1 - Tax Rate) + Cost of Preferred Stock * % Preferred Stock
B34: WACC | G34: =G29*(E27/(E27+D27))+E8*(D27/(D27+E27))*(1-F27) -> 0.1249633

Sheet Merger-Model
B2: ="Merger Model - "&TEXT(Company_Name,"")&" and "&Seller_Name -> Merger Model - Apple Inc. and Research in Motion Limited
B3: ='AAPL-3-Statements'!B3 -> ($ in Millions, Except Per Share Amounts in Dollars and Share Counts in Thousands)
B5: Transaction Assumptions
B7: Per Share Purchase Price: | F7: 75 | H7: Equity Purchase Price: | L7: ='Merger-Shares-BS'!J15 -> 43048.922
B8: % Cash: | F8: =1/3 -> 0.33333333 | H8: Cash Used: | L8: =F8*L7 -> 14349.641
B9: % Debt: | F9: =1/3 -> 0.33333333 | H9: Debt Issued: | L9: =F9*L7 -> 14349.641
B10: % Stock: | F10: =1/3 -> 0.33333333 | H10: New Shares Issued: | L10: =F10*L7/F34*Units -> 74714.364
B11: Foregone Cash Interest Rate: | F11: ='AAPL-3-Statements'!I46 -> 0.01 | H11: Debt Interest Rate: | L11: ='AAPL-3-Statements'!I47 -> 0.09
B13: Revenue Synergy %: | F13: 0.1 | H13: Revenue Synergy COGS %: | L13: 0.5
B14: Cost Synergies % OpEx: | F14: 0.1
B16: Goodwill Creation & Balance Sheet Adjustments
B18: Goodwill Calculation: | H18: Fixed Asset Write-Up:
B19: Equity Purchase Price: | F19: =L7 -> 43048.922 | H19: PP&E Write-Up %: | L19: 0.1
B20: Less: Seller Book Value: | F20: =-'Merger-Shares-BS'!J62 -> -6986.62 | H20: PP&E Write-Up Amount: | L20: =L19*'Merger-Shares-BS'!J36 -> 173.7403
B21: Plus: Write-Off of Existing Goodwill: | F21: ='Merger-Shares-BS'!J37 -> 146.557 | H21: Depreciation Period (Years): | L21: 8
B22: Total Allocable Purchase Premium: | F22: =F19+F20+F21 -> 36208.859
H23: Intangible Asset Write-Up:
B24: Less: Write-Up of PP&E: | F24: =-L20 -> -173.7403 | H24: Purchase Price to Allocate: | L24: =F22 -> 36208.859
B25: Less: Write-Up of Intangibles: | F25: =-L26 -> -7241.7718 | H25: % Allocated to Intangibles: | L25: 0.2
B26: Less: Write-Down of DTL: | F26: =-'Merger-Shares-BS'!J52 -> -43.265 | H26: Intangibles Write-Up Amount: | L26: =L25*L24 -> 7241.7718
B27: Plus: New Deferred Tax Liability: | F27: =L29 -> 2224.6536 | H27: Amortization Period (Years): | L27: 5
B28: Total Goodwill Created: | F28: =F22+F24+F25+F26+F27 -> 30974.736
H29: New Deferred Tax Liability: | L29: =(L26+L20)*Tax_Rate -> 2224.6536
B31: Buyer - Financial Profile | H31: Seller - Financial Profile
B33: Buyer Name: | F33: =Company_Name -> Apple Inc. | H33: Seller Name: | L33: =Seller_Name -> Research in Motion Limited
B34: Share Price: | F34: =Share_Price -> 192.06 | H34: Share Price: | L34: =Seller_Share_Price -> 62.91
B35: Diluted Shares Outstanding: | F35: =Diluted_Shares -> 920525.62 | H35: Diluted Shares Outstanding: | L35: ='Merger-Shares-BS'!E14 -> 572950.86
B36: Diluted Equity Value: | F36: =Equity_Value -> 176796.15 | H36: Diluted Equity Value: | L36: ='Merger-Shares-BS'!E15 -> 36044.339
B37: Enterprise Value: | F37: =Enterprise_Value -> 141401.15 | H37: Enterprise Value: | L37: ='Merger-Shares-BS'!E21 -> 33546.592
B38: Tax Rate: | F38: =Tax_Rate -> 0.3 | H38: Tax Rate: | L38: ='Merger-Shares-BS'!J9 -> 0.28
B40: Buyer - Income Statement | H40: Seller - Income Statement
E42: ='AAPL-3-Statements'!I96 -> FY 2010E | F42: ='AAPL-3-Statements'!J96 -> FY 2011E | K42: =E42 -> FY 2010E | L42: =F42 -> FY 2011E
B43: Revenue: | E43: ='AAPL-3-Statements'!I66 -> 53631.25 | F43: ='AAPL-3-Statements'!J66 -> 62748.562 | H43: Revenue: | K43: 17231 | L43: 20868
B44: Cost of Goods Sold: | E44: ='AAPL-3-Statements'!I67 -> 31655.417 | F44: ='AAPL-3-Statements'!J67 -> 37036.838 | H44: Cost of Goods Sold: | K44: 9755 | L44: 11868.5
B45: Gross Profit: | E45: =E43-E44 -> 21975.833 | F45: =F43-F44 -> 25711.725 | H45: Gross Profit: | K45: =K43-K44 -> 7476 | L45: =L43-L44 -> 8999.5
B47: Operating Expenses: | E47: ='AAPL-3-Statements'!I72 -> 5495.8333 | F47: ='AAPL-3-Statements'!J72 -> 6430.125 | H47: Operating Expenses: | K47: 2697.532 | L47: 3258.96
B49: Depreciation of PP&E: | E49: ='AAPL-3-Statements'!I74 -> 917.5 | F49: ='AAPL-3-Statements'!J74 -> 1073.475 | H49: Depreciation of PP&E: | K49: 430.775 | L49: 563.436
B50: Amortization of Intangibles: | E50: ='AAPL-3-Statements'!I75 -> 40 | F50: ='AAPL-3-Statements'!J75 -> 37 | H50: Amortization of Intangibles: | K50: 359 | L50: 433
B51: Stock-Based Compensation: | E51: ='AAPL-3-Statements'!I76 -> 887.5 | F51: ='AAPL-3-Statements'!J76 -> 1038.375 | H51: Stock-Based Compensation: | K51: 51.693 | L51: 62.604
B53: Operating Income: | E53: =E45-E47-E49-E50-E51 -> 14635 | F53: =F45-F47-F49-F50-F51 -> 17132.75 | H53: Operating Income: | K53: =K45-K47-K49-K50-K51 -> 3937 | L53: =L45-L47-L49-L50-L51 -> 4681.5
...

Sheet Merger-Shares-BS
B2: ="Merger Model - Seller Diluted Share Count & Combined Balance Sheets" -> Merger Model - Seller Diluted Share Count & Combined Balance Sheets
B3: ='AAPL-3-Statements'!B3 -> ($ in Millions, Except Per Share Amounts in Dollars and Share Counts in Thousands)
B5: Diluted Share & Enterprise Value Calculations - Seller
B7: Company Name: | E7: Research in Motion Limited | L7: Options Calculations - Current Price:
B8: Share Price: | E8: 62.91
B9: Offer Price Per Share: | E9: =Purchase_Price -> 75 | G9: Tax Rate: | J9: 0.28 | N9: Exercise
L10: Name | M10: Number | N10: Price | O10: Dilution
B11: Current Share Price: | G11: Purchase Price: | L11: Tranche A | M11: 10470 | N11: 38.57 | O11: =IF(N11>Seller_Share_Price,0,M11-M11*N11/Seller_Share_Price) -> 4050.8631
B12: Basic Shares Outstanding: | E12: 568900 | G12: Basic Shares Outstanding: | J12: =E12 -> 568900 | L12: Tranche B
B13: Basic Equity Value: | E13: =E12/Units*Seller_Share_Price -> 35789.499 | G13: Basic Equity Value: | J13: =J12/Units*E9 -> 42667.5 | L13: Total | O13: =SUM(O11:O12) -> 4050.8631
B14: Diluted Shares Outstanding: | E14: =E12+O13 -> 572950.86 | G14: Diluted Shares Outstanding: | J14: =J12+O21 -> 573985.63
B15: Diluted Equity Value: | E15: =E14/Units*Seller_Share_Price -> 36044.339 | G15: Diluted Equity Value: | J15: =J14/Units*E9 -> 43048.922 | L15: Options Calculations - Purchase Price:
B16: Less: Cash & Investments | E16: =J27+J35 -> 2497.747 | G16: Less: Cash & Investments | J16: =E16 -> 2497.747
B17: Plus: Debt | E17: 0 | G17: Plus: Debt | J17: =E17 -> 0 | N17: Exercise
B18: Plus: Minority Interest | E18: 0 | G18: Plus: Minority Interest | J18: =E18 -> 0 | L18: Name | M18: Number | N18: Price | O18: Dilution
B19: Plus: Preferred Stock | E19: 0 | G19: Plus: Preferred Stock | J19: =E19 -> 0 | L19: Tranche A | M19: 10470 | N19: 38.57 | O19: =IF(N19>E9,0,M19-M19*N19/E9) -> 5085.628
B20: Plus: Other Liabilities | E20: 0 | G20: Plus: Other Liabilities | J20: =E20 -> 0 | L20: Tranche B
B21: Enterprise Value: | E21: =E15-E16+E17+E18+E19+E20 -> 33546.592 | G21: Enterprise Value: | J21: =J15-J16+J17+J18+J19+J20 -> 40551.175 | L21: Total | O21: =SUM(O19:O20) -> 5085.628
B23: Balance Sheets - Buyer, Seller & Combined
B25: Assets: | H25: Buyer | J25: Seller | L25: Adjustments | N25: Combined
B26: Current Assets:
B27: Cash & Short-Term Securities: | H27: ='AAPL-3-Statements'!H99+'AAPL-3-Statements'!H100 -> 32841 | J27: =1083.251+580.921 -> 1664.172 | L27: =-'Merger-Model'!L8 -> -14349.641 | N27: =H27+J27+L27 -> 20155.531
B28: Accounts Receivable: | H28: ='AAPL-3-Statements'!H101 -> 3361 | J28: =2365.106+248.162 -> 2613.268 | L28: 0 | N28: =H28+J28+L28 -> 5974.268
B29: Inventory: | H29: ='AAPL-3-Statements'!H102 -> 455 | J29: 572.761 | L29: 0 | N29: =H29+J29+L29 -> 1027.761
B30: Deferred Tax Assets: | H30: ='AAPL-3-Statements'!H103 -> 4 | J30: 175.568 | L30: 0 | N30: =H30+J30+L30 -> 179.568
B31: Other Current Assets: | H31: ='AAPL-3-Statements'!H104 -> 3140 | J31: 189.676 | L31: 0 | N31: =H31+J31+L31 -> 3329.676
B32: Total Current Assets: | H32: =SUM(H27:H31) -> 39801 | J32: =SUM(J27:J31) -> 5215.445 | L32: =SUM(L27:L31) -> -14349.641 | N32: =SUM(N27:N31) -> 30666.804
B34: Long-Term Assets:
B35: Long-Term Securities: | H35: ='AAPL-3-Statements'!H108 -> 2554 | J35: 833.575 | L35: 0 | N35: =H35+J35+L35 -> 3387.575
B36: Plants, Property & Equipment: | H36: ='AAPL-3-Statements'!H109 -> 2839 | J36: 1737.403 | L36: ='Merger-Model'!L20 -> 173.7403 | N36: =H36+J36+L36 -> 4750.1433
B37: Goodwill: | H37: ='AAPL-3-Statements'!H110 -> 207 | J37: 146.557 | L37: =-'Merger-Model'!F21+'Merger-Model'!F28 -> 30828.179 | N37: =H37+J37+L37 -> 31181.736
B38: Other Intangible Assets: | H38: ='AAPL-3-Statements'!H111 -> 354 | J38: 1291.454 | L38: ='Merger-Model'!L26 -> 7241.7718 | N38: =H38+J38+L38 -> 8887.2258
B39: Other Assets: | H39: ='AAPL-3-Statements'!H112 -> 2011 | J39: 0 | L39: 0 | N39: =H39+J39+L39 -> 2011
B40: Total Assets: | H40: =SUM(H35:H39)+H32 -> 47766 | J40: =SUM(J35:J39)+J32 -> 9224.434 | L40: =SUM(L35:L39)+L32 -> 23894.05 | N40: =SUM(N35:N39)+N32 -> 80884.484
B42: Liabilities & Shareholders' Equity:
B43: Current Liabilities:
B44: Accounts Payable: | H44: ='AAPL-3-Statements'!H117 -> 5601 | J44: 496.005 | L44: 0 | N44: =H44+J44+L44 -> 6097.005
B45: Accrued Expenses: | H45: ='AAPL-3-Statements'!H118 -> 3852 | J45: 1603.842 | L45: 0 | N45: =H45+J45+L45 -> 5455.842
B46: Deferred Revenue: | H46: ='AAPL-3-Statements'!H119 -> 2053 | J46: 66.912 | L46: 0 | N46: =H46+J46+L46 -> 2119.912
B47: Total Current Liabilities: | H47: =SUM(H44:H46) -> 11506 | J47: =SUM(J44:J46) -> 2166.759 | L47: =SUM(L44:L46) -> 0 | N47: =SUM(N44:N46) -> 13672.759
...

Sheet Basic-LBO
B2: =Company_Name&" - Basic LBO Model" -> Apple Inc. - Basic LBO Model
B3: ='AAPL-3-Statements'!B3 -> ($ in Millions, Except Per Share Amounts in Dollars and Share Counts in Thousands)
B5: Transaction Assumptions
B7: Current Share Price: | F7: =Share_Price -> 192.06 | H7: Equity Purchase Price: | L7: =F17 -> 212713.43
B8: Offer Premium: | F8: 0.2 | H8: Enterprise Value: | L8: =F23 -> 177318.43
B9: Offer Price Per Share: | F9: =F7*(1+F8) -> 230.472 | H9: EBITDA Purchase Multiple: | L9: =L8/'AAPL-3-Statements'!H91 -> 13.449516
B10: % Debt: | F10: 0.5 | H10: Debt Required: | L10: =F10*L7 -> 106356.71
B11: % Equity: | F11: =1-F10 -> 0.5 | H11: Equity Used: | L11: =F11*L7 -> 106356.71
H12: EBITDA Exit Multiple: | L12: 10
B13: Purchase Price Calculations:
B14: Basic Shares Outstanding: | F14: ='AAPL-3-Statements'!E11 -> 900678.47 | H14: Advisory Fee %: | L14: 0.0002
B15: Basic Equity Value: | F15: =F14/Units*F9 -> 207581.17 | H15: Financing Fee %: | L15: 0.0006
B16: Diluted Shares Outstanding: | F16: =F14+K23 -> 922946.93
B17: Diluted Equity Value: | F17: =F16/Units*F9 -> 212713.43 | H17: Options Calculations - Purchase Price:
B18: Less: Cash & Investments | F18: ='AAPL-3-Statements'!E15 -> 35395
B19: Plus: Debt | F19: ='AAPL-3-Statements'!E16 -> 0 | J19: Exercise
B20: Plus: Minority Interest | F20: ='AAPL-3-Statements'!E17 -> 0 | H20: Name | I20: Number | J20: Price | K20: Dilution
B21: Plus: Preferred Stock | F21: ='AAPL-3-Statements'!E18 -> 0 | H21: Tranche A | I21: ='AAPL-3-Statements'!H15 -> 34375 | J21: ='AAPL-3-Statements'!I15 -> 81.17 | K21: =IF(J21>F9,0,I21-I21*J21/F9) -> 22268.459
B22: Plus: Other Liabilities | F22: ='AAPL-3-Statements'!E19 -> 0 | H22: Tranche B
B23: Enterprise Value: | F23: =F17-F18+F19+F20+F21+F22 -> 177318.43 | H23: Total | K23: =SUM(K21:K22) -> 22268.459
B25: Debt Assumptions
B27: Debt %: | F27: =F10 -> 0.5 | H27: Debt Required: | L27: =L10 -> 106356.71
B28: Bank Debt %: | F28: 0.75 | H28: Bank Debt: | L28: =F28*L27 -> 79767.534
B29: High-Yield Debt %: | F29: =1-F28 -> 0.25 | H29: High-Yield Debt: | L29: =F29*L27 -> 26589.178
B31: Bank Debt Interest Rate: | F31: 0.08 | H31: Bank Debt Principal Repayment %: | L31: 0.1
B32: High-Yield Debt Interest Rate: | F32: 0.11 | H32: High-Yield Debt Principal Repayment %: | L32: 0
B34: Sources & Uses
B36: Sources: | H36: Uses:
B37: Bank Debt: | F37: =L28 -> 79767.534 | H37: Equity Value of Company: | L37: =L7 -> 212713.43
B38: High-Yield Debt: | F38: =L29 -> 26589.178 | H38: Advisory Fees: | L38: =L14*L7 -> 42.542685
B39: Investor Equity: | F39: =L40-SUM(F37:F38) -> 106463.07 | H39: Financing Fees: | L39: =L15*L10 -> 63.814028
B40: Total Sources: | F40: =SUM(F37:F39) -> 212819.78 | H40: Total Uses: | L40: =SUM(L37:L39) -> 212819.78
B42: Operating Assumptions
B44: Initial Cash Balance: | F44: ='AAPL-3-Statements'!H99 -> 6559
B45: Minimum Cash Balance: | F45: 5000
F47: ='AAPL-3-Statements'!F22 -> Historical | I47: ='AAPL-3-Statements'!I22 -> Projections
F48: ='AAPL-3-Statements'!F24 -> FY 2007 | G48: ='AAPL-3-Statements'!G24 -> FY 2008 | H48: ='AAPL-3-Statements'!H24 -> FY 2009 | I48: ='AAPL-3-Statements'!I24 -> FY 2010E | J48: ='AAPL-3-Statements'!J24 -> FY 2011E | K48: ='AAPL-3-Statements'!K24 -> FY 2012E | L48: ='AAPL-3-Statements'!L24 -> FY 2013E | M48: ='AAPL-3-Statements'!M24 -> FY 2014E
B50: Revenue Growth %: | F50: ='AAPL-3-Statements'!F39 -> 0.27248253 | G50: ='AAPL-3-Statements'!G39 -> 0.52538856 | H50: ='AAPL-3-Statements'!H39 -> 0.14440799 | I50: ='AAPL-3-Statements'!I39 -> 0.25 | J50: ='AAPL-3-Statements'!J39 -> 0.17 | K50: ='AAPL-3-Statements'!K39 -> 0.11 | L50: ='AAPL-3-Statements'!L39 -> 0.09 | M50: ='AAPL-3-Statements'!M39 -> 0.07
B51: COGS % Revenue: | F51: ='AAPL-3-Statements'!F40 -> 0.66246236 | G51: ='AAPL-3-Statements'!G40 -> 0.64145173 | H51: ='AAPL-3-Statements'!H40 -> 0.59024201 | I51: ='AAPL-3-Statements'!I40 -> 0.59024201 | J51: ='AAPL-3-Statements'!J40 -> 0.59024201 | K51: ='AAPL-3-Statements'!K40 -> 0.59024201 | L51: ='AAPL-3-Statements'!L40 -> 0.59024201 | M51: ='AAPL-3-Statements'!M40 -> 0.59024201
B52: R&D % Revenue: | F52: ='AAPL-3-Statements'!F41 -> 0.024249329 | G52: ='AAPL-3-Statements'!G41 -> 0.020235968 | H52: ='AAPL-3-Statements'!H41 -> 0.019352834 | I52: ='AAPL-3-Statements'!I41 -> 0.019352834 | J52: ='AAPL-3-Statements'!J41 -> 0.019352834 | K52: ='AAPL-3-Statements'!K41 -> 0.019352834 | L52: ='AAPL-3-Statements'!L41 -> 0.019352834 | M52: ='AAPL-3-Statements'!M41 -> 0.019352834
...

Sheet More-Adv-LBO
B2: =Company_Name&" - More Advanced LBO Model" -> Apple Inc. - More Advanced LBO Model
B3: ='AAPL-3-Statements'!B3 -> ($ in Millions, Except Per Share Amounts in Dollars and Share Counts in Thousands)
B5: Transaction Assumptions
B7: Current Share Price: | F7: =Share_Price -> 192.06 | H7: Equity Purchase Price: | L7: =F17 -> 212713.43
B8: Offer Premium: | F8: 0.2 | H8: Enterprise Value: | L8: =F23 -> 177318.43
B9: Offer Price Per Share: | F9: =F7*(1+F8) -> 230.472 | H9: EBITDA Purchase Multiple: | L9: =L8/H124 -> 13.449516
B10: Leverage Ratio: | F10: 6 | H10: Debt Required: | L10: =F10*H124 -> 79104
H11: Equity Used: | L11: =L7-L10 -> 133609.43
H12: EBITDA Exit Multiple: | L12: 10
B13: Purchase Price Calculations:
B14: Basic Shares Outstanding: | F14: ='AAPL-3-Statements'!E11 -> 900678.47 | H14: Advisory Fee %: | L14: 0.0002
B15: Basic Equity Value: | F15: =F14/Units*F9 -> 207581.17 | H15: Financing Fee %: | L15: 0.0006
B16: Diluted Shares Outstanding: | F16: =F14+K23 -> 922946.93 | H16: Legal & Misc. Fees: | L16: 10
B17: Diluted Equity Value: | F17: =F16/Units*F9 -> 212713.43
