Workbook

Sheet README
A1: NORTH SOUND HEALTH NETWORK — Sterile Supply Control Workbook
A2: Purpose: control workbook behind the Sterile Supply Resilience Portal. Quantifies shortage exposure,
A3: expiry/recall exposure, supplier performance and the adverse/base/upside action program for the supplier
A4: renewal decision. Analysis cells are live formulas over raw data sheets (Lots_Data, Usage_Data, PO_Data,
A5: Delivery_Data, Quality_Data, Exceptions, Site_Constraints, Action_Catalog).
A7: Sheet map:
A8: Inputs — editable scenario assumptions: multipliers, target cover, score weights, snapshot date, window.
A9: Dashboard — KPI summary; the figures that must reconcile with the portal.
A10: SKU_Exposure — per-SKU demand, days-of-cover, scenario gaps, reorder-point adequacy.
A11: Scenario_Decision — action catalog per scenario with capacity/mutual-exclusion/eligibility checks.
A12: Supplier_Scorecard — delivery, quality and renewal scoring over the supplier database extracts.
A13: Exceptions — exception register with evidence grading (invoice/statement = documented).
... A31: conclusions (see Uncertainty_Register). No contract terms, prices or authorities beyond the sources are asserted.

Sheet Inputs
A1: Editable Inputs & Scenario Assumptions
A2: Yellow cells are the only editable inputs; downstream sheets recalculate from them. Locators cited per row.
A4: Snapshot / analysis date | B4: 46259
A5: Window start | B5: 2026-01
A6: Window end | B6: 2026-08
A7: Target days of cover | B7: 30
A9: Scenario | B9: Demand multiplier | C9: Basis / evidence locator
A10: adverse | B10: 1.315 | C10: Observed surge ratio (usage file exception_flag="surge"): mean of per-SKU surge/non-surge usage ratios over 16 flagged rows in window. Small sample — see U-03.
A11: base | B11: 1 | C11: Trailing 8 complete months (Inputs B5..B6) average monthly usage.
A12: upside | B12: 0.9 | C12: Planning judgment — demand relief; no direct evidence in sources. Editable.
A14: Score weight | B14: Value | C14: Component
A15: OTD weight | B15: 0.4 | C15: on-time/placed
A16: Lead-time weight | B16: 0.25 | C16: min lead / supplier lead
A17: Quality-closure weight | B17: 0.2 | C17: 1 - not-closed/max not-closed
A18: Fill weight | B18: 0.15 | C18: items received/ordered (PO_Data)

Sheet Lots_Data
A1: sku_id | B1: item_description | C1: clinical_family | D1: supplier | E1: site_id | F1: lot_id | G1: unit_cost_usd | H1: on_hand_qty | I1: quarantine_qty | J1: recall_state | K1: usable_qty | L1: usable_value | M1: onhand_value | N1: lead_time_days | O1: storage_zone | P1: expiry_date | Q1: days_to_expiry | R1: expiry_bucket | S1: static_reorder_point
A2: SS-01001 | B2: vascular access kit 100 | C2: vascular | D2: Northstar Surgical | E2: HOSP-1 | F2: LOT-07001 | G2: 16.47 | H2: 13 | I2: 0 | J2: recalled | K2: =IF(J2="recalled",0,MAX(0,H2-I2)) | L2: =K2*G2 | M2: =H2*G2 | N2: 6 | O2: D2-21 | P2: 46388 | Q2: =P2-Inputs!$B$4 | R2: =IF(Q2<0,"expired",IF(Q2<=30,"<=30d",IF(Q2<=90,"31-90d",IF(Q2<=180,"91-180d",">180d")))) | S2: 5
A3: SS-01002 | B3: respiratory circuit 101 | C3: respiratory | D3: MedAxis Distribution | E3: HOSP-2 | F3: LOT-07002 | G3: 37.23 | H3: 3 | I3: 0 | J3: clear | K3: =IF(J3="recalled",0,MAX(0,H3-I3)) | L3: =K3*G3 | M3: =H3*G3 | N3: 6 | O3: A5-08 | P3: 46420 | Q3: =P3-Inputs!$B$4 | R3: =IF(Q3<0,"expired",IF(Q3<=30,"<=30d",IF(Q3<=90,"31-90d",IF(Q3<=180,"91-180d",">180d")))) | S3: 5
A4: SS-01003 | B4: sterile surgical pack 102 | C4: surgical | D4: SterilePath Medical | E4: HOSP-3 | F4: LOT-07003 | G4: 23.98 | H4: 3 | I4: 0 | J4: clear | K4: =IF(J4="recalled",0,MAX(0,H4-I4)) | L4: =K4*G4 | M4: =H4*G4 | N4: 3 | O4: B8-03 | P4: 46449 | Q4: =P4-Inputs!$B$4 | R4: =IF(Q4<0,"expired",IF(Q4<=30,"<=30d",IF(Q4<=90,"31-90d",IF(Q4<=180,"91-180d",">180d")))) | S4: 5
A5: SS-01004 | B5: diagnostic collection set 103 | C5: diagnostic | D5: Aegis Clinical Supply | E5: HOSP-4 | F5: LOT-07004 | G5: 23.77 | H5: 50 | I5: 0 | J5: clear | K5: =IF(J5="recalled",0,MAX(0,H5-I5)) | L5: =K5*G5 | M5: =H5*G5 | N5: 7 | O5: A12-07 | P5: 46481 | Q5: =P5-Inputs!$B$4 | R5: =IF(Q5<0,"expired",IF(Q5<=30,"<=30d",IF(Q5<=90,"31-90d",IF(Q5<=180,"91-180d",">180d")))) | S5: 5
A6: SS-01005 | B6: advanced wound dressing 104 | C6: wound | D6: HarborMed Logistics | E6: HOSP-1 | F6: LOT-07005 | G6: 12.46 | H6: 3 | I6: 0 | J6: clear | K6: =IF(J6="recalled",0,MAX(0,H6-I6)) | L6: =K6*G6 | M6: =H6*G6 | N6: 11 | O6: F4-01 | P6: 46512 | Q6: =P6-Inputs!$B$4 | R6: =IF(Q6<0,"expired",IF(Q6<=30,"<=30d",IF(Q6<=90,"31-90d",IF(Q6<=180,"91-180d",">180d")))) | S6: 5
A7: SS-01006 | B7: vascular access kit 105 | C7: vascular | D7: Northstar Surgical | E7: HOSP-2 | F7: LOT-07006 | G7: 21.42 | H7: 13 | I7: 0 | J7: clear | K7: =IF(J7="recalled",0,MAX(0,H7-I7)) | L7: =K7*G7 | M7: =H7*G7 | N7: 7 | O7: B6-11 | P7: 46544 | Q7: =P7-Inputs!$B$4 | R7: =IF(Q7<0,"expired",IF(Q7<=30,"<=30d",IF(Q7<=90,"31-90d",IF(Q7<=180,"91-180d",">180d")))) | S7: 5
A8: SS-01007 | B8: respiratory circuit 106 | C8: respiratory | D8: MedAxis Distribution | E8: HOSP-3 | F8: LOT-07007 | G8: 34.4 | H8: 26 | I8: 0 | J8: clear | K8: =IF(J8="recalled",0,MAX(0,H8-I8)) | L8: =K8*G8 | M8: =H8*G8 | N8: 3 | O8: A2-06 | P8: 46575 | Q8: =P8-Inputs!$B$4 | R8: =IF(Q8<0,"expired",IF(Q8<=30,"<=30d",IF(Q8<=90,"31-90d",IF(Q8<=180,"91-180d",">180d")))) | S8: 5
A9: SS-01008 | B9: sterile surgical pack 107 | C9: surgical | D9: SterilePath Medical | E9: HOSP-4 | F9: LOT-07008 | G9: 19.54 | H9: 0 | I9: 0 | J9: clear | K9: =IF(J9="recalled",0,MAX(0,H9-I9)) | L9: =K9*G9 | M9: =H9*G9 | N9: 7 | O9: C8-21 | P9: 46607 | Q9: =P9-Inputs!$B$4 | R9: =IF(Q9<0,"expired",IF(Q9<=30,"<=30d",IF(Q9<=90,"31-90d",IF(Q9<=180,"91-180d",">180d")))) | S9: 5
A10: SS-01009 | B10: diagnostic collection set 108 | C10: diagnostic | D10: Aegis Clinical Supply | E10: HOSP-1 | F10: LOT-07009 | G10: 9.96 | H10: 19 | I10: 0 | J10: clear | K10: =IF(J10="recalled",0,MAX(0,H10-I10)) | L10: =K10*G10 | M10: =H10*G10 | N10: 8 | O10: D7-20 | P10: 46639 | Q10: =P10-Inputs!$B$4 | R10: =IF(Q10<0,"expired",IF(Q10<=30,"<=30d",IF(Q10<=90,"31-90d",IF(Q10<=180,"91-180d",">180d")))) | S10: 16
A11: SS-01010 | B11: advanced wound dressing 109 | C11: wound | D11: HarborMed Logistics | E11: HOSP-2 | F11: LOT-07010 | G11: 8.34 | H11: 10 | I11: 0 | J11: clear | K11: =IF(J11="recalled",0,MAX(0,H11-I11)) | L11: =K11*G11 | M11: =H11*G11 | N11: 6 | O11: D4-02 | P11: 46670 | Q11: =P11-Inputs!$B$4 | R11: =IF(Q11<0,"expired",IF(Q11<=30,"<=30d",IF(Q11<=90,"31-90d",IF(Q11<=180,"91-180d",">180d")))) | S11: 5
A12: SS-01011 | B12: vascular access kit 110 | C12: vascular | D12: Northstar Surgical | E12: HOSP-3 | F12: LOT-07011 | G12: 3.58 | H12: 16 | I12: 0 | J12: clear | K12: =IF(J12="recalled",0,MAX(0,H12-I12)) | L12: =K12*G12 | M12: =H12*G12 | N12: 7 | O12: E12-03 | P12: 46702 | Q12: =P12-Inputs!$B$4 | R12: =IF(Q12<0,"expired",IF(Q12<=30,"<=30d",IF(Q12<=90,"31-90d",IF(Q12<=180,"91-180d",">180d")))) | S12: 5
A13: SS-01012 | B13: respiratory circuit 111 | C13: respiratory | D13: MedAxis Distribution | E13: HOSP-4 | F13: LOT-07012 | G13: 20.76 | H13: 3 | I13: 3 | J13: clear | K13: =IF(J13="recalled",0,MAX(0,H13-I13)) | L13: =K13*G13 | M13: =H13*G13 | N13: 6 | O13: C9-19 | P13: 46733 | Q13: =P13-Inputs!$B$4 | R13: =IF(Q13<0,"expired",IF(Q13<=30,"<=30d",IF(Q13<=90,"31-90d",IF(Q13<=180,"91-180d",">180d")))) | S13: 5
... A234: SS-01233 | B234: sterile surgical pack 110 | C234: surgical | D234: SterilePath Medical | E234: HOSP-1 | F234: LOT-07233 | G234: 19.38 | H234: 2 | I234: 0 | J234: clear | K234: =IF(J234="recalled",0,MAX(0,H234-I234)) | L234: =K234*G234 | M234: =H234*G234 | N234: 8 | O234: A9-23 | P234: 46524 | Q234: =P234-Inputs!$B$4 | R234: =IF(Q234<0,"expired",IF(Q234<=30,"<=30d",IF(Q234<=90,"31-90d",IF(Q234<=180,"91-180d",">180d")))) | S234: 5

Sheet Usage_Data
A1: period | B1: site_id | C1: sku_id | D1: usage_qty | E1: transfer_qty | F1: exception_flag | G1: in_window
A2: 2026-01 | B2: HOSP-1 | C2: SS-01001 | D2: 48 | E2: 0 | F2: surge | G2: =IF(AND(A2>=Inputs!$B$5,A2<=Inputs!$B$6),1,0)
A3: 2026-01 | B3: HOSP-2 | C3: SS-01002 | D3: 24 | E3: 1 | G3: =IF(AND(A3>=Inputs!$B$5,A3<=Inputs!$B$6),1,0)
A4: 2026-01 | B4: HOSP-3 | C4: SS-01003 | D4: 0 | E4: 0 | G4: =IF(AND(A4>=Inputs!$B$5,A4<=Inputs!$B$6),1,0)
A5: 2026-01 | B5: HOSP-4 | C5: SS-01004 | D5: 24 | E5: 0 | G5: =IF(AND(A5>=Inputs!$B$5,A5<=Inputs!$B$6),1,0)
A6: 2026-01 | B6: HOSP-1 | C6: SS-01005 | D6: 96 | E6: 0 | G6: =IF(AND(A6>=Inputs!$B$5,A6<=Inputs!$B$6),1,0)
A7: 2026-01 | B7: HOSP-2 | C7: SS-01006 | D7: 0 | E7: 0 | G7: =IF(AND(A7>=Inputs!$B$5,A7<=Inputs!$B$6),1,0)
A8: 2026-01 | B8: HOSP-3 | C8: SS-01007 | D8: 13 | E8: 3 | G8: =IF(AND(A8>=Inputs!$B$5,A8<=Inputs!$B$6),1,0)
A9: 2026-01 | B9: HOSP-4 | C9: SS-01008 | D9: 0 | E9: 0 | G9: =IF(AND(A9>=Inputs!$B$5,A9<=Inputs!$B$6),1,0)
A10: 2026-01 | B10: HOSP-1 | C10: SS-01009 | D10: 12 | E10: 0 | G10: =IF(AND(A10>=Inputs!$B$5,A10<=Inputs!$B$6),1,0)
A11: 2026-01 | B11: HOSP-2 | C11: SS-01010 | D11: 96 | E11: 0 | G11: =IF(AND(A11>=Inputs!$B$5,A11<=Inputs!$B$6),1,0)
A12: 2026-01 | B12: HOSP-3 | C12: SS-01101 | D12: 48 | E12: 0 | G12: =IF(AND(A12>=Inputs!$B$5,A12<=Inputs!$B$6),1,0)
A13: 2026-01 | B13: HOSP-4 | C13: SS-01012 | D13: 15 | E13: 0 | G13: =IF(AND(A13>=Inputs!$B$5,A13<=Inputs!$B$6),1,0)
A14: 2026-01 | B14: HOSP-1 | C14: SS-01013 | D14: 5 | E14: 0 | G14: =IF(AND(A14>=Inputs!$B$5,A14<=Inputs!$B$6),1,0)
... A174: 2026-01 | B174: HOSP-1 | C174: SS-01173 | D174: 48 | E174: 0 | G174: =IF(AND(A174>=Inputs!$B$5,A174<=Inputs!$B$6),1,0)
A175: 2026-01 | B175: HOSP-2 | C175: SS-01174 | D175: 36 | E175: 0 | F175: surge | G175: =IF(AND(A175>=Inputs!$B$5,A175<=Inputs!$B$6),1,0)
A176: 2026-01 | B176: HOSP-3 | C176: SS-01175 | D176: 0 | E176: 0 | G176: =IF(AND(A176>=Inputs!$B$5,A176<=Inputs!$B$6),1,0)
A177: 2026-01 | B177: HOSP-4 | C177: SS-01176 | D177: 48 | E177: 0 | G177: =IF(AND(A177>=Inputs!$B$5,A177<=Inputs!$B$6),1,0)
A178: 2026-01 | B178: HOSP-1 | C178: SS-01177 | D178: 24 | E178: 0 | G178: =IF(AND(A178>=Inputs!$B$5,A178<=Inputs!$B$6),1,0)
A179: 2026-01 | B179: HOSP-2 | C179: SS-01178 | D179: 0 | E179: 0 | G179: =IF(AND(A179>=Inputs!$B$5,A179<=Inputs!$B$6),1,0)
A180: 2026-01 | B180: HOSP-3 | C180: SS-01179 | D180: 144 | E180: 0 | G180: =IF(AND(A180>=Inputs!$B$5,A180<=Inputs!$B$6),1,0)
A181: 2026-01 | B181: HOSP-4 | C181: SS-01180 | D181: 0 | E181: 0 | G181: =IF(AND(A181>=Inputs!$B$5,A181<=Inputs!$B$6),1,0)
A182: 2026-01 | B182: HOSP-1 | C182: SS-01181 | D182: 0 | E182: 1 | G182: =IF(AND(A182>=Inputs!$B$5,A182<=Inputs!$B$6),1,0)
A183: 2026-01 | B183: HOSP-2 | C183: SS-01182 | D183: 0 | E183: 0 | G183: =IF(AND(A183>=Inputs!$B$5,A183<=Inputs!$B$6),1,0)
A184: 2026-01 | B184: HOSP-3 | C184: SS-01183 | D184: 12 | E184: 0 | G184: =IF(AND(A184>=Inputs!$B$5,A184<=Inputs!$B$6),1,0)
A185: 2026-01 | B185: HOSP-4 | C185: SS-01184 | D185: 60 | E185: 0 | G185: =IF(AND(A185>=Inputs!$B$5,A185<=Inputs!$B$6),1,0)
A186: 2026-01 | B186: HOSP-1 | C186: SS-01185 | D186: 2 | E186: 2 | G186: =IF(AND(A186>=Inputs!$B$5,A186<=Inputs!$B$6),1,0)
A187: 2026-01 | B187: HOSP-2 | C187: SS-01186 | D187: 0 | E187: 0 | G187: =IF(AND(A187>=Inputs!$B$5,A187<=Inputs!$B$6),1,0)
... A347: 2026-02 | B347: HOSP-2 | C347: SS-01113 | D347: 0 | E347: 0 | G347: =IF(AND(A347>=Inputs!$B$5,A347<=Inputs!$B$6),1,0)
A348: 2026-02 | B348: HOSP-3 | C348: SS-01114 | D348: 36 | E348: 0 | F348: surge | G348: =IF(AND(A348>=Inputs!$B$5,A348<=Inputs!$B$6),1,0)
A349: 2026-02 | B349: HOSP-4 | C349: SS-01115 | D349: 13 | E349: 0 | G349: =IF(AND(A349>=Inputs!$B$5,A349<=Inputs!$B$6),1,0)
A350: 2026-02 | B350: HOSP-1 | C350: SS-01116 | D350: 24 | E350: 0 | G350: =IF(AND(A350>=Inputs!$B$5,A350<=Inputs!$B$6),1,0)
A351: 2026-02 | B351: HOSP-2 | C351: SS-01117 | D351: 300 | E351: 0 | G351: =IF(AND(A351>=Inputs!$B$5,A351<=Inputs!$B$6),1,0)
A352: 2026-02 | B352: HOSP-3 | C352: SS-01118 | D352: 0 | E352: 0 | G352: =IF(AND(A352>=Inputs!$B$5,A352<=Inputs!$B$6),1,0)
A353: 2026-02 | B353: HOSP-4 | C353: SS-01119 | D353: 2 | E353: 1 | G353: =IF(AND(A353>=Inputs!$B$5,A353<=Inputs!$B$6),1,0)
A354: 2026-02 | B354: HOSP-1 | C354: SS-01120 | D354: 60 | E354: 0 | G354: =IF(AND(A354>=Inputs!$B$5,A354<=Inputs!$B$6),1,0)
A355: 2026-02 | B355: HOSP-2 | C355: SS-01121 | D355: 18 | E355: 0 | G355: =IF(AND(A355>=Inputs!$B$5,A355<=Inputs!$B$6),1,0)
A356: 2026-02 | B356: HOSP-3 | C356: SS-01122 | D356: 2 | E356: 3 | G356: =IF(AND(A356>=Inputs!$B$5,A356<=Inputs!$B$6),1,0)
A357: 2026-02 | B357: HOSP-4 | C357: SS-01123 | D357: 24 | E357: 0 | G357: =IF(AND(A357>=Inputs!$B$5,A357<=Inputs!$B$6),1,0)
A358: 2026-02 | B358: HOSP-1 | C358: SS-01124 | D358: 0 | E358: 0 | G358: =IF(AND(A358>=Inputs!$B$5,A358<=Inputs!$B$6),1,0)
...

Sheet Usage_Summary
A1: Per-SKU usage aggregates (formulas over Usage_Data; window = Inputs B5..B6)
A3: sku_id | B3: window_usage | C3: base_monthly_usage | D3: surge_flags | E3: transfers_in_window
A4: SS-01001 | B4: =SUMIFS(Usage_Data!$D$2:$D$5001,Usage_Data!$C$2:$C$5001,$A4,Usage_Data!$G$2:$G$5001,1) | C4: =B4/8 | D4: =COUNTIFS(Usage_Data!$C$2:$C$5001,$A4,Usage_Data!$F$2:$F$5001,"surge",Usage_Data!$G$2:$G$5001,1) | E4: =SUMIFS(Usage_Data!$E$2:$E$5001,Usage_Data!$C$2:$C$5001,$A4,Usage_Data!$G$2:$G$5001,1)
A5: SS-01002 | B5: =SUMIFS(Usage_Data!$D$2:$D$5001,Usage_Data!$C$2:$C$5001,$A5,Usage_Data!$G$2:$G$5001,1) | C5: =B5/8 | D5: =COUNTIFS(Usage_Data!$C$2:$C$5001,$A5,Usage_Data!$F$2:$F$5001,"surge",Usage_Data!$G$2:$G$5001,1) | E5: =SUMIFS(Usage_Data!$E$2:$E$5001,Usage_Data!$C$2:$C$5001,$A5,Usage_Data!$G$2:$G$5001,1)
A6: SS-01003 | B6: =SUMIFS(Usage_Data!$D$2:$D$5001,Usage_Data!$C$2:$C$5001,$A6,Usage_Data!$G$2:$G$5001,1) | C6: =B6/8 | D6: =COUNTIFS(Usage_Data!$C$2:$C$5001,$A6,Usage_Data!$F$2:$F$5001,"surge",Usage_Data!$G$2:$G$5001,1) | E6: =SUMIFS(Usage_Data!$E$2:$E$5001,Usage_Data!$C$2:$C$5001,$A6,Usage_Data!$G$2:$G$5001,1)
A7: SS-01004 | B7: =SUMIFS(Usage_Data!$D$2:$D$5001,Usage_Data!$C$2:$C$5001,$A7,Usage_Data!$G$2:$G$5001,1) | C7: =B7/8 | D7: =COUNTIFS(Usage_Data!$C$2:$C$5001,$A7,Usage_Data!$F$2:$F$5001,"surge",Usage_Data!$G$2:$G$5001,1) | E7: =SUMIFS(Usage_Data!$E$2:$E$5001,Usage_Data!$C$2:$C$5001,$A7,Usage_Data!$G$2:$G$5001,1)
A8: SS-01005 | B8: =SUMIFS(Usage_Data!$D$2:$D$5001,Usage_Data!$C$2:$C$5001,$A8,Usage_Data!$G$2:$G$5001,1) | C8: =B8/8 | D8: =COUNTIFS(Usage_Data!$C$2:$C$5001,$A8,Usage_Data!$F$2:$F$5001,"surge",Usage_Data!$G$2:$G$5001,1) | E8: =SUMIFS(Usage_Data!$E$2:$E$5001,Usage_Data!$C$2:$C$5001,$A8,Usage_Data!$G$2:$G$5001,1)
A9: SS-01006 | B9: =SUMIFS(Usage_Data!$D$2:$D$5001,Usage_Data!$C$2:$C$5001,$A9,Usage_Data!$G$2:$G$5001,1) | C9: =B9/8 | D9: =COUNTIFS(Usage_Data!$C$2:$C$5001,$A9,Usage_Data!$F$2:$F$5001,"surge",Usage_Data!$G$2:$G$5001,1) | E9: =SUMIFS(Usage_Data!$E$2:$E$5001,Usage_Data!$C$2:$C$5001,$A9,Usage_Data!$G$2:$G$5001,1)
A10: SS-01007 | B10: =SUMIFS(Usage_Data!$D$2:$D$5001,Usage_Data!$C$2:$C$5001,$A10,Usage_Data!$G$2:$G$5001,1) | C10: =B10/8 | D10: =COUNTIFS(Usage_Data!$C$2:$C$5001,$A10,Usage_Data!$F$2:$F$5001,"surge",Usage_Data!$G$2:$G$5001,1) | E10: =SUMIFS(Usage_Data!$E$2:$E$5001,Usage_Data!$C$2:$C$5001,$A10,Usage_Data!$G$2:$G$5001,1)
A11: SS-01008 | B11: =SUMIFS(Usage_Data!$D$2:$D$5001,Usage_Data!$C$2:$C$5001,$A11,Usage_Data!$G$2:$G$5001,1) | C11: =B11/8 | D11: =COUNTIFS(Usage_Data!$C$2:$C$5001,$A11,Usage_Data!$F$2:$F$5001,"surge",Usage_Data!$G$2:$G$5001,1) | E11: =SUMIFS(Usage_Data!$E$2:$E$5001,Usage_Data!$C$2:$C$5001,$A11,Usage_Data!$G$2:$G$5001,1)
A12: SS-01009 | B12: =SUMIFS(Usage_Data!$D$2:$D$5001,Usage_Data!$C$2:$C$5001,$A12,Usage_Data!$G$2:$G$5001,1) | C12: =B12/8 | D12: =COUNTIFS(Usage_Data!$C$2:$C$5001,$A12,Usage_Data!$F$2:$F$5001,"surge",Usage_Data!$G$2:$G$5001,1) | E12: =SUMIFS(Usage_Data!$E$2:$E$5001,Usage_Data!$C$2:$C$5001,$A12,Usage_Data!$G$2:$G$5001,1)
A13: SS-01010 | B13: =SUMIFS(Usage_Data!$D$2:$D$5001,Usage_Data!$C$2:$C$5001,$A13,Usage_Data!$G$2:$G$5001,1) | C13: =B13/8 | D13: =COUNTIFS(Usage_Data!$C$2:$C$5001,$A13,Usage_Data!$F$2:$F$5001,"surge",Usage_Data!$G$2:$G$5001,1) | E13: =SUMIFS(Usage_Data!$E$2:$E$5001,Usage_Data!$C$2:$C$5001,$A13,Usage_Data!$G$2:$G$5001,1)
A14: SS-01011 | B14: =SUMIFS(Usage_Data!$D$2:$D$5001,Usage_Data!$C$2:$C$5001,$A14,Usage_Data!$G$2:$G$5001,1) | C14: =B14/8 | D14: =COUNTIFS(Usage_Data!$C$2:$C$5001,$A14,Usage_Data!$F$2:$F$5001,"surge",Usage_Data!$G$2:$G$5001,1) | E14: =SUMIFS(Usage_Data!$E$2:$E$5001,Usage_Data!$C$2:$C$5001,$A14,Usage_Data!$G$2:$G$5001,1)
A15: SS-01012 | B15: =SUMIFS(Usage_Data!$D$2:$D$5001,Usage_Data!$C$2:$C$5001,$A15,Usage_Data!$G$2:$G$5001,1) | C15: =B15/8 | D15: =COUNTIFS(Usage_Data!$C$2:$C$5001,$A15,Usage_Data!$F$2:$F$5001,"surge",Usage_Data!$G$2:$G$5001,1) | E15: =SUMIFS(Usage_Data!$E$2:$E$5001,Usage_Data!$C$2:$C$5001,$A15,Usage_Data!$G$2:$G$5001,1)
... A236: SS-01233 | B236: =SUMIFS(Usage_Data!$D$2:$D$5001,Usage_Data!$C$2:$C$5001,$A236,Usage_Data!$G$2:$G$5001,1) | C236: =B236/8 | D236: =COUNTIFS(Usage_Data!$C$2:$C$5001,$A236,Usage_Data!$F$2:$F$5001,"surge",Usage_Data!$G$2:$G$5001,1) | E236: =SUMIFS(Usage_Data!$E$2:$E$5001,Usage_Data!$C$2:$C$5001,$A236,Usage_Data!$G$2:$G$5001,1)

Sheet ABC_Classification
A1: ABC classification from complete annual usage value + supplier concentration by class
A2: Annual usage value = SUMIFS(Usage_Data usage, sku) * Lots_Data unit_cost. Classes by cumulative value share: A<=80%, B<=95%, C>95% (80/95 split). annual_usage_value_total reconciles to 879602.39.
A4: site_sku | B4: site_id | C4: sku_id | D4: abc_class | E4: annual_usage_value | F4: unit_cost_usd | G4: annual_usage_qty | H4: supplier | I4: clinical_family
A5: HOSP-1|SS-01001 | B5: =INDEX(Lots_Data!$E$2:$E$234,MATCH($A5,Lots_Data!$A$2:$A$234,0)) | C5: =INDEX(Lots_Data!$A$2:$A$234,MATCH($A5,Lots_Data!$A$2:$A$234,0)) | D5: B | E5: =INDEX(Usage_Summary!$B$4:$B$236,MATCH($C5,Usage_Summary!$A$4:$A$236,0))*INDEX(Lots_Data!$G$2:$G$234,MATCH($A5,Lots_Data!$A$2:$A$234,0)) | F5: =INDEX(Lots_Data!$G$2:$G$234,MATCH($A5,Lots_Data!$A$2:$A$234,0)) | G5: =INDEX(Usage_Summary!$B$4:$B$236,MATCH($C5,Usage_Summary!$A$4:$A$236,0)) | H5: =INDEX(Lots_Data!$D$2:$D$234,MATCH($A5,Lots_Data!$A$2:$A$234,0)) | I5: =INDEX(Lots_Data!$C$2:$C$234,MATCH($A5,Lots_Data!$A$2:$A$234,0))
A6: HOSP-1|SS-01005 | B6: =INDEX(Lots_Data!$E$2:$E$234,MATCH($A6,Lots_Data!$A$2:$A$234,0)) | C6: =INDEX(Lots_Data!$A$2:$A$234,MATCH($A6,Lots_Data!$A$2:$A$234,0)) | D6: A | E6: =INDEX(Usage_Summary!$B$4:$B$236,MATCH($C6,Usage_Summary!$A$4:$A$236,0))*INDEX(Lots_Data!$G$2:$G$234,MATCH($A6,Lots_Data!$A$2:$A$234,0)) | F6: =INDEX(Lots_Data!$G$2:$G$234,MATCH($A6,Lots_Data!$A$2:$A$234,0)) | G6: =INDEX(Usage_Summary!$B$4:$B$236,MATCH($C6,Usage_Summary!$A$4:$A$236,0)) | H6: =INDEX(Lots_Data!$D$2:$D$234,MATCH($A6,Lots_Data!$A$2:$A$234,0)) | I6: =INDEX(Lots_Data!$C$2:$C$234,MATCH($A6,Lots_Data!$A$2:$A$234,0))
A7: HOSP-1|SS-01009 | B7: =INDEX(Lots_Data!$E$2:$E$234,MATCH($A7,Lots_Data!$A$2:$A$234,0)) | C7: =INDEX(Lots_Data!$A$2:$A$234,MATCH($A7,Lots_Data!$A$2:$A$234,0)) | D7: B | E7: =INDEX(Usage_Summary!$B$4:$B$236,MATCH($C7,Usage_Summary!$A$4:$A$236,0))*INDEX(Lots_Data!$G$2:$G$234,MATCH($A7,Lots_Data!$A$2:$A$234,0)) | F7: =INDEX(Lots_Data!$G$2:$G$234,MATCH($A7,Lots_Data!$A$2:$A$234,0)) | G7: =INDEX(Usage_Summary!$B$4:$B$236,MATCH($C7,Usage_Summary!$A$4:$A$236,0)) | H7: =INDEX(Lots_Data!$D$2:$D$234,MATCH($A7,Lots_Data!$A$2:$A$234,0)) | I7: =INDEX(Lots_Data!$C$2:$C$234,MATCH($A7,Lots_Data!$A$2:$A$234,0))
A8: HOSP-1|SS-01013 | B8: =INDEX(Lots_Data!$E$2:$E$234,MATCH($A8,Lots_Data!$A$2:$A$234,0)) | C8: =INDEX(Lots_Data!$A$2:$A$234,MATCH($A8,Lots_Data!$A$2:$A$234,0)) | D8: A | E8: =INDEX(Usage_Summary!$B$4:$B$236,MATCH($C8,Usage_Summary!$A$4:$A$236,0))*INDEX(Lots_Data!$G$2:$G$234,MATCH($A8,Lots_Data!$A$2:$A$234,0)) | F8: =INDEX(Lots_Data!$G$2:$G$234,MATCH($A8,Lots_Data!$A$2:$A$234,0)) | G8: =INDEX(Usage_Summary!$B$4:$B$236,MATCH($C8,Usage_Summary!$A$4:$A$236,0)) | H8: =INDEX(Lots_Data!$D$2:$D$234,MATCH($A8,Lots_Data!$A$2:$A$234,0)) | I8: =INDEX(Lots_Data!$C$2:$C$234,MATCH($A8,Lots_Data!$A$2:$A$234,0))
A9: HOSP-1|SS-01017 | B9: =INDEX(Lots_Data!$E$2:$E$234,MATCH($A9,Lots_Data!$A$2:$A$234,0)) | C9: =INDEX(Lots_Data!$A$2:$A$234,MATCH($A9,Lots_Data!$A$2:$A$234,0)) | D9: C | E9: =INDEX(Usage_Summary!$B$4:$B$236,MATCH($C9,Usage_Summary!$A$4:$A$236,0))*INDEX(Lots_Data!$G$2:$G$234,MATCH($A9,Lots_Data!$A$2:$A$234,0)) | F9: =INDEX(Lots_Data!$G$2:$G$234,MATCH($A9,Lots_Data!$A$2:$A$234,0)) | G9: =INDEX(Usage_Summary!$B$4:$B$236,MATCH($C9,Usage_Summary!$A$4:$A$236,0)) | H9: =INDEX(Lots_Data!$D$2:$D$234,MATCH($A9,Lots_Data!$A$2:$A$234,0)) | I9: =INDEX(Lots_Data!$C$2:$C$234,MATCH($A9,Lots_Data!$A$2:$A$234,0))
A10: HOSP-1|SS-01021 | B10: =INDEX(Lots_Data!$E$2:$E$234,MATCH($A10,Lots_Data!$A$2:$A$234,0)) | C10: =INDEX(Lots_Data!$A$2:$A$234,MATCH($A10,Lots_Data!$A$2:$A$234,0)) | D10: A | E10: =INDEX(Usage_Summary!$B$4:$B$236,MATCH($C10,Usage_Summary!$A$4:$A$236,0))*INDEX(Lots_Data!$G$2:$G$234,MATCH($A10,Lots_Data!$A$2:$A$234,0)) | F10: =INDEX(Lots_Data!$G$2:$G$234,MATCH($A10,Lots_Data!$A$2:$A$234,0)) | G10: =INDEX(Usage_Summary!$B$4:$B$236,MATCH($C10,Usage_Summary!$A$4:$A$236,0)) | H10: =INDEX(Lots_Data!$D$2:$D$234,MATCH($A10,Lots_Data!$A$2:$A$234,0)) | I10: =INDEX(Lots_Data!$C$2:$C$234,MATCH($A10,Lots_Data!$A$2:$A$234,0))
A11: HOSP-1|SS-01025 | B11: =INDEX(Lots_Data!$E$2:$E$234,MATCH($A11,Lots_Data!$A$2:$A$234,0)) | C11: =INDEX(Lots_Data!$A$2:$A$234,MATCH($A11,Lots_Data!$A$2:$A$234,0)) | D11: C | E11: =INDEX(Usage_Summary!$B$4:$B$236,MATCH($C11,Usage_Summary!$A$4:$A$236,0))*INDEX(Lots_Data!$G$2:$G$234,MATCH($A11,Lots_Data!$A$2:$A$234,0)) | F11: =INDEX(Lots_Data!$G$2:$G$234,MATCH($A11,Lots_Data!$A$2:$A$234,0)) | G11: =INDEX(Usage_Summary!$B$4:$B$236,MATCH($C11,Usage_Summary!$A$4:$A$236,0)) | H11: =INDEX(Lots_Data!$D$2:$D$234,MATCH($A11,Lots_Data!$A$2:$A$234,0)) | I11: =INDEX(Lots_Data!$C$2:$C$234,MATCH($A11,Lots_Data!$A$2:$A$234,0))
A12: HOSP-1|SS-01029 | B12: =INDEX(Lots_Data!$E$2:$E$234,MATCH($A12,Lots_Data!$A$2:$A$234,0)) | C12: =INDEX(Lots_Data!$A$2:$A$234,MATCH($A12,Lots_Data!$A$2:$A$234,0)) | D12: B | E12: =INDEX(Usage_Summary!$B$4:$B$236,MATCH($C12,Usage_Summary!$A$4:$A$236,0))*INDEX(Lots_Data!$G$2:$G$234,MATCH($A12,Lots_Data!$A$2:$A$234,0)) | F12: =INDEX(Lots_Data!$G$2:$G$234,MATCH($A12,Lots_Data!$A$2:$A$234,0)) | G12: =INDEX(Usage_Summary!$B$4:$B$236,MATCH($C12,Usage_Summary!$A$4:$A$236,0)) | H12: =INDEX(Lots_Data!$D$2:$D$234,MATCH($A12,Lots_Data!$A$2:$A$234,0)) | I12: =INDEX(Lots_Data!$C$2:$C$234,MATCH($A12,Lots_Data!$A$2:$A$234,0))
A13: HOSP-1|SS-01033 | B13: =INDEX(Lots_Data!$E$2:$E$234,MATCH($A13,Lots_Data!$A$2:$A$234,0)) | C13: =INDEX(Lots_Data!$A$2:$A$234,MATCH($A13,Lots_Data!$A$2:$A$234,0)) | D13: A | E13: =INDEX(Usage_Summary!$B$4:$B$236,MATCH($C13,Usage_Summary!$A$4:$A$236,0))*INDEX(Lots_Data!$G$2:$G$234,MATCH($A13,Lots_Data!$A$2:$A$234,0)) | F13: =INDEX(Lots_Data!$G$2:$G$234,MATCH($A13,Lots_Data!$A$2:$A$234,0)) | G13: =INDEX(Usage_Summary!$B$4:$B$236,MATCH($C13,Usage_Summary!$A$4:$A$236,0)) | H13: =INDEX(Lots_Data!$D$2:$D$234,MATCH($A13,Lots_Data!$A$2:$A$234,0)) | I13: =INDEX(Lots_Data!$C$2:$C$234,MATCH($A13,Lots_Data!$A$2:$A$234,0))
A14: HOSP-1|SS-01037 | B14: =INDEX(Lots_Data!$E$2:$E$234,MATCH($A14,Lots_Data!$A$2:$A$234,0)) | C14: =INDEX(Lots_Data!$A$2:$A$234,MATCH($A14,Lots_Data!$A$2:$A$234,0)) | D14: A | E14: =INDEX(Usage_Summary!$B$4:$B$236,MATCH($C14,Usage_Summary!$A$4:$A$236,0))*INDEX(Lots_Data!$G$2:$G$234,MATCH($A14,Lots_Data!$A$2:$A$234,0)) | F14: =INDEX(Lots_Data!$G$2:$G$234,MATCH($A14,Lots_Data!$A$2:$A$234,0)) | G14: =INDEX(Usage_Summary!$B$4:$B$236,MATCH($C14,Usage_Summary!$A$4:$A$236,0)) | H14: =INDEX(Lots_Data!$D$2:$D$234,MATCH($A14,Lots_Data!$A$2:$A$234,0)) | I14: =INDEX(Lots_Data!$C$2:$C$234,MATCH($A14,Lots_Data!$A$2:$A$234,0))
A15: HOSP-1|SS-01041 | B15: =INDEX(Lots_Data!$E$2:$E$234,MATCH($A15,Lots_Data!$A$2:$A$234,0)) | C15: =INDEX(Lots_Data!$A$2:$A$234,MATCH($A15,Lots_Data!$A$2:$A$234,0)) | D15: A | E15: =INDEX(Usage_Summary!$B$4:$B$236,MATCH($C15,Usage_Summary!$A$4:$A$236,0))*INDEX(Lots_Data!$G$2:$G$234,MATCH($A15,Lots_Data!$A$2:$A$234,0)) | F15: =INDEX(Lots_Data!$G$2:$G$234,MATCH($A15,Lots_Data!$A$2:$A$234,0)) | G15: =INDEX(Usage_Summary!$B$4:$B$236,MATCH($C15,Usage_Summary!$A$4:$A$236,0)) | H15: =INDEX(Lots_Data!$D$2:$D$234,MATCH($A15,Lots_Data!$A$2:$A$234,0)) | I15: =INDEX(Lots_Data!$C$2:$C$234,MATCH($A15,Lots_Data!$A$2:$A$234,0))
A16: HOSP-1|SS-01045 | B16: =INDEX(Lots_Data!$E$2:$E$234,MATCH($A16,Lots_Data!$A$2:$A$234,0)) | C16: =INDEX(Lots_Data!$A$2:$A$234,MATCH($A16,Lots_Data!$A$2:$A$234,0)) | D16: A | E16: =INDEX(Usage_Summary!$B$4:$B$236,MATCH($C16,Usage_Summary!$A$4:$A$236,0))*INDEX(Lots_Data!$G$2:$G$234,MATCH($A16,Lots_Data!$A$2:$A$234,0)) | F16: =INDEX(Lots_Data!$G$2:$G$234,MATCH($A16,Lots_Data!$A$2:$A$234,0)) | G16: =INDEX(Usage_Summary!$B$4:$B$236,MATCH($C16,Usage_Summary!$A$4:$A$236,0)) | H16: =INDEX(Lots_Data!$D$2:$D$234,MATCH($A16,Lots_Data!$A$2:$A$234,0)) | I16: =INDEX(Lots_Data!$C$2:$C$234,MATCH($A16,Lots_Data!$A$2:$A$234,0))
... A237: HOSP-4|SS-01232 | B237: =INDEX(Lots_Data!$E$2:$E$234,MATCH($A237,Lots_Data!$A$2:$A$234,0)) | C237: =INDEX(Lots_Data!$A$2:$A$234,MATCH($A237,Lots_Data!$A$2:$A$234,0)) | D237: A | E237: =INDEX(Usage_Summary!$B$4:$B$236,MATCH($C237,Usage_Summary!$A$4:$A$236,0))*INDEX(Lots_Data!$G$2:$G$234,MATCH($A237,Lots_Data!$A$2:$A$234,0)) | F237: =INDEX(Lots_Data!$G$2:$G$234,MATCH($A237,Lots_Data!$A$2:$A$234,0)) | G237: =INDEX(Usage_Summary!$B$4:$B$236,MATCH($C237,Usage_Summary!$A$4:$A$236,0)) | H237: =INDEX(Lots_Data!$D$2:$D$234,MATCH($A237,Lots_Data!$A$2:$A$234,0)) | I237: =INDEX(Lots_Data!$C$2:$C$234,MATCH($A237,Lots_Data!$A$2:$A$234,0))
A239: Class counts (exact)
A240: class | B240: sku_count | C240: value_share_pct
A241: A | B241: =COUNTIF($D$5:$D$237,$A241) | C241: =SUMIF($D$5:$D$237,$A241,$E$5:$E$237)/SUM($E$5:$E$237)*100
A242: B | B242: =COUNTIF($D$5:$D$237,$A242) | C242: =SUMIF($D$5:$D$237,$A242,$E$5:$E$237)/SUM($E$5:$E$237)*100
A243: C | B243: =COUNTIF($D$5:$D$237,$A243) | C243: =SUMIF($D$5:$D$237,$A243,$E$5:$E$237)/SUM($E$5:$E$237)*100
A246: Supplier concentration by class (exact counts and shares)
A247: abc_class | B247: supplier | C247: sku_count | D247: value_usd | E247: value_share_in_class_pct
A248: A | B248: Aegis Clinical Supply | C248: =COUNTIFS($D$5:$D$237,$A248,$H$5:$H$237,$B248) | D248: =SUMIFS($E$5:$E$237,$D$5:$D$237,$A248,$H$5:$H$237,$B248) | E248: =IF(SUMIFS($E$5:$E$237,$D$5:$D$237,$A248)=0,0,$D248/SUMIFS($E$5:$E$237,$D$5:$D$237,$A248)*100)
A249: A | B249: HarborMed Logistics | C249: =COUNTIFS($D$5:$D$237,$A249,$H$5:$H$237,$B249) | D249: =SUMIFS($E$5:$E$237,$D$5:$D$237,$A249,$H$5:$H$237,$B249) | E249: =IF(SUMIFS($E$5:$E$237,$D$5:$D$237,$A249)=0,0,$D249/SUMIFS($E$5:$E$237,$D$5:$D$237,$A249)*100)
A250: A | B250: MedAxis Distribution | C250: =COUNTIFS($D$5:$D$237,$A250,$H$5:$H$237,$B250) | D250: =SUMIFS($E$5:$E$237,$D$5:$D$237,$A250,$H$5:$H$237,$B250) | E250: =IF(SUMIFS($E$5:$E$237,$D$5:$D$237,$A250)=0,0,$D250/SUMIFS($E$5:$E$237,$D$5:$D$237,$A250)*100)
A251: A | B251: Northstar Surgical | C251: =COUNTIFS($D$5:$D$237,$A251,$H$5:$H$237,$B251) | D251: =SUMIFS($E$5:$E$237,$D$5:$D$237,$A251,$H$5:$H$237,$B251) | E251: =IF(SUMIFS($E$5:$E$237,$D$5:$D$237,$A251)=0,0,$D251/SUMIFS($E$5:$E$237,$D$5:$D$237,$A251)*100)
A252: A | B252: SterilePath Medical | C252: =COUNTIFS($D$5:$D$237,$A252,$H$5:$H$237,$B252) | D252: =SUMIFS($E$5:$E$237,$D$5:$D$237,$A252,$H$5:$H$237,$B252) | E252: =IF(SUMIFS($E$5:$E$237,$D$5:$D$237,$A252)=0,0,$D252/SUMIFS($E$5:$E$237,$D$5:$D$237,$A252)*100)
A253: B | B253: Aegis Clinical Supply | C253: =COUNTIFS($D$5:$D$237,$A253,$H$5:$H$237,$B253) | D253: =SUMIFS($E$5:$E$237,$D$5:$D$237,$A253,$H$5:$H$237,$B253) | E253: =IF(SUMIFS($E$5:$E$237,$D$5:$D$237,$A253)=0,0,$D253/SUMIFS($E$5:$E$237,$D$5:$D$237,$A253)*100)
A254: B | B254: HarborMed Logistics | C254: =COUNTIFS($D$5:$D$237,$A254,$H$5:$H$237,$B254) | D254: =SUMIFS($E$5:$E$237,$D$5:$D$237,$A254,$H$5:$H$237,$B254) | E254: =IF(SUMIFS($E$5:$E$237,$D$5:$D$237,$A254)=0,0,$D254/SUMIFS($E$5:$E$237,$D$5:$D$237,$A254)*100)
A255: B | B255: MedAxis Distribution | C255: =COUNTIFS($D$5:$D$237,$A255,$H$5:$H$237,$B255) | D255: =SUMIFS($E$5:$E$237,$D$5:$D$237,$A255,$H$5:$H$237,$B255) | E255: =IF(SUMIFS($E$5:$E$237,$D$5:$D$237,$A255)=0,0,$D255/SUMIFS($E$5:$E$237,$D$5:$D$237,$A255)*100)
A256: B | B256: Northstar Surgical | C256: =COUNTIFS($D$5:$D$237,$A256,$H$5:$H$237,$B256) | D256: =SUMIFS($E$5:$E$237,$D$5:$D$237,$A256,$H$5:$H$237,$B256) | E256: =IF(SUMIFS($E$5:$E$237,$D$5:$D$237,$A256)=0,0,$D256/SUMIFS($E$5:$E$237,$D$5:$D$237,$A256)*100)
A257: B | B257: SterilePath Medical | C257: =COUNTIFS($D$5:$D$237,$A257,$H$5:$H$237,$B257) | D257: =SUMIFS($E$5:$E$237,$D$5:$D$237,$A257,$H$5:$H$237,$B257) | E257: =IF(SUMIFS($E$5:$E$237,$D$5:$D$237,$A257)=0,0,$D257/SUMIFS($E$5:$E$237,$D$5:$D$237,$A257)*100)
A258: C | B258: Aegis Clinical Supply | C258: =COUNTIFS($D$5:$D$237,$A258,$H$5:$H$237,$B258) | D258: =SUMIFS($E$5:$E$237,$D$5:$D$237,$A258,$H$5:$H$237,$B258) | E258: =IF(SUMIFS($E$5:$E$237,$D$5:$D$237,$A258)=0,0,$D258/SUMIFS($E$5:$E$237,$D$5:$D$237,$A258)*100)
A259: C | B259: HarborMed Logistics | C259: =COUNTIFS($D$5:$D$237,$A259,$H$5:$H$237,$B259) | D259: =SUMIFS($E$5:$E$237,$D$5:$D$237,$A259,$H$5:$H$237,$B259) | E259: =IF(SUMIFS($E$5:$E$237,$D$5:$D$237,$A259)=0,0,$D259/SUMIFS($E$5:$E$237,$D$5:$D$237,$A259)*100)
... A262: C | B262: SterilePath Medical | C262: =COUNTIFS($D$5:$D$237,$A262,$H$5:$H$237,$B262) | D262: =SUMIFS($E$5:$E$237,$D$5:$D$237,$A262,$H$5:$H$237,$B262) | E262: =IF(SUMIFS($E$5:$E$237,$D$5:$D$237,$A262)=0,0,$D262/SUMIFS($E$5:$E$237,$D$5:$D$237,$A262)*100)

Sheet Volatility_Reorder
A1: Demand volatility (CV) and dynamic reorder point / safety stock
A2: CV = STDEV.P(monthly usage)/AVERAGE(monthly usage) over complete periods; deterministic sparse-demand treatment: SKUs with mean=0 get CV=0 (no demand -> no variability). Dynamic ROP = (mean/30)*lead_time + z*STDEV.P/30*SQRT(lead_time); safety stock = z*sd_daily*SQRT(LT). z=1.65 (95% service level, disclosed assumption, editable in Inputs).
A4: sku_id | B4: mean_monthly_usage | C4: std_monthly_usage | D4: cv | E4: lead_time_days | F4: safety_stock | G4: dynamic_rop | H4: submitted_static_rop
A5: SS-01001 | B5: =AVERAGEIFS(Usage_Data!$D$2:$D$5001,Usage_Data!$C$2:$C$5001,$A5) | C5: =SQRT(SUMPRODUCT((Usage_Data!$C$2:$C$5001=$A5)*(Usage_Data!$D$2:$D$5001-$B5)^2)/MAX(1,COUNTIF(Usage_Data!$C$2:$C$5001,$A5)))) | D5: =IF($B5=0,0,$C5/$B5) | E5: =INDEX(Lots_Data!$N$2:$N$234,MATCH($A5,Lots_Data!$A$2:$A$234,0)) | F5: =1.65*($C5/30)*SQRT($E5) | G5: =($B5/30)*$E5+$F5 | H5: =INDEX(Lots_Data!$S$2:$S$234,MATCH($A5,Lots_Data!$A$2:$A$234,0))
A6: SS-01002 | B6: =AVERAGEIFS(Usage_Data!$D$2:$D$5001,Usage_Data!$C$2:$C$5001,$A6) | C6: =SQRT(SUMPRODUCT((Usage_Data!$C$2:$C$5001=$A6)*(Usage_Data!$D$2:$D$5001-$B6)^2)/MAX(1,COUNTIF(Usage_Data!$C$2:$C$5001,$A6)))) | D6: =IF($B6=0,0,$C6/$B6) | E6: =INDEX(Lots_Data!$N$2:$N$234,MATCH($A6,Lots_Data!$A$2:$A$234,0)) | F6: =1.65*($C6/30)*SQRT($E6) | G6: =($B6/30)*$E6+$F6 | H6: =INDEX(Lots_Data!$S$2:$S$234,MATCH($A6,Lots_Data!$A$2:$A$234,0))
A7: SS-01003 | B7: =AVERAGEIFS(Usage_Data!$D$2:$D$5001,Usage_Data!$C$2:$C$5001,$A7) | C7: =SQRT(SUMPRODUCT((Usage_Data!$C$2:$C$5001=$A7)*(Usage_Data!$D$2:$D$5001-$B7)^2)/MAX(1,COUNTIF(Usage_Data!$C$2:$C$5001,$A7)))) | D7: =IF($B7=0,0,$C7/$B7) | E7: =INDEX(Lots_Data!$N$2:$N$234,MATCH($A7,Lots_Data!$A$2:$A$234,0)) | F7: =1.65*($C7/30)*SQRT($E7) | G7: =($B7/30)*$E7+$F7 | H7: =INDEX(Lots_Data!$S$2:$S$234,MATCH($A7,Lots_Data!$A$2:$A$234,0))
A8: SS-01004 | B8: =AVERAGEIFS(Usage_Data!$D$2:$D$5001,Usage_Data!$C$2:$C$5001,$A8) | C8: =SQRT(SUMPRODUCT((Usage_Data!$C$2:$C$5001=$A8)*(Usage_Data!$D$2:$D$5001-$B8)^2)/MAX(1,COUNTIF(Usage_Data!$C$2:$C$5001,$A8)))) | D8: =IF($B8=0,0,$C8/$B8) | E8: =INDEX(Lots_Data!$N$2:$N$234,MATCH($A8,Lots_Data!$A$2:$A$234,0)) | F8: =1.65*($C8/30)*SQRT($E8) | G8: =($B8/30)*$E8+$F8 | H8: =INDEX(Lots_Data!$S$2:$S$234,MATCH($A8,Lots_Data!$A$2:$A$234,0))
A9: SS-01005 | B9: =AVERAGEIFS(Usage_Data!$D$2:$D$5001,Usage_Data!$C$2:$C$5001,$A9) | C9: =SQRT(SUMPRODUCT((Usage_Data!$C$2:$C$5001=$A9)*(Usage_Data!$D$2:$D$5001-$B9)^2)/MAX(1,COUNTIF(Usage_Data!$C$2:$C$5001,$A9)))) | D9: =IF($B9=0,0,$C9/$B9) | E9: =INDEX(Lots_Data!$N$2:$N$234,MATCH($A9,Lots_Data!$A$2:$A$234,0)) | F9: =1.65*($C9/30)*SQRT($E9) | G9: =($B9/30)*$E9+$F9 | H9: =INDEX(Lots_Data!$S$2:$S$234,MATCH($A9,Lots_Data!$A$2:$A$234,0))
A10: SS-01006 | B10: =AVERAGEIFS(Usage_Data!$D$2:$D$5001,Usage_Data!$C$2:$C$5001,$A10) | C10: =SQRT(SUMPRODUCT((Usage_Data!$C$2:$C$5001=$A10)*(Usage_Data!$D$2:$D$5001-$B10)^2)/MAX(1,COUNTIF(Usage_Data!$C$2:$C$5001,$A10)))) | D10: =IF($B10=0,0,$C10/$B10) | E10: =INDEX(Lots_Data!$N$2:$N$234,MATCH($A10,Lots_Data!$A$2:$A$234,0)) | F10: =1.65*($C10/30)*SQRT($E10) | G10: =($B10/30)*$E10+$F10 | H10: =INDEX(Lots_Data!$S$2:$S$234,MATCH($A10,Lots_Data!$A$2:$A$234,0))
A11: SS-01007 | B11: =AVERAGEIFS(Usage_Data!$D$2:$D$5001,Usage_Data!$C$2:$C$5001,$A11) | C11: =SQRT(SUMPRODUCT((Usage_Data!$C$2:$C$5001=$A11)*(Usage_Data!$D$2:$D$5001-$B11)^2)/MAX(1,COUNTIF(Usage_Data!$C$2:$C$5001,$A11)))) | D11: =IF($B11=0,0,$C11/$B11) | E11: =INDEX(Lots_Data!$N$2:$N$234,MATCH($A11,Lots_Data!$A$2:$A$234,0)) | F11: =1.65*($C11/30)*SQRT($E11) | G11: =($B11/30)*$E11+$F11 | H11: =INDEX(Lots_Data!$S$2:$S$234,MATCH($A11,Lots_Data!$A$2:$A$234,0))
A12: SS-01008 | B12: =AVERAGEIFS(Usage_Data!$D$2:$D$5001,Usage_Data!$C$2:$C$5001,$A12) | C12: =SQRT(SUMPRODUCT((Usage_Data!$C$2:$C$5001=$A12)*(Usage_Data!$D$2:$D$5001-$B12)^2)/MAX(1,COUNTIF(Usage_Data!$C$2:$C$5001,$A12)))) | D12: =IF($B12=0,0,$C12/$B12) | E12: =INDEX(Lots_Data!$N$2:$N$234,MATCH($A12,Lots_Data!$A$2:$A$234,0)) | F12: =1.65*($C12/30)*SQRT($E12) | G12: =($B12/30)*$E12+$F12 | H12: =INDEX(Lots_Data!$S$2:$S$234,MATCH($A12,Lots_Data!$A$2:$A$234,0))
A13: SS-01009 | B13: =AVERAGEIFS(Usage_Data!$D$2:$D$5001,Usage_Data!$C$2:$C$5001,$A13) | C13: =SQRT(SUMPRODUCT((Usage_Data!$C$2:$C$5001=$A13)*(Usage_Data!$D$2:$D$5001-$B13)^2)/MAX(1,COUNTIF(Usage_Data!$C$2:$C$5001,$A13)))) | D13: =IF($B13=0,0,$C13/$B13) | E13: =INDEX(Lots_Data!$N$2:$N$234,MATCH($A13,Lots_Data!$A$2:$A$234,0)) | F13: =1.65*($C13/30)*SQRT($E13) | G13: =($B13/30)*$E13+$F13 | H13: =INDEX(Lots_Data!$S$2:$S$234,MATCH($A13,Lots_Data!$A$2:$A$234,0))
A14: SS-01010 | B14: =AVERAGEIFS(Usage_Data!$D$2:$D$5001,Usage_Data!$C$2:$C$5001,$A14) | C14: =SQRT(SUMPRODUCT((Usage_Data!$C$2:$C$5001=$A14)*(Usage_Data!$D$2:$D$5001-$B14)^2)/MAX(1,COUNTIF(Usage_Data!$C$2:$C$5001,$A14)))) | D14: =IF($B14=0,0,$C14/$B14) | E14: =INDEX(Lots_Data!$N$2:$N$234,MATCH($A14,Lots_Data!$A$2:$A$234,0)) | F14: =1.65*($C14/30)*SQRT($E14) | G14: =($B14/30)*$E14+$F14 | H14: =INDEX(Lots_Data!$S$2:$S$234,MATCH($A14,Lots_Data!$A$2:$A$234,0))
A15: SS-01011 | B15: =AVERAGEIFS(Usage_Data!$D$2:$D$5001,Usage_Data!$C$2:$C$5001,$A15) | C15: =SQRT(SUMPRODUCT((Usage_Data!$C$2:$C$5001=$A15)*(Usage_Data!$D$2:$D$5001-$B15)^2)/MAX(1,COUNTIF(Usage_Data!$C$2:$C$5001,$A15)))) | D15: =IF($B15=0,0,$C15/$B15) | E15: =INDEX(Lots_Data!$N$2:$N$234,MATCH($A15,Lots_Data!$A$2:$A$234,0)) | F15: =1.65*($C15/30)*SQRT($E15) | G15: =($B15/30)*$E15+$F15 | H15: =INDEX(Lots_Data!$S$2:$S$234,MATCH($A15,Lots_Data!$A$2:$A$234,0))
A16: SS-01012 | B16: =AVERAGEIFS(Usage_Data!$D$2:$D$5001,Usage_Data!$C$2:$C$5001,$A16) | C16: =SQRT(SUMPRODUCT((Usage_Data!$C$2:$C$5001=$A16)*(Usage_Data!$D$2:$D$5001-$B16)^2)/MAX(1,COUNTIF(Usage_Data!$C$2:$C$5001,$A16)))) | D16: =IF($B16=0,0,$C16/$B16) | E16: =INDEX(Lots_Data!$N$2:$N$234,MATCH($A16,Lots_Data!$A$2:$A$234,0)) | F16: =1.65*($C16/30)*SQRT($E16) | G16: =($B16/30)*$E16+$F16 | H16: =INDEX(Lots_Data!$S$2:$S$234,MATCH($A16,Lots_Data!$A$2:$A$234,0))
... A237: SS-01233 | B237: =AVERAGEIFS(Usage_Data!$D$2:$D$5001,Usage_Data!$C$2:$C$5001,$A237) | C237: =SQRT(SUMPRODUCT((Usage_Data!$C$2:$C$5001=$A237)*(Usage_Data!$D$2:$D$5001-$B237)^2)/MAX(1,COUNTIF(Usage_Data!$C$2:$C$5001,$A237)))) | D237: =IF($B237=0,0,$C237/$B237) | E237: =INDEX(Lots_Data!$N$2:$N$234,MATCH($A237,Lots_Data!$A$2:$A$234,0)) | F237: =1.65*($C237/30)*SQRT($E237) | G237: =($B237/30)*$E237+$F237 | H237: =INDEX(Lots_Data!$S$2:$S$234,MATCH($A237,Lots_Data!$A$2:$A$234,0))
A239: Network CV / dynamic reorder summary
A240: SKUs with demand | B240: 233
A241: Mean CV | B241: 1.047
A242: Median CV | B242: 1.011
A243: Min / Max CV | B243: 0.261 / 2.051
A244: % SKUs with CV>1 (volatile / intermittent) | B244: 50.6%
A245: Total safety stock (units) | B245: 1183
A246: Total dynamic ROP (units) | B246: 2834.6
A247: Service level z | B247: 1.65

Sheet Sensitivity
A1: Leave-one-out sensitivity: decision change when each supplier / site capacity is removed
A2: For each supplier (and each site) removed individually, recompute ABC classes on the remaining annual-usage-value set (80/95 split) and report the change in A-class SKU count (dA) and the remaining value share. dA<0 means the removed node was load-bearing for A-class coverage. annual_usage_value_total reconciles to 879602.39.
A4: Baseline class counts (all nodes present)
A5: A | B5: B | C5: C | D5: Total
A6: 106 | B6: 65 | C6: 62 | D6: =SUM(A6:C6)
A8: SUPPLIER REMOVAL SENSITIVITY
A9: supplier | B9: removed_value_usd | C9: removed_pct | D9: remaining_value_pct | E9: dA_vs_baseline
A10: Aegis Clinical Supply | B10: =SUMIFS(ABC_Classification!$E$4:$E$236,ABC_Classification!$H$4:$H$236,$A10) | C10: =IF(SUM(ABC_Classification!$E$4:$E$236)=0,0,$B10/SUM(ABC_Classification!$E$4:$E$236)*100) | D10: =100-$C10
A11: HarborMed Logistics | B11: =SUMIFS(ABC_Classification!$E$4:$E$236,ABC_Classification!$H$4:$H$236,$A11) | C11: =IF(SUM(ABC_Classification!$E$4:$E$236)=0,0,$B11/SUM(ABC_Classification!$E$4:$E$236)*100) | D11: =100-$C11
A12: MedAxis Distribution | B12: =SUMIFS(ABC_Classification!$E$4:$E$236,ABC_Classification!$H$4:$H$236,$A12) | C12: =IF(SUM(ABC_Classification!$E$4:$E$236)=0,0,$B12/SUM(ABC_Classification!$E$4:$E$236)*100) | D12: =100-$C12
A13: Northstar Surgical | B13: =SUMIFS(ABC_Classification!$E$4:$E$236,ABC_Classification!$H$4:$H$236,$A13) | C13: =IF(SUM(ABC_Classification!$E$4:$E$236)=0,0,$B13/SUM(ABC_Classification!$E$4:$E$236)*100) | D13: =100-$C13
A14: SterilePath Medical | B14: =SUMIFS(ABC_Classification!$E$4:$E$236,ABC_Classification!$H$4:$H$236,$A14) | C14: =IF(SUM(ABC_Classification!$E$4:$E$236)=0,0,$B14/SUM(ABC_Classification!$E$4:$E$236)*100) | D14: =100-$C14
A16: dA = change in A-class SKU count vs baseline after removing the node and recomputing the 80/95 ABC split on remaining value (see portal Sensitivity tab for exact per-node dA).
A18: SITE REMOVAL SENSITIVITY
A19: supplier | B19: removed_value_usd | C19: removed_pct | D19: remaining_value_pct | E19: dA_vs_baseline
A20: HOSP-1 | B20: =SUMIFS(ABC_Classification!$E$4:$E$236,ABC_Classification!$B$4:$B$236,$A20) | C20: =IF(SUM(ABC_Classification!$E$4:$E$236)=0,0,$B20/SUM(ABC_Classification!$E$4:$E$236)*100) | D20: =100-$C20
A21: HOSP-2 | B21: =SUMIFS(ABC_Classification!$E$4:$E$236,ABC_Classification!$B$4:$B$236,$A21) | C21: =IF(SUM(ABC_Classification!$E$4:$E$236)=0,0,$B21/SUM(ABC_Classification!$E$4:$E$236)*100) | D21: =100-$C21
A22: HOSP-3 | B22: =SUMIFS(ABC_Classification!$E$4:$E$236,ABC_Classification!$B$4:$B$236,$A22) | C22: =IF(SUM(ABC_Classification!$E$4:$E$236)=0,0,$B22/SUM(ABC_Classification!$E$4:$E$236)*100) | D22: =100-$C22
A23: HOSP-4 | B23: =SUMIFS(ABC_Classification!$E$4:$E$236,ABC_Classification!$B$4:$B$236,$A23) | C23: =IF(SUM(ABC_Classification!$E$4:$E$236)=0,0,$B23/SUM(ABC_Classification!$E$4:$E$236)*100) | D23: =100-$C23

Sheet Supplier_Info
A1: supplier_id | B1: supplier_name | C1: contact_name | D1: contact_email | E1: payment_terms | F1: contract_start_date | G1: contract_end_date | H1: minimum_order_value
A2: 1 | B2: Northstar Surgical | C2: Clinical Supply Contact 1 | D2: contracts1@northsound-health.example | E2: Net 30 | F2: 2025-01-15 | G2: 2027-01-14 | H2: 2000
A3: 2 | B3: MedAxis Distribution | C3: Clinical Supply Contact 2 | D3: contracts2@northsound-health.example | E3: 2/10 Net 30 | F3: 2025-03-01 | G3: 2027-02-28 | H3: 1500
A4: 3 | B4: SterilePath Medical | C4: Clinical Supply Contact 3 | D4: contracts3@northsound-health.example | E4: Net 45 | F4: 2024-07-01 | G4: 2027-06-30 | H4: 3000
A5: 4 | B5: Aegis Clinical Supply | C5: Clinical Supply Contact 4 | D5: contracts4@northsound-health.example | E5: Net 30 | F5: 2025-06-01 | G5: 2027-05-31 | H5: 1000
A6: 5 | B6: HarborMed Logistics | C6: Clinical Supply Contact 5 | D6: contracts5@northsound-health.example | E6: 2/10 Net 30 | F6: 2025-02-01 | G6: 2028-01-31 | H6: 2500

Sheet PO_Data
A1: po_id | B1: po_number | C1: supplier_id | D1: order_date | E1: requested_delivery_date | F1: actual_delivery_date | G1: total_amount | H1: status | I1: items_ordered | J1: items_received | K1: discrepancy_notes
A2: 1 | B2: PO-2020-0001 | C2: 1 | D2: 2020-11-23 | E2: 2020-11-30 | F2: 2020-11-30 | G2: 18938.84 | H2: Partially Delivered | I2: 44 | J2: 37 | K2: 2 cases arrived damaged during transit
A3: 2 | B3: PO-2020-0002 | C3: 1 | D3: 2020-01-16 | E3: 2020-01-23 | F3: 2020-01-23 | G3: 13623.17 | H3: Delivered | I3: 11 | J3: 11
A4: 3 | B4: PO-2020-0003 | C4: 1 | D4: 2020-12-25 | E4: 2020-12-28 | F4: 2020-12-28 | G4: 19452.57 | H4: Delivered | I4: 20 | J4: 20
A5: 4 | B5: PO-2020-0004 | C5: 1 | D5: 2020-03-20 | E5: 2020-03-24 | F5: 2020-03-24 | G5: 4350.84 | H5: Partially Delivered | I5: 34 | J5: 28 | K5: Partial fulfillment due to production delay
A6: 5 | B6: PO-2020-0005 | C6: 1 | D6: 2020-05-15 | E6: 2020-05-21 | F6: 2020-05-20 | G6: 3812.4 | H6: Delivered | I6: 28 | J6: 28
A7: 6 | B7: PO-2020-0006 | C7: 1 | D7: 2020-07-04 | E7: 2020-07-06 | F7: 2020-07-06 | G7: 3053.96 | H7: Delivered | I7: 24 | J7: 24
A8: 7 | B8: PO-2020-0007 | C8: 1 | D8: 2020-04-29 | E8: 2020-05-05 | F8: 2020-05-05 | G8: 5741.04 | H8: Delivered | I8: 32 | J8: 32
A9: 8 | B9: PO-2020-0008 | C9: 1 | D9: 2020-12-15 | E9: 2020-12-18 | F9: 2020-12-18 | G9: 14285.22 | H9: Delivered | I9: 25 | J9: 25
A10: 9 | B10: PO-2020-0009 | C10: 1 | D10: 2020-11-23 | E10: 2020-11-27 | F10: 2020-11-27 | G10: 7268.11 | H10: Delivered | I10: 12 | J10: 12
A11: 10 | B11: PO-2020-0010 | C11: 1 | D11: 2020-02-03 | E11: 2020-02-06 | F11: 2020-02-06 | G11: 6890.41 | H11: Delivered | I11: 41 | J11: 41
A12: 11 | B12: PO-2020-0011 | C12: 1 | D12: 2020-08-22 | E12: 2020-08-27 | F12: 2020-08-27 | G12: 19181.32 | H12: Delivered | I12: 37 | J12: 37
A13: 12 | B13: PO-2020-0012 | C13: 1 | D13: 2020-04-22 | E13: 2020-04-27 | F13: 2020-04-30 | G13: 13719.1 | H13: Delivered | I13: 15 | J13: 15
A14: 13 | B14: PO-2020-0013 | C14: 1 | D14: 2020-03-19 | E14: 2020-03-21 | F14: 2020-03-21 | G14: 10849.65 | H14: Delivered | I14: 48 | J14: 48
A15: 14 | B15: PO-2020-0014 | C15: 1 | D15: 2020-10-10 | E15: 2020-10-12 | F15: 2020-10-13 | G15: 17646.52 | H15: Delivered | I15: 17 | J15: 17
A16: 15 | B16: PO-2020-0015 | C16: 1 | D16: 2020-05-16 | E16: 2020-05-21 | F16: 2020-05-21 | G16: 12435.65 | H16: Delivered | I16: 26 | J16: 26
A17: 16 | B17: PO-2020-0016 | C17: 1 | D17: 2020-09-16 | E17: 2020-09-19 | F17: 2020-09-24 | G17: 21358.4 | H17: Delivered | I17: 42 | J17: 42
A18: 17 | B18: PO-2020-0017 | C18: 1 | D18: 2020-03-23 | E18: 2020-03-25 | G18: 15775.73 | H18: Cancelled | I18: 41 | J18: 0 | K18: Order cancelled by supplier due to stock-out
A19: 18 | B19: PO-2020-0018 | C19: 1 | D19: 2020-07-04 | E19: 2020-07-08 | F19: 2020-07-13 | G19: 7507.4 | H19: Delivered | I19: 25 | J19: 25
A20: 19 | B20: PO-2020-0019 | C20: 1 | D20: 2020-02-13 | E20: 2020-02-17 | F20: 2020-02-20 | G20: 4953 | H20: Delivered | I20: 40 | J20: 40
A21: 20 | B21: PO-2020-0020 | C21: 1 | D21: 2020-09-27 | E21: 2020-09-29 | F21: 2020-10-06 | G21: 24180.35 | H21: Delivered | I21: 44 | J21: 44
A22: 21 | B22: PO-2020-0021 | C22: 1 | D22: 2020-12-31 | E22: 2021-01-02 | F22: 2021-01-01 | G22: 22691.12 | H22: Partially Delivered | I22: 38 | J22: 34 | K22: Short-shipped: supplier back-ordered 3 SKUs
A23: 22 | B23: PO-2020-0022 | C23: 1 | D23: 2020-06-22 | E23: 2020-07-03 | F23: 2020-07-03 | G23: 15534.12 | H23: Partially Delivered | I23: 10 | J23: 9 | K23: Temperature excursion noted on 4 cases
A24: 23 | B24: PO-2020-0023 | C24: 1 | D24: 2020-02-04 | E24: 2020-02-12 | F24: 2020-02-12 | G24: 8404.98 | H24: Delivered | I24: 41 | J24: 41
A25: 24 | B25: PO-2020-0024 | C25: 1 | D25: 2020-10-19 | E25: 2020-10-21 | F25: 2020-10-21 | G25: 20046.25 | H25: Delivered | I25: 36 | J25: 36
A26: 25 | B26: PO-2020-0025 | C26: 1 | D26: 2020-08-08 | E26: 2020-08-11 | F26: 2020-08-12 | G26: 17487.38 | H26: Partially Delivered | I26: 16 | J26: 13 | K26: Short-shipped: supplier back-ordered 3 SKUs
A27: 26 | B27: PO-2020-0026 | C27: 1 | D27: 2020-05-07 | E27: 2020-05-13 | F27: 2020-05-12 | G27: 5224.19 | H27: Delivered | I27: 21 | J27: 21
A28: 27 | B28: PO-2020-0027 | C28: 1 | D28: 2020-02-08 | E28: 2020-02-10 | F28: 2020-02-10 | G28: 16999.33 | H28: Delivered | I28: 44 | J28: 44
A29: 28 | B29: PO-2020-0028 | C29: 1 | D29: 2020-05-01 | E29: 2020-05-07 | F29: 2020-05-06 | G29: 13071.24 | H29: Delivered | I29: 35 | J29: 35
A30: 29 | B30: PO-2020-0029 | C30: 1 | D30: 2020-01-02 | E30: 2020-01-08 | F30: 2020-01-07 | G30: 8560.73 | H30: Delivered | I30: 45 | J30: 45
A31: 30 | B31: PO-2020-0030 | C31: 1 | D31: 2020-04-07 | E31: 2020-04-11 | F31: 2020-04-11 | G31: 15321.15 | H31: Partially Delivered | I31: 44 | J31: 38 | K31: 2 cases arrived damaged during transit
A32: 31 | B32: PO-2020-0031 | C32: 2 | D32: 2020-01-26 | E32: 2020-01-29 | F32: 2020-02-01 | G32: 1796.31 | H32: Partially Delivered | I32: 21 | J32: 19 | K32: Short-shipped: supplier back-ordered 3 SKUs
A33: 32 | B33: PO-2020-0032 | C33: 2 | D33: 2020-10-31 | E33: 2020-11-05 | F33: 2020-11-05 | G33: 6652.86 | H33: Delivered | I33: 35 | J33: 35
A34: 33 | B34: PO-2020-0033 | C34: 2 | D34: 2020-10-31 | E34: 2020-11-08 | F34: 2020-11-08 | G34: 14085.89 | H34: Delivered | I34: 11 | J34: 11
A35: 34 | B35: PO-2020-0034 | C35: 2 | D35: 2020-05-15 | E35: 2020-05-22 | F35: 2020-05-22 | G35: 7401.14 | H35: Delivered | I35: 34 | J35: 34 | K35: Temperature excursion noted on 4 cases
A36: 35 | B36: PO-2020-0035 | C36: 2 | D36: 2020-11-14 | E36: 2020-11-30 | F36: 2020-11-30 | G36: 8082.39 | H36: Delivered | I36: 9 | J36: 9
A37: 36 | B37: PO-2020-0036 | C37: 2 | D37: 2020-05-05 | E37: 2020-05-11 | F37: 2020-05-11 | G37: 7134.58 | H37: Delivered | I37: 22 | J37: 22
A38: 37 | B38: PO-2020-0037 | C38: 2 | D38: 2020-11-30 | E38: 2020-12-02 | F38: 2020-12-02 | G38: 14145.02 | H38: Delivered | I38: 9 | J38: 9
A39: 38 | B39: PO-2020-0038 | C39: 2 | D39: 2020-10-10 | E39: 2020-10-16 | F39: 2020-10-16 | G39: 9467.62 | H39: Delivered | I39: 27 | J39: 27
A40: 39 | B40: PO-2020-0039 | C40: 2 | D40: 2020-05-15 | E40: 2020-05-19 | F40: 2020-05-20 | G40: 2292.18 | H40: Delivered | I40: 18 | J40: 18 | K40: Incorrect vintage delivered for 1 line item
...

Sheet Delivery_Data
A1: id | B1: supplier_id | C1: month | D1: year | E1: orders_placed | F1: orders_on_time | G1: orders_late | H1: orders_short_shipped | I1: total_spend | J1: avg_lead_time_days | K1: quality_issues
A2: 1 | B2: 1 | C2: 1 | D2: 2020 | E2: 2 | F2: 2 | G2: 0 | H2: 0 | I2: 22183.9 | J2: 6 | K2: 0
A3: 2 | B3: 1 | C3: 2 | D3: 2020 | E3: 4 | F3: 3 | G3: 1 | H3: 0 | I3: 37247.72 | J3: 5 | K3: 0
A4: 3 | B4: 1 | C4: 3 | D4: 2020 | E4: 3 | F4: 2 | G4: 0 | H4: 1 | I4: 30976.22 | J4: 3 | K4: 0
A5: 4 | B5: 1 | C5: 4 | D5: 2020 | E5: 3 | F5: 2 | G5: 1 | H5: 1 | I5: 34781.29 | J5: 6 | K5: 1
A6: 5 | B6: 1 | C6: 5 | D6: 2020 | E6: 4 | F6: 4 | G6: 0 | H6: 0 | I6: 34543.48 | J6: 5 | K6: 0
A7: 6 | B7: 1 | C7: 6 | D7: 2020 | E7: 1 | F7: 1 | G7: 0 | H7: 1 | I7: 15534.12 | J7: 11 | K7: 1
A8: 7 | B8: 1 | C8: 7 | D8: 2020 | E8: 2 | F8: 1 | G8: 1 | H8: 0 | I8: 10561.36 | J8: 5.5 | K8: 0
A9: 8 | B9: 1 | C9: 8 | D9: 2020 | E9: 2 | F9: 1 | G9: 1 | H9: 1 | I9: 36668.7 | J9: 4.5 | K9: 0
A10: 9 | B10: 1 | C10: 9 | D10: 2020 | E10: 2 | F10: 0 | G10: 2 | H10: 0 | I10: 45538.75 | J10: 8.5 | K10: 0
A11: 10 | B11: 1 | C11: 10 | D11: 2020 | E11: 2 | F11: 1 | G11: 1 | H11: 0 | I11: 37692.77 | J11: 2.5 | K11: 0
A12: 11 | B12: 1 | C12: 11 | D12: 2020 | E12: 2 | F12: 2 | G12: 0 | H12: 1 | I12: 26206.95 | J12: 5.5 | K12: 1
A13: 12 | B13: 1 | C13: 12 | D13: 2020 | E13: 3 | F13: 3 | G13: 0 | H13: 1 | I13: 56428.91 | J13: 2.3 | K13: 0
... A61: 60 | B61: 5 | C61: 12 | D61: 2020 | E61: 3 | F61: 3 | G61: 0 | H61: 0 | I61: 36639.95 | J61: 3.3 | K61: 0

Sheet Quality_Data
A1: event_id | B1: supplier_id | C1: sku_id | D1: event_type | E1: event_date | F1: affected_lots | G1: closure_state
A2: 1 | B2: 1 | C2: SS-01001 | D2: recall | E2: 2026-01-01 | F2: 1 | G2: closed
A3: 2 | B3: 2 | C3: SS-01010 | D3: sterility_deviation | E3: 2026-02-02 | F3: 2 | G3: open
A4: 3 | B4: 3 | C4: SS-01019 | D4: late_cold_chain | E4: 2026-03-03 | F4: 3 | G4: scope-unresolved
A5: 4 | B5: 4 | C5: SS-01028 | D5: packaging_damage | E5: 2026-04-04 | F5: 4 | G5: closed
A6: 5 | B6: 5 | C6: SS-01037 | D6: recall | E6: 2026-05-05 | F6: 1 | G6: open
A7: 6 | B7: 1 | C7: SS-01046 | D7: sterility_deviation | E7: 2026-06-06 | F7: 2 | G7: scope-unresolved
A8: 7 | B8: 2 | C8: SS-01055 | D8: late_cold_chain | E8: 2026-07-07 | F8: 3 | G8: closed
A9: 8 | B9: 3 | C9: SS-01064 | D9: packaging_damage | E9: 2026-08-08 | F9: 4 | G9: open
A10: 9 | B10: 4 | C10: SS-01073 | D10: recall | E10: 2026-09-09 | F10: 1 | G10: scope-unresolved
A11: 10 | B11: 5 | C11: SS-01082 | D11: sterility_deviation | E11: 2026-10-10 | F11: 2 | G11: closed
A12: 11 | B12: 1 | C12: SS-01091 | D12: late_cold_chain | E12: 2026-11-11 | F12: 3 | G12: open
A13: 12 | B13: 2 | C13: SS-01100 | D13: packaging_damage | E13: 2026-12-12 | F13: 4 | G13: scope-unresolved
... A25: 24 | B25: 4 | C25: SS-01208 | D25: packaging_damage | E25: 2026-12-24 | F25: 4 | G25: scope-unresolved

Sheet Exceptions
A1: Exception register with evidence grading
A2: evidence_class: invoice/statement = documented; assertion-only/missing-support = unverified (excluded from confirmed exposure).
A3: exception_id | B3: sku_id | C3: lot_id | D3: site_id | E3: exception_type | F3: quantity | G3: evidence_status | H3: source_locator | I3: evidence_class | J3: confirmed_qty
A4: EX-0001 | B4: SS-01001 | C4: LOT-07001 | D4: HOSP-1 | E4: recall | F4: 5 | G4: invoice | H4: exception control source row 2 | I4: =IF(OR(G4="invoice",G4="statement"),"documented","unverified") | J4: =IF(I4="documented",F4,0)
A5: EX-0002 | B5: SS-01002 | C5: LOT-07002 | D5: HOSP-2 | E5: damage | F5: 2 | G5: statement | H5: exception control source row 3 | I5: =IF(OR(G5="invoice",G5="statement"),"documented","unverified") | J5: =IF(I5="documented",F5,0)
A6: EX-0003 | B6: SS-01003 | C6: LOT-07003 | D6: HOSP-3 | E6: near-expiry | F6: 0 | G6: assertion-only | H6: exception control source row 4 | I6: =IF(OR(G6="invoice",G6="statement"),"documented","unverified") | J6: =IF(I6="documented",F6,0)
A7: EX-0004 | B7: SS-01004 | C7: LOT-07004 | D7: HOSP-4 | E7: lot-conflict | F7: 37 | G7: missing-support | H7: exception control source row 5 | I7: =IF(OR(G7="invoice",G7="statement"),"documented","unverified") | J7: =IF(I7="documented",F7,0)
A8: EX-0005 | B8: SS-01005 | C8: LOT-07005 | D8: HOSP-1 | E8: evidence-gap | F8: 35 | G8: invoice | H8: exception control source row 6 | I8: =IF(OR(G8="invoice",G8="statement"),"documented","unverified") | J8: =IF(I8="documented",F8,0)
A9: EX-0006 | B9: SS-01006 | C9: LOT-07006 | D9: HOSP-2 | E9: recall | F9: 32 | G9: statement | H9: exception control source row 7 | I9: =IF(OR(G9="invoice",G9="statement"),"documented","unverified") | J9: =IF(I9="documented",F9,0)
A10: EX-0007 | B10: SS-01007 | C10: LOT-07007 | D10: HOSP-3 | E10: damage | F10: 30 | G10: assertion-only | H10: exception control source row 8 | I10: =IF(OR(G10="invoice",G10="statement"),"documented","unverified") | J10: =IF(I10="documented",F10,0)
A11: EX-0008 | B11: SS-01008 | C11: LOT-07008 | D11: HOSP-4 | E11: near-expiry | F11: 27 | G11: missing-support | H11: exception control source row 9 | I11: =IF(OR(G11="invoice",G11="statement"),"documented","unverified") | J11: =IF(I11="documented",F11,0)
A12: EX-0009 | B12: SS-01009 | C12: LOT-07009 | D12: HOSP-1 | E12: lot-conflict | F12: 25 | G12: invoice | H12: exception control source row 10 | I12: =IF(OR(G12="invoice",G12="statement"),"documented","unverified") | J12: =IF(I12="documented",F12,0)
A13: EX-0010 | B13: SS-01010 | C13: LOT-07010 | D13: HOSP-2 | E13: evidence-gap | F13: 22 | G13: statement | H13: exception control source row 11 | I13: =IF(OR(G13="invoice",G13="statement"),"documented","unverified") | J13: =IF(I13="documented",F13,0)
A14: EX-0011 | B14: SS-01011 | C14: LOT-07011 | D14: HOSP-3 | E14: recall | F14: 20 | G14: assertion-only | H14: exception control source row 12 | I14: =IF(OR(G14="invoice",G14="statement"),"documented","unverified") | J14: =IF(I14="documented",F14,0)
A15: EX-0012 | B15: SS-01012 | C15: LOT-07012 | D15: HOSP-4 | E15: damage | F15: 17 | G15: missing-support | H15: exception control source row 13 | I15: =IF(OR(G15="invoice",G15="statement"),"documented","unverified") | J15: =IF(I15="documented",F15,0)
... A51: EX-0048 | B51: SS-01048 | C51: LOT-07048 | D51: HOSP-4 | E51: near-expiry | F51: 5 | G51: missing-support | H51: exception control source row 49 | I51: =IF(OR(G51="invoice",G51="statement"),"documented","unverified") | J51: =IF(I51="documented",F51,0)

Sheet Site_Constraints
A1: Site capacity pools by scenario (net of reserved emergency units)
A2: Raw rows 4-15 (site_storage_clinical_constraints.csv). Pool summary rows 19-23: SUMIFS; net = MAX(0, gross - reserved).
A4: constraint_id | B4: site_id | C4: capacity_pool | D4: adverse_units | E4: base_units | F4: upside_units | G4: reserved_emergency_units | H4: clinical_access_floor | I4: minimum_floor | J4: evidence_status
A5: SSC-001 | B5: HOSP-1 | C5: BUYER_FTE | D5: 0.5 | E5: 1 | F5: 2 | G5: 0.25 | H5: vascular kits | I5: 80 | J5: approved
A6: SSC-002 | B6: HOSP-2 | C6: COLD_CHAIN_PALLET | D6: 1 | E6: 2 | F6: 3 | G6: 0.5 | H6: airway kits | I6: 65 | J6: planning range
A7: SSC-003 | B7: HOSP-3 | C7: RECEIVING_SLOT | D7: 2 | E7: 3 | F7: 4 | G7: 1 | H7: surgical packs | I7: 120 | J7: conditional
A8: SSC-004 | B8: HOSP-4 | C8: CLINICAL_REVIEW | D8: 0.5 | E8: 1 | F8: 2 | G8: 0.25 | H8: wound supplies | I8: 95 | J8: approved
A9: SSC-005 | B9: HOSP-1 | C9: TRANSFER_VEHICLE | D9: 1 | E9: 2 | F9: 3 | G9: 0.5 | H9: vascular kits | I9: 80 | J9: planning range
A10: SSC-006 | B10: HOSP-2 | C10: BUYER_FTE | D10: 2 | E10: 3 | F10: 4 | G10: 1 | H10: airway kits | I10: 65 | J10: conditional
A11: SSC-007 | B11: HOSP-3 | C11: COLD_CHAIN_PALLET | D11: 0.5 | E11: 1 | F11: 2 | G11: 0.25 | H11: surgical packs | I11: 120 | J11: approved
A12: SSC-008 | B12: HOSP-4 | C12: RECEIVING_SLOT | D12: 1 | E12: 2 | F12: 3 | G12: 0.5 | H12: wound supplies | I12: 95 | J12: planning range
A13: SSC-009 | B13: HOSP-1 | C13: CLINICAL_REVIEW | D13: 2 | E13: 3 | F13: 4 | G13: 1 | H13: vascular kits | I13: 80 | J13: conditional
A14: SSC-010 | B14: HOSP-2 | C14: TRANSFER_VEHICLE | D14: 0.5 | E14: 1 | F14: 2 | G14: 0.25 | H14: airway kits | I14: 65 | J14: approved
A15: SSC-011 | B15: HOSP-3 | C15: BUYER_FTE | D15: 1 | E15: 2 | F15: 3 | G15: 0.5 | H15: surgical packs | I15: 120 | J15: planning range
A16: SSC-012 | B16: HOSP-4 | C16: COLD_CHAIN_PALLET | D16: 2 | E16: 3 | F16: 4 | G16: 1 | H16: wound supplies | I16: 95 | J16: conditional
A18: capacity_pool | B18: adv_gross | C18: adv_reserved | D18: adv_net | E18: base_gross | F18: base_reserved | G18: base_net | H18: up_gross | I18: up_reserved | J18: up_net | K18: non_approved_rows
A19: BUYER_FTE | B19: =SUMIF($C$5:$C$16,$A19,D$5:D$16) | C19: =SUMIF($C$5:$C$16,$A19,$G$5:$G$16) | D19: =MAX(0,B19-C19) | E19: =SUMIF($C$5:$C$16,$A19,E$5:E$16) | F19: =SUMIF($C$5:$C$16,$A19,$G$5:$G$16) | G19: =MAX(0,E19-F19) | H19: =SUMIF($C$5:$C$16,$A19,F$5:F$16) | I19: =SUMIF($C$5:$C$16,$A19,$G$5:$G$16) | J19: =MAX(0,H19-I19) | K19: =COUNTIFS($C$5:$C$16,$A19,$J$5:$J$16,"<>approved")
A20: CLINICAL_REVIEW | B20: =SUMIF($C$5:$C$16,$A20,D$5:D$16) | C20: =SUMIF($C$5:$C$16,$A20,$G$5:$G$16) | D20: =MAX(0,B20-C20) | E20: =SUMIF($C$5:$C$16,$A20,E$5:E$16) | F20: =SUMIF($C$5:$C$16,$A20,$G$5:$G$16) | G20: =MAX(0,E20-F20) | H20: =SUMIF($C$5:$C$16,$A20,F$5:F$16) | I20: =SUMIF($C$5:$C$16,$A20,$G$5:$G$16) | J20: =MAX(0,H20-I20) | K20: =COUNTIFS($C$5:$C$16,$A20,$J$5:$J$16,"<>approved")
A21: COLD_CHAIN_PALLET | B21: =SUMIF($C$5:$C$16,$A21,D$5:D$16) | C21: =SUMIF($C$5:$C$16,$A21,$G$5:$G$16) | D21: =MAX(0,B21-C21) | E21: =SUMIF($C$5:$C$16,$A21,E$5:E$16) | F21: =SUMIF($C$5:$C$16,$A21,$G$5:$G$16) | G21: =MAX(0,E21-F21) | H21: =SUMIF($C$5:$C$16,$A21,F$5:F$16) | I21: =SUMIF($C$5:$C$16,$A21,$G$5:$G$16) | J21: =MAX(0,H21-I21) | K21: =COUNTIFS($C$5:$C$16,$A21,$J$5:$J$16,"<>approved")
A22: RECEIVING_SLOT | B22: =SUMIF($C$5:$C$16,$A22,D$5:D$16) | C22: =SUMIF($C$5:$C$16,$A22,$G$5:$G$16) | D22: =MAX(0,B22-C22) | E22: =SUMIF($C$5:$C$16,$A22,E$5:E$16) | F22: =SUMIF($C$5:$C$16,$A22,$G$5:$G$16) | G22: =MAX(0,E22-F22) | H22: =SUMIF($C$5:$C$16,$A22,F$5:F$16) | I22: =SUMIF($C$5:$C$16,$A22,$G$5:$G$16) | J22: =MAX(0,H22-I22) | K22: =COUNTIFS($C$5:$C$16,$A22,$J$5:$J$16,"<>approved")
A23: TRANSFER_VEHICLE | B23: =SUMIF($C$5:$C$16,$A23,D$5:D$16) | C23: =SUMIF($C$5:$C$16,$A23,$G$5:$G$16) | D23: =MAX(0,B23-C23) | E23: =SUMIF($C$5:$C$16,$A23,E$5:E$16) | F23: =SUMIF($C$5:$C$16,$A23,$G$5:$G$16) | G23: =MAX(0,E23-F23) | H23: =SUMIF($C$5:$C$16,$A23,F$5:F$16) | I23: =SUMIF($C$5:$C$16,$A23,$G$5:$G$16) | J23: =MAX(0,H23-I23) | K23: =COUNTIFS($C$5:$C$16,$A23,$J$5:$J$16,"<>approved")

Sheet Action_Catalog
A1: Supply action catalog (raw from supply_action_constraints.csv) + scenario eligibility flags
A3: action_id | B3: eligible_family | C3: operational_lever | D3: lead_time_change_days | E3: transfer_or_receipt_capacity_units | F3: start_delay_days | G3: fixed_cost_usd | H3: capacity_pool | I3: capacity_units | J3: dependency_group | K3: mutual_exclusion_group | L3: overlap_group | M3: shared_execution_fraction | N3: eligible_scenarios | O3: clinical_constraint | P3: supporting_record_grade | Q3: elig_adverse | R3: elig_base | S3: elig_upside
A4: SAC-001 | B4: vascular | C4: expedite receipt | D4: 4 | E4: 16.2 | F4: 1 | G4: 1200 | H4: BUYER_FTE | I4: 0.5 | J4: DG-1 | K4: MX-1 | L4: OV-1 | M4: 0 | N4: adverse|base|upside | O4: no reduction below emergency access floor | P4: A | Q4: =IF(ISNUMBER(SEARCH("adverse",$N4)),1,0) | R4: =IF(ISNUMBER(SEARCH("base",$N4)),1,0) | S4: =IF(ISNUMBER(SEARCH("upside",$N4)),1,0)
A5: SAC-002 | B5: respiratory | C5: site transfer | D5: 1 | E5: 24.3 | F5: 3 | G5: 4500 | H5: COLD_CHAIN_PALLET | I5: 1 | J5: DG-2 | L5: OV-2 | M5: 0.2 | N5: base|upside | O5: requires infection-control approval | P5: B | Q5: =IF(ISNUMBER(SEARCH("adverse",$N5)),1,0) | R5: =IF(ISNUMBER(SEARCH("base",$N5)),1,0) | S5: =IF(ISNUMBER(SEARCH("upside",$N5)),1,0)
A6: SAC-003 | B6: surgical | C6: supplier substitution | D6: 7 | E6: 32.4 | F6: 7 | G6: 9000 | H6: RECEIVING_SLOT | I6: 1.5 | J6: DG-3 | L6: OV-3 | M6: 0.35 | N6: upside | O6: preserve cold-chain integrity | P6: C | Q6: =IF(ISNUMBER(SEARCH("adverse",$N6)),1,0) | R6: =IF(ISNUMBER(SEARCH("base",$N6)),1,0) | S6: =IF(ISNUMBER(SEARCH("upside",$N6)),1,0)
A7: SAC-004 | B7: diagnostic | C7: allocation hold | D7: 6 | E7: 43.2 | F7: 14 | G7: 18000 | H7: CLINICAL_REVIEW | I7: 2 | J7: DG-4 | L7: OV-4 | M7: 0.5 | N7: adverse|base|upside | O7: lot-level recall clearance required | P7: A | Q7: =IF(ISNUMBER(SEARCH("adverse",$N7)),1,0) | R7: =IF(ISNUMBER(SEARCH("base",$N7)),1,0) | S7: =IF(ISNUMBER(SEARCH("upside",$N7)),1,0)
A8: SAC-005 | B8: wound | C8: expedite receipt | D8: 1 | E8: 60.8 | F8: 1 | G8: 1200 | H8: TRANSFER_VEHICLE | I8: 0.5 | J8: DG-5 | L8: OV-5 | M8: 0 | N8: base|upside | O8: no reduction below emergency access floor | P8: B | Q8: =IF(ISNUMBER(SEARCH("adverse",$N8)),1,0) | R8: =IF(ISNUMBER(SEARCH("base",$N8)),1,0) | S8: =IF(ISNUMBER(SEARCH("upside",$N8)),1,0)
